Workbook

Sheet Libreta
A2: LIBRETA INFORMATIVA DE NOTAS
A3: NIVEL PRIMARIA 2025
C5: AÑO/GRADO: | D5: 6° GRADO
B6: N° LISTA: | C6: 25
B7: ESTUDIANTE: | C7: =VLOOKUP(Libreta!$C$6,PRIMARIA!$A$1:$EH$33,PRIMARIA!$B$1,0) -> VEGA BUSTINZA LUCIANA NATALIA | E7: I BIMESTRE
B8: DOCENTE: | C8: LUZ MENDOZA CAMI
B9: AREAS | C9: COMPETENCIAS | D9: NOTAS FINALES
D10: U1 | E10: U2 | F10: BIM
B11: Personal Social | C11: Construye su identidad. | D11: =IFERROR(VLOOKUP($C$6,PRIMARIA!$A$1:$EH$33,PRIMARIA!$C$1,0),"-") -> A | E11: =IFERROR(VLOOKUP($C$6,PRIMARIA!$A$1:$EH$33,PRIMARIA!$D$1,0),"-") -> A | F11: =IFERROR(VLOOKUP($C$6,PRIMARIA!$A$1:$EH$33,PRIMARIA!$E$1,0),"-") -> A
C12: Convive y participa democráticamente. | D12: =IFERROR(VLOOKUP($C$6,PRIMARIA!$A$1:$EH$33,PRIMARIA!$F$1,0),"-") -> A | E12: =IFERROR(VLOOKUP($C$6,PRIMARIA!$A$1:$EH$33,PRIMARIA!$G$1,0),"-") -> A | F12: =IFERROR(VLOOKUP($C$6,PRIMARIA!$A$1:$EH$33,PRIMARIA!$H$1,0),"-") -> A
C13: Construye interpretaciones históricas. | D13: =IFERROR(VLOOKUP($C$6,PRIMARIA!$A$1:$EH$33,PRIMARIA!$I$1,0),"-") -> A | E13: =IFERROR(VLOOKUP($C$6,PRIMARIA!$A$1:$EH$33,PRIMARIA!$J$1,0),"-") -> A | F13: =IFERROR(VLOOKUP($C$6,PRIMARIA!$A$1:$EH$33,PRIMARIA!$K$1,0),"-") -> A
C14: Gestiona responsablemente el espacio y el ambiente. | D14: =IFERROR(VLOOKUP($C$6,PRIMARIA!$A$1:$EH$33,PRIMARIA!$L$1,0),"-") -> A | E14: =IFERROR(VLOOKUP($C$6,PRIMARIA!$A$1:$EH$33,PRIMARIA!$M$1,0),"-") -> A | F14: =IFERROR(VLOOKUP($C$6,PRIMARIA!$A$1:$EH$33,PRIMARIA!$N$1,0),"-") -> A
C15: Gestiona responsablemente los recursos económicos. | D15: =IFERROR(VLOOKUP($C$6,PRIMARIA!$A$1:$EH$33,PRIMARIA!$O$1,0),"-") -> A | E15: =IFERROR(VLOOKUP($C$6,PRIMARIA!$A$1:$EH$33,PRIMARIA!$P$1,0),"-") -> A | F15: =IFERROR(VLOOKUP($C$6,PRIMARIA!$A$1:$EH$33,PRIMARIA!$Q$1,0),"-") -> A
B16: Educación Fisica | C16: Se desenvuelve de manera autónoma a través de su identidad. | D16: =IFERROR(VLOOKUP($C$6,PRIMARIA!$A$1:$EH$33,PRIMARIA!$R$1,0),"-") -> A | E16: =IFERROR(VLOOKUP($C$6,PRIMARIA!$A$1:$EH$33,PRIMARIA!$S$1,0),"-") -> A | F16: =IFERROR(VLOOKUP($C$6,PRIMARIA!$A$1:$EH$33,PRIMARIA!$T$1,0),"-") -> A
C17: Asume una vida saludable. | D17: =IFERROR(VLOOKUP($C$6,PRIMARIA!$A$1:$EH$33,PRIMARIA!$U$1,0),"-") -> A | E17: =IFERROR(VLOOKUP($C$6,PRIMARIA!$A$1:$EH$33,PRIMARIA!$V$1,0),"-") -> A | F17: =IFERROR(VLOOKUP($C$6,PRIMARIA!$A$1:$EH$33,PRIMARIA!$W$1,0),"-") -> A
C18: Interactúa a través de sus habilidades sociomotrices. | D18: =IFERROR(VLOOKUP($C$6,PRIMARIA!$A$1:$EH$33,PRIMARIA!$X$1,0),"-") -> A | E18: =IFERROR(VLOOKUP($C$6,PRIMARIA!$A$1:$EH$33,PRIMARIA!$Y$1,0),"-") -> A | F18: =IFERROR(VLOOKUP($C$6,PRIMARIA!$A$1:$EH$33,PRIMARIA!$Z$1,0),"-") -> A
B19: Comunicación | C19: Se comunica oralmente en lengua materna. | D19: =IFERROR(VLOOKUP($C$6,PRIMARIA!$A$1:$EH$33,PRIMARIA!$AA$1,0),"-") -> A | E19: =IFERROR(VLOOKUP($C$6,PRIMARIA!$A$1:$EH$33,PRIMARIA!$AB$1,0),"-") -> A | F19: =IFERROR(VLOOKUP($C$6,PRIMARIA!$A$1:$EH$33,PRIMARIA!$AC$1,0),"-") -> A
C20: Lee diversos tipos de textos escritos. | D20: =IFERROR(VLOOKUP($C$6,PRIMARIA!$A$1:$EH$33,PRIMARIA!$AD$1,0),"-") -> A | E20: =IFERROR(VLOOKUP($C$6,PRIMARIA!$A$1:$EH$33,PRIMARIA!$AE$1,0),"-") -> A | F20: =IFERROR(VLOOKUP($C$6,PRIMARIA!$A$1:$EH$33,PRIMARIA!$AF$1,0),"-") -> A
C21: Escribe diversos tipos de texto. | D21: =IFERROR(VLOOKUP($C$6,PRIMARIA!$A$1:$EH$33,PRIMARIA!$AG$1,0),"-") -> A | E21: =IFERROR(VLOOKUP($C$6,PRIMARIA!$A$1:$EH$33,PRIMARIA!$AH$1,0),"-") -> A | F21: =IFERROR(VLOOKUP($C$6,PRIMARIA!$A$1:$EH$33,PRIMARIA!$AI$1,0),"-") -> A
B22: Arte y Cultura | C22: Aprecia de manera crítica manifestaciones artístico-culturales. | D22: =IFERROR(VLOOKUP($C$6,PRIMARIA!$A$1:$EH$33,PRIMARIA!$AJ$1,0),"-") -> A | E22: =IFERROR(VLOOKUP($C$6,PRIMARIA!$A$1:$EH$33,PRIMARIA!$AK$1,0),"-") -> A | F22: =IFERROR(VLOOKUP($C$6,PRIMARIA!$A$1:$EH$33,PRIMARIA!$AL$1,0),"-") -> A
C23: Crea proyectos desde los lenguajes artísticos. | D23: =IFERROR(VLOOKUP($C$6,PRIMARIA!$A$1:$EH$33,PRIMARIA!$AM$1,0),"-") -> A | E23: =IFERROR(VLOOKUP($C$6,PRIMARIA!$A$1:$EH$33,PRIMARIA!$AN$1,0),"-") -> A | F23: =IFERROR(VLOOKUP($C$6,PRIMARIA!$A$1:$EH$33,PRIMARIA!$AO$1,0),"-") -> A
B24: Ingles | C24: Se comunica oralmente en inglés como lengua extranjera. | D24: =IFERROR(VLOOKUP($C$6,PRIMARIA!$A$1:$EH$33,PRIMARIA!$AP$1,0),"-") -> A | E24: =IFERROR(VLOOKUP($C$6,PRIMARIA!$A$1:$EH$33,PRIMARIA!$AQ$1,0),"-") -> A | F24: =IFERROR(VLOOKUP($C$6,PRIMARIA!$A$1:$EH$33,PRIMARIA!$AR$1,0),"-") -> A
C25: Lee diversos tipos de texto en inglés como lengua extranjera. | D25: =IFERROR(VLOOKUP($C$6,PRIMARIA!$A$1:$EH$33,PRIMARIA!$AS$1,0),"-") -> A | E25: =IFERROR(VLOOKUP($C$6,PRIMARIA!$A$1:$EH$33,PRIMARIA!$AT$1,0),"-") -> A | F25: =IFERROR(VLOOKUP($C$6,PRIMARIA!$A$1:$EH$33,PRIMARIA!$AU$1,0),"-") -> A
C26: Escribe diversos tipos de texto en inglés como lengua extranjera. | D26: =IFERROR(VLOOKUP($C$6,PRIMARIA!$A$1:$EH$33,PRIMARIA!$AV$1,0),"-") -> A | E26: =IFERROR(VLOOKUP($C$6,PRIMARIA!$A$1:$EH$33,PRIMARIA!$AW$1,0),"-") -> A | F26: =IFERROR(VLOOKUP($C$6,PRIMARIA!$A$1:$EH$33,PRIMARIA!$AX$1,0),"-") -> A
B27: Matemática | C27: Resuelve problemas de cantidad. | D27: =IFERROR(VLOOKUP($C$6,PRIMARIA!$A$1:$EH$33,PRIMARIA!$AY$1,0),"-") -> B | E27: =IFERROR(VLOOKUP($C$6,PRIMARIA!$A$1:$EH$33,PRIMARIA!$AZ$1,0),"-") -> B | F27: =IFERROR(VLOOKUP($C$6,PRIMARIA!$A$1:$EH$33,PRIMARIA!$BA$1,0),"-") -> B
C28: Resuelve problemas de regularidad, equivalencia y cambio. | D28: =IFERROR(VLOOKUP($C$6,PRIMARIA!$A$1:$EH$33,PRIMARIA!$BB$1,0),"-") -> A | E28: =IFERROR(VLOOKUP($C$6,PRIMARIA!$A$1:$EH$33,PRIMARIA!$BC$1,0),"-") -> A | F28: =IFERROR(VLOOKUP($C$6,PRIMARIA!$A$1:$EH$33,PRIMARIA!$BD$1,0),"-") -> A
C29: Resuelve problemas de movimiento, forma y localización. | D29: =IFERROR(VLOOKUP($C$6,PRIMARIA!$A$1:$EH$33,PRIMARIA!$BE$1,0),"-") -> A | E29: =IFERROR(VLOOKUP($C$6,PRIMARIA!$A$1:$EH$33,PRIMARIA!$BF$1,0),"-") -> B | F29: =IFERROR(VLOOKUP($C$6,PRIMARIA!$A$1:$EH$33,PRIMARIA!$BG$1,0),"-") -> A
C30: Resuelve problemas de gestión de datos e incertidumbre. | D30: =IFERROR(VLOOKUP($C$6,PRIMARIA!$A$1:$EH$33,PRIMARIA!$BH$1,0),"-") -> A | E30: =IFERROR(VLOOKUP($C$6,PRIMARIA!$A$1:$EH$33,PRIMARIA!$BI$1,0),"-") -> A | F30: =IFERROR(VLOOKUP($C$6,PRIMARIA!$A$1:$EH$33,PRIMARIA!$BJ$1,0),"-") -> A
B31: Ciencia y Tecnología | C31: Indaga mediante métodos científicos para construir conocimientos. | D31: =IFERROR(VLOOKUP($C$6,PRIMARIA!$A$1:$EH$33,PRIMARIA!$BK$1,0),"-") -> B | E31: =IFERROR(VLOOKUP($C$6,PRIMARIA!$A$1:$EH$33,PRIMARIA!$BL$1,0),"-") -> A | F31: =IFERROR(VLOOKUP($C$6,PRIMARIA!$A$1:$EH$33,PRIMARIA!$BM$1,0),"-") -> A
C32: Explica el mundo natural y artificial en base a conocimiento sobre los seres vivos, materia, energía, biodiversidad, tierra y universo. | D32: =IFERROR(VLOOKUP($C$6,PRIMARIA!$A$1:$EH$33,PRIMARIA!$BN$1,0),"-") -> A | E32: =IFERROR(VLOOKUP($C$6,PRIMARIA!$A$1:$EH$33,PRIMARIA!$BO$1,0),"-") -> A | F32: =IFERROR(VLOOKUP($C$6,PRIMARIA!$A$1:$EH$33,PRIMARIA!$BP$1,0),"-") -> A
C33: Diseña y construye soluciones tecnológicas para resolver problemas de entorno. | D33: =IFERROR(VLOOKUP($C$6,PRIMARIA!$A$1:$EH$33,PRIMARIA!$BQ$1,0),"-") -> B | E33: =IFERROR(VLOOKUP($C$6,PRIMARIA!$A$1:$EH$33,PRIMARIA!$BR$1,0),"-") -> B | F33: =IFERROR(VLOOKUP($C$6,PRIMARIA!$A$1:$EH$33,PRIMARIA!$BS$1,0),"-") -> B
B34: Educación Religiosa | C34: Construye su identidad como persona humana amada por Dios, digna, libre y transparente, comprendiendo la doctrina de su propia religión y abierto al diálogo con las personas cercanas. | D34: =IFERROR(VLOOKUP($C$6,PRIMARIA!$A$1:$EH$33,PRIMARIA!$BT$1,0),"-") -> A | E34: =IFERROR(VLOOKUP($C$6,PRIMARIA!$A$1:$EH$33,PRIMARIA!$BU$1,0),"-") -> A | F34: =IFERROR(VLOOKUP($C$6,PRIMARIA!$A$1:$EH$33,PRIMARIA!$BV$1,0),"-") -> A
C35: Asume la experiencia el encuentro personal comunitario con Dios en su proyecto de vida en coherencia con su creencia religiosa. | D35: =IFERROR(VLOOKUP($C$6,PRIMARIA!$A$1:$EH$33,PRIMARIA!$BW$1,0),"-") -> A | E35: =IFERROR(VLOOKUP($C$6,PRIMARIA!$A$1:$EH$33,PRIMARIA!$BX$1,0),"-") -> A | F35: =IFERROR(VLOOKUP($C$6,PRIMARIA!$A$1:$EH$33,PRIMARIA!$BY$1,0),"-") -> A
B36: Taller de Emprendimiento | C36: Gestiona proyectos de emprendimiento económico social. | D36: =IFERROR(VLOOKUP($C$6,PRIMARIA!$A$1:$EH$33,PRIMARIA!$BZ$1,0),"-") -> A | E36: =IFERROR(VLOOKUP($C$6,PRIMARIA!$A$1:$EH$33,PRIMARIA!$CA$1,0),"-") -> A | F36: =IFERROR(VLOOKUP($C$6,PRIMARIA!$A$1:$EH$33,PRIMARIA!$CB$1,0),"-") -> A
B37: Taller de Computo | C37: Crea, ejecuta y aplica las diferentes herramientas tecnológicas en programas informáticos. | D37: =IFERROR(VLOOKUP($C$6,PRIMARIA!$A$1:$EH$33,PRIMARIA!$CC$1,0),"-") -> A | E37: =IFERROR(VLOOKUP($C$6,PRIMARIA!$A$1:$EH$33,PRIMARIA!$CD$1,0),"-") -> A | F37: =IFERROR(VLOOKUP($C$6,PRIMARIA!$A$1:$EH$33,PRIMARIA!$CE$1,0),"-") -> A
B38: Taller Programación y Robótica | C38: Utiliza la lógica para crear programas utilizando código abierto y desarrolla habilidades en el uso de prototipos robóticos. | D38: =IFERROR(VLOOKUP($C$6,PRIMARIA!$A$1:$EH$33,PRIMARIA!$CF$1,0),"-") -> A | E38: =IFERROR(VLOOKUP($C$6,PRIMARIA!$A$1:$EH$33,PRIMARIA!$CG$1,0),"-") -> A | F38: =IFERROR(VLOOKUP($C$6,PRIMARIA!$A$1:$EH$33,PRIMARIA!$CH$1,0),"-") -> A
B39: Tranversalidad | C39: Gestiona su aprendizaje de manera autónoma. | E39: =IFERROR(VLOOKUP($C$6,PRIMARIA!$A$1:$EH$33,PRIMARIA!$CI$1,0),"-") -> A
C40: Se desenvuelve en entornos virtuales generados por las TICs. | E40: =IFERROR(VLOOKUP($C$6,PRIMARIA!$A$1:$EH$33,PRIMARIA!$CJ$1,0),"-") -> A
B42: ACTITUDES DEL ESTUDIANTE | D42: SI | E42: A VECES | F42: NO
B43: 1 | C43: Asiste a clases cuidando su presentación personal en todo momento. | D43: =IFERROR(VLOOKUP($C$6,PRIMARIA!$A$1:$EH$33,PRIMARIA!$CK$1,0),"-") -> X | E43: =IFERROR(VLOOKUP($C$6,PRIMARIA!$A$1:$EH$33,PRIMARIA!$CL$1,0),"-") -> 0 | F43: =IFERROR(VLOOKUP($C$6,PRIMARIA!$A$1:$EH$33,PRIMARIA!$CM$1,0),"-") -> 0
...

Sheet PRIMARIA
B1: 2 | C1: 3 | D1: 4 | E1: 5 | F1: 6 | G1: 7 | H1: 8 | I1: 9 | J1: 10 | K1: 11 | L1: 12 | M1: 13 | N1: 14 | O1: 15 | P1: 16 | Q1: 17 | R1: 18 | S1: 19 | T1: 20 | U1: 21 | V1: 22 | W1: 23 | X1: 24 | Y1: 25 | Z1: 26 | AA1: 27 | AB1: 28 | AC1: 29 | AD1: 30 | AE1: 31 | AF1: 32 | AG1: 33 | AH1: 34 | AI1: 35 | AJ1: 36 | AK1: 37 | AL1: 38 | AM1: 39 | AN1: 40 | AO1: 41 | AP1: 42 | AQ1: 43 | AR1: 44 | AS1: 45 | AT1: 46 | AU1: 47 | AV1: 48 | AW1: 49 | AX1: 50 | AY1: 51 | AZ1: 52 | BA1: 53 | BB1: 54 | BC1: 55 | BD1: 56 | BE1: 57 | BF1: 58 | BG1: 59 | BH1: 60 | BI1: 61 | BJ1: 62 | BK1: 63 | BL1: 64 | BM1: 65 | BN1: 66 | BO1: 67 | BP1: 68 | BQ1: 69 | BR1: 70 | BS1: 71 | BT1: 72 | BU1: 73 | BV1: 74 | BW1: 75 | BX1: 76 | BY1: 77 | BZ1: 78 | CA1: 79 | CB1: 80 | CC1: 81 | CD1: 82 | CE1: 83 | CF1: 84 | CG1: 85 | CH1: 86 | CI1: 87 | CJ1: 88 | CK1: 89 | CL1: 90 | CM1: 91 | CN1: 92 | CO1: 93 | CP1: 94 | CQ1: 95 | CR1: 96 | CS1: 97 | CT1: 98 | CU1: 99 | CV1: 100 | CW1: 101 | CX1: 102 | CY1: 103 | CZ1: 104 | DA1: 105 | DB1: 106 | DC1: 107 | DD1: 108 | DE1: 109 | DF1: 110 | DG1: 111 | DH1: 112 | DI1: 113 | DJ1: 114 | DK1: 115 | DL1: 116 | DM1: 117 | DN1: 118 | DO1: 119 | DP1: 120 | DQ1: 121 | DR1: 122 | DS1: 123 | DT1: 124 | DU1: 125 | DV1: 126 | DW1: 127 | DX1: 128 | DY1: 129 | DZ1: 130 | EA1: 131 | EB1: 132 | EC1: 133 | ED1: 134 | EE1: 135 | EF1: 136
C2: Personal Social | R2: Ed. Fisica | AA2: Comunicación | AJ2: Arte | AP2: Ingles | AY2: Matemática | BK2: C. Tecnologia | BT2: Religión | BZ2: T. Emprende | CC2: T. Computo | CF2: T.Robotica | CI2: Transversal | CK2: Nota Aprec. Personal | DM2: Participación PP.FF | DZ2: Asistencia | EF2: Apuntes del Tutor | EG2: OTROS
A3: N° | B3: ESTUDIANTES | C3: Comp 1 | F3: Comp 2 | I3: Comp 3 | L3: Comp 4 | O3: Comp 5 | R3: Comp 1 | U3: Comp 2 | X3: Comp 3 | AA3: Comp 1 | AD3: Comp 2 | AG3: Comp 3 | AJ3: Comp 1 | AM3: Comp 2 | AP3: Comp 1 | AS3: Comp 2 | AV3: Comp 3 | AY3: Comp 1 | BB3: Comp 2 | BE3: Comp 3 | BH3: Comp 4 | BK3: Comp 1 | BN3: Comp 2 | BQ3: Comp 3 | BT3: Comp 1 | BW3: Comp 2 | BZ3: Comp 1 | CC3: Comp 1 | CF3: Comp 1 | CK3: 1 | CN3: 2 | CQ3: 3 | CT3: 4 | CW3: 5 | CZ3: 6 | DC3: 7 | DF3: 8 | DI3: 9 | DL3: NF | DM3: 1 | DP3: 2 | DS3: 3 | DV3: 4 | DZ3: AT | EA3: A% | EB3: A | EC3: T | ED3: FJ | EE3: F | EG3: Puntaje AD-A | EH3: Orden Merito
C4: 1 | D4: 2 | E4: NF | F4: 1 | G4: 2 | H4: NF | I4: 1 | J4: 2 | K4: NF | L4: 1 | M4: 2 | N4: NF | O4: 1 | P4: 2 | Q4: NF | R4: 1 | S4: 2 | T4: NF | U4: 1 | V4: 2 | W4: NF | X4: 1 | Y4: 2 | Z4: NF | AA4: 1 | AB4: 2 | AC4: NF | AD4: 1 | AE4: 2 | AF4: NF | AG4: 1 | AH4: 2 | AI4: NF | AJ4: 1 | AK4: 2 | AL4: NF | AM4: 1 | AN4: 2 | AO4: NF | AP4: 1 | AQ4: 2 | AR4: NF | AS4: 1 | AT4: 2 | AU4: NF | AV4: 1 | AW4: 2 | AX4: NF | AY4: 1 | AZ4: 2 | BA4: NF | BB4: 1 | BC4: 2 | BD4: NF | BE4: 1 | BF4: 2 | BG4: NF | BH4: 1 | BI4: 2 | BJ4: NF | BK4: 1 | BL4: 2 | BM4: NF | BN4: 1 | BO4: 2 | BP4: NF | BQ4: 1 | BR4: 2 | BS4: NF | BT4: 1 | BU4: 2 | BV4: NF | BW4: 1 | BX4: 2 | BY4: NF | BZ4: 1 | CA4: 2 | CB4: NF | CC4: 1 | CD4: 2 | CE4: NF | CF4: 1 | CG4: 2 | CH4: NF | CI4: 1 | CJ4: 2 | CK4: S | CL4: A | CM4: N | CN4: S | CO4: A | CP4: N | CQ4: S | CR4: A | CS4: N | CT4: S | CU4: A | CV4: N | CW4: S | CX4: A | CY4: N | CZ4: S | DA4: A | DB4: N | DC4: S | DD4: A | DE4: N | DF4: S | DG4: A | DH4: N | DI4: S | DJ4: A | DK4: N | DM4: S | DN4: A | DO4: N | DP4: S | DQ4: A | DR4: N | DS4: S | DT4: A | DU4: N | DV4: S | DW4: A | DX4: N | DY4: NF
A5: 1 | B5: ACERO VARGAS MAIDA NADINE | C5: =[1]PERS!N13 -> A | D5: =[1]PERS!AH13 -> A | E5: =[1]PERS!AZ13 -> A | F5: =[1]PERS!R13 -> A | G5: =[1]PERS!AL13 -> A | H5: =[1]PERS!BA13 -> A | I5: =[1]PERS!V13 -> A | J5: =[1]PERS!AP13 -> A | K5: =[1]PERS!BB13 -> A | L5: =[1]PERS!Z13 -> A | M5: =[1]PERS!AT13 -> A | N5: =[1]PERS!BC13 -> A | O5: =[1]PERS!AD13 -> A | P5: =[1]PERS!AX13 -> A | Q5: =[1]PERS!BD13 -> A | R5: =[1]EFIS!N13 -> AD | S5: =[1]EFIS!AH13 -> A | T5: =[1]EFIS!AZ13 -> AD | U5: =[1]EFIS!R13 -> A | V5: =[1]EFIS!AL13 -> A | W5: =[1]EFIS!BA13 -> A | X5: =[1]EFIS!V13 -> A | Y5: =[1]EFIS!AP13 -> A | Z5: =[1]EFIS!BB13 -> A | AA5: =[1]COMU!N13 -> A | AB5: =[1]COMU!AH13 -> A | AC5: =[1]COMU!AZ13 -> A | AD5: =[1]COMU!R13 -> A | AE5: =[1]COMU!AH13 -> A | AF5: =[1]COMU!BA13 -> A | AG5: =[1]COMU!V13 -> A | AH5: =[1]COMU!AP13 -> A | AI5: =[1]COMU!BB13 -> A | AJ5: =[1]ARTE!N13 -> A | AK5: =[1]ARTE!AH13 -> A | AL5: =[1]ARTE!AZ13 -> A | AM5: =[1]ARTE!R13 -> A | AN5: =[1]ARTE!AL13 -> A | AO5: =[1]ARTE!BA13 -> A | AP5: =[1]ING!N13 -> A | AQ5: =[1]ING!AH13 -> A | AR5: =[1]ING!AZ13 -> A | AS5: =[1]ING!R13 -> A | AT5: =[1]ING!AL13 -> A | AU5: =[1]ING!BA13 -> A | AV5: =[1]ING!V13 -> A | AW5: =[1]ING!AP13 -> A | AX5: =[1]ING!BB13 -> A | AY5: =[1]MATE!N13 -> A | AZ5: =[1]MATE!AH13 -> A | BA5: =[1]MATE!AZ13 -> A | BB5: =[1]MATE!R13 -> B | BC5: =[1]MATE!AL13 -> A | BD5: =[1]MATE!BA13 -> A | BE5: =[1]MATE!V13 -> A | BF5: =[1]MATE!AP13 -> A | BG5: =[1]MATE!BB13 -> A | BH5: =[1]MATE!Z13 -> A | BI5: =[1]MATE!AT13 -> A | BJ5: =[1]MATE!BC13 -> A | BK5: =[1]CTEC!N13 -> A | BL5: =[1]CTEC!AH13 -> A | BM5: =[1]CTEC!AZ13 -> A | BN5: =[1]CTEC!R13 -> A | BO5: =[1]CTEC!AL13 -> A | BP5: =[1]CTEC!BA13 -> A | BQ5: =[1]CTEC!V13 -> A | BR5: =[1]CTEC!AP13 -> A | BS5: =[1]CTEC!BB13 -> A | BT5: =[1]REL!N13 -> A | BU5: =[1]REL!AH13 -> A | BV5: =[1]REL!AZ13 -> A | BW5: =[1]REL!R13 -> A | BX5: =[1]REL!AL13 -> A | BY5: =[1]REL!BA13 -> A | BZ5: =[1]EMPR!N13 -> A | CA5: =[1]EMPR!AH13 -> A | CB5: =[1]EMPR!AZ13 -> A | CC5: =[1]COMPU!N13 -> A | CD5: =[1]COMPU!AH13 -> A | CE5: =[1]COMPU!AZ13 -> A | CF5: =[1]ROBOTI!N13 -> A | CG5: =[1]ROBOTI!AH13 -> A | CH5: =[1]ROBOTI!AZ13 -> A | CI5: =[1]APREPER!AL12 -> A | CJ5: =[1]APREPER!AM12 -> A | CK5: =[1]APREPER!I12 -> X | CL5: =[1]APREPER!J12 -> 0 | CM5: =[1]APREPER!K12 -> 0 | CN5: =[1]APREPER!L12 -> X | CO5: =[1]APREPER!M12 -> 0 | CP5: =[1]APREPER!N12 -> 0 | CQ5: =[1]APREPER!O12 -> X | CR5: =[1]APREPER!P12 -> 0 | ... DL5: =[1]APREPER!AJ12 -> A | DM5: =[1]APREPPFF!I12 -> 0 | DN5: =[1]APREPPFF!J12 -> X | DO5: =[1]APREPPFF!K12 -> 0 | DP5: =[1]APREPPFF!L12 -> X | DQ5: =[1]APREPPFF!M12 -> 0 | DR5: =[1]APREPPFF!N12 -> 0 | DS5: =[1]APREPPFF!O12 -> X | DT5: =[1]APREPPFF!P12 -> 0 | ... DY5: =[1]APREPPFF!U12 -> A | DZ5: =[1]ASISTEN!$BS$4 -> 47 | EA5: =[1]ASISTEN!BT13 -> 1 | EB5: =[1]ASISTEN!BP13 -> 44 | EC5: =[1]ASISTEN!BQ13 -> 3 | ED5: =[1]ASISTEN!BR13 -> 0 | EE5: =[1]ASISTEN!BS13 -> 0 | EF5: =[1]APREPER!AN12 -> Mantiene un rendimiento satisfactorio en todas las competencias evaluadas, demostrando responsabilidad, compromiso y un adecuado desarrollo de sus aprendizajes. | EG5: =((EJ5*3)+(EK5*2)+(EL5*1)) -> 173 | EH5: =RANK(EG5,$EG$5:$EG$32,0) -> 3 | EJ5: =COUNTIF(C5:CJ5,"AD") -> 2 | EK5: =COUNTIF(C5:CJ5,"A") -> 83 | EL5: =COUNTIF(C5:CJ5,"B") -> 1
A6: 2 | B6: CHACHAQUE MAMANI BETSY NOEMI | C6: =[1]PERS!N14 -> A | D6: =[1]PERS!AH14 -> A | E6: =[1]PERS!AZ14 -> A | F6: =[1]PERS!R14 -> A | G6: =[1]PERS!AL14 -> A | H6: =[1]PERS!BA14 -> A | I6: =[1]PERS!V14 -> A | J6: =[1]PERS!AP14 -> A | K6: =[1]PERS!BB14 -> A | L6: =[1]PERS!Z14 -> A | M6: =[1]PERS!AT14 -> A | N6: =[1]PERS!BC14 -> A | O6: =[1]PERS!AD14 -> A | P6: =[1]PERS!AX14 -> A | Q6: =[1]PERS!BD14 -> A | R6: =[1]EFIS!N14 -> A | S6: =[1]EFIS!AH14 -> A | T6: =[1]EFIS!AZ14 -> A | U6: =[1]EFIS!R14 -> A | V6: =[1]EFIS!AL14 -> A | W6: =[1]EFIS!BA14 -> A | X6: =[1]EFIS!V14 -> A | Y6: =[1]EFIS!AP14 -> A | Z6: =[1]EFIS!BB14 -> A | AA6: =[1]COMU!N14 -> A | AB6: =[1]COMU!AH14 -> A | AC6: =[1]COMU!AZ14 -> A | AD6: =[1]COMU!R14 -> A | AE6: =[1]COMU!AH14 -> A | AF6: =[1]COMU!BA14 -> A | AG6: =[1]COMU!V14 -> A | AH6: =[1]COMU!AP14 -> A | AI6: =[1]COMU!BB14 -> A | AJ6: =[1]ARTE!N14 -> A | AK6: =[1]ARTE!AH14 -> A | AL6: =[1]ARTE!AZ14 -> A | AM6: =[1]ARTE!R14 -> A | AN6: =[1]ARTE!AL14 -> A | AO6: =[1]ARTE!BA14 -> A | AP6: =[1]ING!N14 -> A | AQ6: =[1]ING!AH14 -> A | AR6: =[1]ING!AZ14 -> A | AS6: =[1]ING!R14 -> A | AT6: =[1]ING!AL14 -> A | AU6: =[1]ING!BA14 -> A | AV6: =[1]ING!V14 -> A | AW6: =[1]ING!AP14 -> A | AX6: =[1]ING!BB14 -> A | AY6: =[1]MATE!N14 -> A | AZ6: =[1]MATE!AH14 -> B | BA6: =[1]MATE!AZ14 -> A | BB6: =[1]MATE!R14 -> A | BC6: =[1]MATE!AL14 -> A | BD6: =[1]MATE!BA14 -> A | BE6: =[1]MATE!V14 -> A | BF6: =[1]MATE!AP14 -> B | BG6: =[1]MATE!BB14 -> A | BH6: =[1]MATE!Z14 -> A | BI6: =[1]MATE!AT14 -> A | BJ6: =[1]MATE!BC14 -> A | BK6: =[1]CTEC!N14 -> A | BL6: =[1]CTEC!AH14 -> B | BM6: =[1]CTEC!AZ14 -> A | BN6: =[1]CTEC!R14 -> A | BO6: =[1]CTEC!AL14 -> A | BP6: =[1]CTEC!BA14 -> A | BQ6: =[1]CTEC!V14 -> A | BR6: =[1]CTEC!AP14 -> A | BS6: =[1]CTEC!BB14 -> A | BT6: =[1]REL!N14 -> A | BU6: =[1]REL!AH14 -> A | BV6: =[1]REL!AZ14 -> A | BW6: =[1]REL!R14 -> A | BX6: =[1]REL!AL14 -> A | BY6: =[1]REL!BA14 -> A | BZ6: =[1]EMPR!N14 -> A | CA6: =[1]EMPR!AH14 -> A | CB6: =[1]EMPR!AZ14 -> A | CC6: =[1]COMPU!N14 -> A | CD6: =[1]COMPU!AH14 -> A | CE6: =[1]COMPU!AZ14 -> A | CF6: =[1]ROBOTI!N14 -> A | CG6: =[1]ROBOTI!AH14 -> A | CH6: =[1]ROBOTI!AZ14 -> A | CI6: =[1]APREPER!AL13 -> A | CJ6: =[1]APREPER!AM13 -> A | CK6: =[1]APREPER!I13 -> X | CL6: =[1]APREPER!J13 -> 0 | CM6: =[1]APREPER!K13 -> 0 | CN6: =[1]APREPER!L13 -> 0 | CO6: =[1]APREPER!M13 -> X | CP6: =[1]APREPER!N13 -> 0 | CQ6: =[1]APREPER!O13 -> X | CR6: =[1]APREPER!P13 -> 0 | ... DL6: =[1]APREPER!AJ13 -> A | DM6: =[1]APREPPFF!I13 -> X | DN6: =[1]APREPPFF!J13 -> 0 | DO6: =[1]APREPPFF!K13 -> 0 | DP6: =[1]APREPPFF!L13 -> X | DQ6: =[1]APREPPFF!M13 -> 0 | DR6: =[1]APREPPFF!N13 -> 0 | DS6: =[1]APREPPFF!O13 -> X | DT6: =[1]APREPPFF!P13 -> 0 | ... DY6: =[1]APREPPFF!U13 -> A | DZ6: =[1]ASISTEN!$BS$4 -> 47 | EA6: =[1]ASISTEN!BT14 -> 1 | EB6: =[1]ASISTEN!BP14 -> 33 | EC6: =[1]ASISTEN!BQ14 -> 13 | ED6: =[1]ASISTEN!BR14 -> 1 | EE6: =[1]ASISTEN!BS14 -> 0 | EF6: =[1]APREPER!AN13 -> Mantiene un rendimiento satisfactorio en todas las competencias evaluadas, demostrando responsabilidad, compromiso y un adecuado desarrollo de sus aprendizajes. | EG6: =((EJ6*3)+(EK6*2)+(EL6*1)) -> 169 | EH6: =RANK(EG6,$EG$5:$EG$32,0) -> 7 | EJ6: =COUNTIF(C6:CJ6,"AD") -> 0 | EK6: =COUNTIF(C6:CJ6,"A") -> 83 | EL6: =COUNTIF(C6:CJ6,"B") -> 3
A7: 3 | B7: CHALCO HEREDIA SHJENKA KATALEYA | C7: =[1]PERS!N15 -> A | D7: =[1]PERS!AH15 -> A | E7: =[1]PERS!AZ15 -> A | F7: =[1]PERS!R15 -> A | G7: =[1]PERS!AL15 -> A | H7: =[1]PERS!BA15 -> A | I7: =[1]PERS!V15 -> B | J7: =[1]PERS!AP15 -> B | K7: =[1]PERS!BB15 -> B | L7: =[1]PERS!Z15 -> A | M7: =[1]PERS!AT15 -> A | N7: =[1]PERS!BC15 -> A | O7: =[1]PERS!AD15 -> A | P7: =[1]PERS!AX15 -> A | Q7: =[1]PERS!BD15 -> A | R7: =[1]EFIS!N15 -> AD | S7: =[1]EFIS!AH15 -> A | T7: =[1]EFIS!AZ15 -> AD | U7: =[1]EFIS!R15 -> A | V7: =[1]EFIS!AL15 -> A | W7: =[1]EFIS!BA15 -> A | X7: =[1]EFIS!V15 -> A | Y7: =[1]EFIS!AP15 -> A | Z7: =[1]EFIS!BB15 -> A | AA7: =[1]COMU!N15 -> A | AB7: =[1]COMU!AH15 -> A | AC7: =[1]COMU!AZ15 -> A | AD7: =[1]COMU!R15 -> A | AE7: =[1]COMU!AH15 -> A | AF7: =[1]COMU!BA15 -> A | AG7: =[1]COMU!V15 -> A | AH7: =[1]COMU!AP15 -> A | AI7: =[1]COMU!BB15 -> A | AJ7: =[1]ARTE!N15 -> A | AK7: =[1]ARTE!AH15 -> A | AL7: =[1]ARTE!AZ15 -> A | AM7: =[1]ARTE!R15 -> A | AN7: =[1]ARTE!AL15 -> A | AO7: =[1]ARTE!BA15 -> A | AP7: =[1]ING!N15 -> A | AQ7: =[1]ING!AH15 -> A | AR7: =[1]ING!AZ15 -> A | AS7: =[1]ING!R15 -> B | AT7: =[1]ING!AL15 -> A | AU7: =[1]ING!BA15 -> A | AV7: =[1]ING!V15 -> A | AW7: =[1]ING!AP15 -> A | AX7: =[1]ING!BB15 -> A | AY7: =[1]MATE!N15 -> B | AZ7: =[1]MATE!AH15 -> B | BA7: =[1]MATE!AZ15 -> B | BB7: =[1]MATE!R15 -> A | BC7: =[1]MATE!AL15 -> A | BD7: =[1]MATE!BA15 -> A | BE7: =[1]MATE!V15 -> A | BF7: =[1]MATE!AP15 -> B | BG7: =[1]MATE!BB15 -> A | BH7: =[1]MATE!Z15 -> A | BI7: =[1]MATE!AT15 -> A | BJ7: =[1]MATE!BC15 -> A | BK7: =[1]CTEC!N15 -> B | BL7: =[1]CTEC!AH15 -> A | BM7: =[1]CTEC!AZ15 -> A | BN7: =[1]CTEC!R15 -> B | BO7: =[1]CTEC!AL15 -> A | BP7: =[1]CTEC!BA15 -> A | BQ7: =[1]CTEC!V15 -> A | BR7: =[1]CTEC!AP15 -> A | BS7: =[1]CTEC!BB15 -> A | BT7: =[1]REL!N15 -> A | BU7: =[1]REL!AH15 -> A | BV7: =[1]REL!AZ15 -> A | BW7: =[1]REL!R15 -> A | BX7: =[1]REL!AL15 -> AD | BY7: =[1]REL!BA15 -> AD | BZ7: =[1]EMPR!N15 -> A | CA7: =[1]EMPR!AH15 -> A | CB7: =[1]EMPR!AZ15 -> A | CC7: =[1]COMPU!N15 -> A | CD7: =[1]COMPU!AH15 -> A | CE7: =[1]COMPU!AZ15 -> A | CF7: =[1]ROBOTI!N15 -> A | CG7: =[1]ROBOTI!AH15 -> A | CH7: =[1]ROBOTI!AZ15 -> A | CI7: =[1]APREPER!AL14 -> A | CJ7: =[1]APREPER!AM14 -> A | CK7: =[1]APREPER!I14 -> X | CL7: =[1]APREPER!J14 -> 0 | CM7: =[1]APREPER!K14 -> 0 | CN7: =[1]APREPER!L14 -> 0 | CO7: =[1]APREPER!M14 -> X | CP7: =[1]APREPER!N14 -> 0 | CQ7: =[1]APREPER!O14 -> X | CR7: =[1]APREPER!P14 -> 0 | ... DL7: =[1]APREPER!AJ14 -> A | DM7: =[1]APREPPFF!I14 -> X | DN7: =[1]APREPPFF!J14 -> 0 | DO7: =[1]APREPPFF!K14 -> 0 | DP7: =[1]APREPPFF!L14 -> X | DQ7: =[1]APREPPFF!M14 -> 0 | DR7: =[1]APREPPFF!N14 -> 0 | DS7: =[1]APREPPFF!O14 -> 0 | DT7: =[1]APREPPFF!P14 -> X | ... DY7: =[1]APREPPFF!U14 -> A | DZ7: =[1]ASISTEN!$BS$4 -> 47 | EA7: =[1]ASISTEN!BT15 -> 1 | EB7: =[1]ASISTEN!BP15 -> 44 | EC7: =[1]ASISTEN!BQ15 -> 3 | ED7: =[1]ASISTEN!BR15 -> 0 | EE7: =[1]ASISTEN!BS15 -> 0 | EF7: =[1]APREPER!AN14 -> Ha logrado avances importantes en varias competencias; sin embargo, aún requiere fortalecer algunos aprendizajes para alcanzar un desempeño más uniforme y seguro. | EG7: =((EJ7*3)+(EK7*2)+(EL7*1)) -> 166 | EH7: =RANK(EG7,$EG$5:$EG$32,0) -> 11 | EJ7: =COUNTIF(C7:CJ7,"AD") -> 4 | EK7: =COUNTIF(C7:CJ7,"A") -> 72 | EL7: =COUNTIF(C7:CJ7,"B") -> 10
A8: 4 | B8: CHARA MAMANI NAHUEL HAGEN | C8: =[1]PERS!N16 -> A | D8: =[1]PERS!AH16 -> A | E8: =[1]PERS!AZ16 -> A | F8: =[1]PERS!R16 -> A | G8: =[1]PERS!AL16 -> A | H8: =[1]PERS!BA16 -> A | I8: =[1]PERS!V16 -> A | J8: =[1]PERS!AP16 -> A | K8: =[1]PERS!BB16 -> A | L8: =[1]PERS!Z16 -> A | M8: =[1]PERS!AT16 -> A | N8: =[1]PERS!BC16 -> A | O8: =[1]PERS!AD16 -> A | P8: =[1]PERS!AX16 -> A | Q8: =[1]PERS!BD16 -> A | R8: =[1]EFIS!N16 -> A | S8: =[1]EFIS!AH16 -> A | T8: =[1]EFIS!AZ16 -> A | U8: =[1]EFIS!R16 -> A | V8: =[1]EFIS!AL16 -> A | W8: =[1]EFIS!BA16 -> A | X8: =[1]EFIS!V16 -> A | Y8: =[1]EFIS!AP16 -> A | Z8: =[1]EFIS!BB16 -> A | AA8: =[1]COMU!N16 -> A | AB8: =[1]COMU!AH16 -> A | AC8: =[1]COMU!AZ16 -> A | AD8: =[1]COMU!R16 -> A | AE8: =[1]COMU!AH16 -> A | AF8: =[1]COMU!BA16 -> A | AG8: =[1]COMU!V16 -> A | AH8: =[1]COMU!AP16 -> A | AI8: =[1]COMU!BB16 -> A | AJ8: =[1]ARTE!N16 -> A | AK8: =[1]ARTE!AH16 -> A | AL8: =[1]ARTE!AZ16 -> A | AM8: =[1]ARTE!R16 -> A | AN8: =[1]ARTE!AL16 -> A | AO8: =[1]ARTE!BA16 -> A | AP8: =[1]ING!N16 -> A | AQ8: =[1]ING!AH16 -> A | AR8: =[1]ING!AZ16 -> A | AS8: =[1]ING!R16 -> A | AT8: =[1]ING!AL16 -> A | AU8: =[1]ING!BA16 -> A | AV8: =[1]ING!V16 -> A | AW8: =[1]ING!AP16 -> A | AX8: =[1]ING!BB16 -> A | AY8: =[1]MATE!N16 -> A | AZ8: =[1]MATE!AH16 -> A | BA8: =[1]MATE!AZ16 -> A | BB8: =[1]MATE!R16 -> A | BC8: =[1]MATE!AL16 -> A | BD8: =[1]MATE!BA16 -> A | BE8: =[1]MATE!V16 -> A | BF8: =[1]MATE!AP16 -> A | BG8: =[1]MATE!BB16 -> A | BH8: =[1]MATE!Z16 -> A | BI8: =[1]MATE!AT16 -> A | BJ8: =[1]MATE!BC16 -> A | BK8: =[1]CTEC!N16 -> A | BL8: =[1]CTEC!AH16 -> A | BM8: =[1]CTEC!AZ16 -> A | BN8: =[1]CTEC!R16 -> A | BO8: =[1]CTEC!AL16 -> A | BP8: =[1]CTEC!BA16 -> A | BQ8: =[1]CTEC!V16 -> A | BR8: =[1]CTEC!AP16 -> A | BS8: =[1]CTEC!BB16 -> A | BT8: =[1]REL!N16 -> A | BU8: =[1]REL!AH16 -> A | BV8: =[1]REL!AZ16 -> A | BW8: =[1]REL!R16 -> A | BX8: =[1]REL!AL16 -> AD | BY8: =[1]REL!BA16 -> AD | BZ8: =[1]EMPR!N16 -> A | CA8: =[1]EMPR!AH16 -> A | CB8: =[1]EMPR!AZ16 -> A | CC8: =[1]COMPU!N16 -> A | CD8: =[1]COMPU!AH16 -> A | CE8: =[1]COMPU!AZ16 -> A | CF8: =[1]ROBOTI!N16 -> A | CG8: =[1]ROBOTI!AH16 -> A | CH8: =[1]ROBOTI!AZ16 -> A | CI8: =[1]APREPER!AL15 -> A | CJ8: =[1]APREPER!AM15 -> A | CK8: =[1]APREPER!I15 -> X | CL8: =[1]APREPER!J15 -> 0 | CM8: =[1]APREPER!K15 -> 0 | CN8: =[1]APREPER!L15 -> X | CO8: =[1]APREPER!M15 -> 0 | CP8: =[1]APREPER!N15 -> 0 | CQ8: =[1]APREPER!O15 -> X | CR8: =[1]APREPER!P15 -> 0 | ... DL8: =[1]APREPER!AJ15 -> A | DM8: =[1]APREPPFF!I15 -> X | DN8: =[1]APREPPFF!J15 -> 0 | DO8: =[1]APREPPFF!K15 -> 0 | DP8: =[1]APREPPFF!L15 -> X | DQ8: =[1]APREPPFF!M15 -> 0 | DR8: =[1]APREPPFF!N15 -> 0 | DS8: =[1]APREPPFF!O15 -> X | DT8: =[1]APREPPFF!P15 -> 0 | ... DY8: =[1]APREPPFF!U15 -> A | DZ8: =[1]ASISTEN!$BS$4 -> 47 | EA8: =[1]ASISTEN!BT16 -> 1 | EB8: =[1]ASISTEN!BP16 -> 47 | EC8: =[1]ASISTEN!BQ16 -> 0 | ED8: =[1]ASISTEN!BR16 -> 0 | EE8: =[1]ASISTEN!BS16 -> 0 | EF8: =[1]APREPER!AN15 -> Evidencia un desempeño destacado en diversas competencias, alcanzando con solvencia los logros esperados y sobresaliendo por su participación y dedicación constante. | EG8: =((EJ8*3)+(EK8*2)+(EL8*1)) -> 174 | EH8: =RANK(EG8,$EG$5:$EG$32,0) -> 2 | EJ8: =COUNTIF(C8:CJ8,"AD") -> 2 | EK8: =COUNTIF(C8:CJ8,"A") -> 84 | EL8: =COUNTIF(C8:CJ8,"B") -> 0
A9: 5 | B9: COAQUIRA FERNANDEZ RASECK LUCIO LYZER | C9: =[1]PERS!N17 -> C | D9: =[1]PERS!AH17 -> A | E9: =[1]PERS!AZ17 -> B | F9: =[1]PERS!R17 -> A | G9: =[1]PERS!AL17 -> A | H9: =[1]PERS!BA17 -> A | I9: =[1]PERS!V17 -> B | J9: =[1]PERS!AP17 -> B | K9: =[1]PERS!BB17 -> B | L9: =[1]PERS!Z17 -> A | M9: =[1]PERS!AT17 -> A | N9: =[1]PERS!BC17 -> A | O9: =[1]PERS!AD17 -> A | P9: =[1]PERS!AX17 -> B | Q9: =[1]PERS!BD17 -> A | R9: =[1]EFIS!N17 -> A | S9: =[1]EFIS!AH17 -> A | T9: =[1]EFIS!AZ17 -> A | U9: =[1]EFIS!R17 -> A | V9: =[1]EFIS!AL17 -> A | W9: =[1]EFIS!BA17 -> A | X9: =[1]EFIS!V17 -> A | Y9: =[1]EFIS!AP17 -> A | Z9: =[1]EFIS!BB17 -> A | AA9: =[1]COMU!N17 -> B | AB9: =[1]COMU!AH17 -> B | AC9: =[1]COMU!AZ17 -> B | AD9: =[1]COMU!R17 -> B | AE9: =[1]COMU!AH17 -> B | AF9: =[1]COMU!BA17 -> B | AG9: =[1]COMU!V17 -> B | AH9: =[1]COMU!AP17 -> B | AI9: =[1]COMU!BB17 -> B | AJ9: =[1]ARTE!N17 -> A | AK9: =[1]ARTE!AH17 -> A | AL9: =[1]ARTE!AZ17 -> A | AM9: =[1]ARTE!R17 -> A | AN9: =[1]ARTE!AL17 -> A | AO9: =[1]ARTE!BA17 -> A | AP9: =[1]ING!N17 -> A | AQ9: =[1]ING!AH17 -> A | AR9: =[1]ING!AZ17 -> A | AS9: =[1]ING!R17 -> B | AT9: =[1]ING!AL17 -> B | AU9: =[1]ING!BA17 -> B | AV9: =[1]ING!V17 -> A | AW9: =[1]ING!AP17 -> B | AX9: =[1]ING!BB17 -> A | AY9: =[1]MATE!N17 -> B | AZ9: =[1]MATE!AH17 -> C | BA9: =[1]MATE!AZ17 -> B | BB9: =[1]MATE!R17 -> A | BC9: =[1]MATE!AL17 -> A | BD9: =[1]MATE!BA17 -> A | BE9: =[1]MATE!V17 -> A | BF9: =[1]MATE!AP17 -> A | BG9: =[1]MATE!BB17 -> A | BH9: =[1]MATE!Z17 -> A | BI9: =[1]MATE!AT17 -> A | BJ9: =[1]MATE!BC17 -> A | BK9: =[1]CTEC!N17 -> B | BL9: =[1]CTEC!AH17 -> B | BM9: =[1]CTEC!AZ17 -> B | BN9: =[1]CTEC!R17 -> A | BO9: =[1]CTEC!AL17 -> A | BP9: =[1]CTEC!BA17 -> A | BQ9: =[1]CTEC!V17 -> B | BR9: =[1]CTEC!AP17 -> B | BS9: =[1]CTEC!BB17 -> B | BT9: =[1]REL!N17 -> A | BU9: =[1]REL!AH17 -> A | BV9: =[1]REL!AZ17 -> A | BW9: =[1]REL!R17 -> A | BX9: =[1]REL!AL17 -> A | BY9: =[1]REL!BA17 -> A | BZ9: =[1]EMPR!N17 -> A | CA9: =[1]EMPR!AH17 -> B | CB9: =[1]EMPR!AZ17 -> A | CC9: =[1]COMPU!N17 -> A | CD9: =[1]COMPU!AH17 -> A | CE9: =[1]COMPU!AZ17 -> A | CF9: =[1]ROBOTI!N17 -> A | CG9: =[1]ROBOTI!AH17 -> A | CH9: =[1]ROBOTI!AZ17 -> A | CI9: =[1]APREPER!AL16 -> A | CJ9: =[1]APREPER!AM16 -> A | CK9: =[1]APREPER!I16 -> X | CL9: =[1]APREPER!J16 -> 0 | CM9: =[1]APREPER!K16 -> 0 | CN9: =[1]APREPER!L16 -> X | CO9: =[1]APREPER!M16 -> 0 | CP9: =[1]APREPER!N16 -> 0 | CQ9: =[1]APREPER!O16 -> 0 | CR9: =[1]APREPER!P16 -> X | ... DL9: =[1]APREPER!AJ16 -> A | DM9: =[1]APREPPFF!I16 -> 0 | DN9: =[1]APREPPFF!J16 -> X | DO9: =[1]APREPPFF!K16 -> 0 | DP9: =[1]APREPPFF!L16 -> X | DQ9: =[1]APREPPFF!M16 -> 0 | DR9: =[1]APREPPFF!N16 -> 0 | DS9: =[1]APREPPFF!O16 -> X | DT9: =[1]APREPPFF!P16 -> 0 | ... DY9: =[1]APREPPFF!U16 -> A | DZ9: =[1]ASISTEN!$BS$4 -> 47 | EA9: =[1]ASISTEN!BT17 -> 1 | EB9: =[1]ASISTEN!BP17 -> 45 | EC9: =[1]ASISTEN!BQ17 -> 2 | ED9: =[1]ASISTEN!BR17 -> 0 | EE9: =[1]ASISTEN!BS17 -> 0 | EF9: =[1]APREPER!AN16 -> Requiere mayor esfuerzo y compromiso en sus actividades escolares, ya que la mayoría de competencias aún se encuentran en proceso y demandan atención continua. | EG9: =((EJ9*3)+(EK9*2)+(EL9*1)) -> 141 | EH9: =RANK(EG9,$EG$5:$EG$32,0) -> 23 | EJ9: =COUNTIF(C9:CJ9,"AD") -> 0 | EK9: =COUNTIF(C9:CJ9,"A") -> 57 | EL9: =COUNTIF(C9:CJ9,"B") -> 27
A10: 6 | B10: CONDORI QUISPE JOSSEPH MILAN | C10: =[1]PERS!N18 -> A | D10: =[1]PERS!AH18 -> B | E10: =[1]PERS!AZ18 -> A | F10: =[1]PERS!R18 -> A | G10: =[1]PERS!AL18 -> A | H10: =[1]PERS!BA18 -> A | I10: =[1]PERS!V18 -> A | J10: =[1]PERS!AP18 -> A | K10: =[1]PERS!BB18 -> A | L10: =[1]PERS!Z18 -> A | M10: =[1]PERS!AT18 -> A | N10: =[1]PERS!BC18 -> A | O10: =[1]PERS!AD18 -> A | P10: =[1]PERS!AX18 -> A | Q10: =[1]PERS!BD18 -> A | R10: =[1]EFIS!N18 -> A | S10: =[1]EFIS!AH18 -> A | T10: =[1]EFIS!AZ18 -> A | U10: =[1]EFIS!R18 -> A | V10: =[1]EFIS!AL18 -> A | W10: =[1]EFIS!BA18 -> A | X10: =[1]EFIS!V18 -> A | Y10: =[1]EFIS!AP18 -> A | Z10: =[1]EFIS!BB18 -> A | AA10: =[1]COMU!N18 -> A | AB10: =[1]COMU!AH18 -> A | AC10: =[1]COMU!AZ18 -> A | AD10: =[1]COMU!R18 -> A | AE10: =[1]COMU!AH18 -> A | AF10: =[1]COMU!BA18 -> A | AG10: =[1]COMU!V18 -> A | AH10: =[1]COMU!AP18 -> A | AI10: =[1]COMU!BB18 -> A | AJ10: =[1]ARTE!N18 -> A | AK10: =[1]ARTE!AH18 -> A | AL10: =[1]ARTE!AZ18 -> A | AM10: =[1]ARTE!R18 -> A | AN10: =[1]ARTE!AL18 -> A | AO10: =[1]ARTE!BA18 -> A | AP10: =[1]ING!N18 -> A | AQ10: =[1]ING!AH18 -> A | AR10: =[1]ING!AZ18 -> A | AS10: =[1]ING!R18 -> A | AT10: =[1]ING!AL18 -> A | AU10: =[1]ING!BA18 -> A | AV10: =[1]ING!V18 -> A | AW10: =[1]ING!AP18 -> A | AX10: =[1]ING!BB18 -> A | AY10: =[1]MATE!N18 -> A | AZ10: =[1]MATE!AH18 -> B | BA10: =[1]MATE!AZ18 -> A | BB10: =[1]MATE!R18 -> A | BC10: =[1]MATE!AL18 -> A | BD10: =[1]MATE!BA18 -> A | BE10: =[1]MATE!V18 -> A | BF10: =[1]MATE!AP18 -> C | BG10: =[1]MATE!BB18 -> B | BH10: =[1]MATE!Z18 -> A | BI10: =[1]MATE!AT18 -> A | BJ10: =[1]MATE!BC18 -> A | BK10: =[1]CTEC!N18 -> B | BL10: =[1]CTEC!AH18 -> A | BM10: =[1]CTEC!AZ18 -> A | BN10: =[1]CTEC!R18 -> A | BO10: =[1]CTEC!AL18 -> A | BP10: =[1]CTEC!BA18 -> A | BQ10: =[1]CTEC!V18 -> A | BR10: =[1]CTEC!AP18 -> A | BS10: =[1]CTEC!BB18 -> A | BT10: =[1]REL!N18 -> A | BU10: =[1]REL!AH18 -> A | BV10: =[1]REL!AZ18 -> A | BW10: =[1]REL!R18 -> A | BX10: =[1]REL!AL18 -> A | BY10: =[1]REL!BA18 -> A | BZ10: =[1]EMPR!N18 -> A | CA10: =[1]EMPR!AH18 -> A | CB10: =[1]EMPR!AZ18 -> A | CC10: =[1]COMPU!N18 -> A | CD10: =[1]COMPU!AH18 -> A | CE10: =[1]COMPU!AZ18 -> A | CF10: =[1]ROBOTI!N18 -> A | CG10: =[1]ROBOTI!AH18 -> A | CH10: =[1]ROBOTI!AZ18 -> A | CI10: =[1]APREPER!AL17 -> A | CJ10: =[1]APREPER!AM17 -> A | CK10: =[1]APREPER!I17 -> X | CL10: =[1]APREPER!J17 -> 0 | CM10: =[1]APREPER!K17 -> 0 | CN10: =[1]APREPER!L17 -> 0 | CO10: =[1]APREPER!M17 -> X | CP10: =[1]APREPER!N17 -> 0 | CQ10: =[1]APREPER!O17 -> X | CR10: =[1]APREPER!P17 -> 0 | ... DL10: =[1]APREPER!AJ17 -> A | DM10: =[1]APREPPFF!I17 -> 0 | DN10: =[1]APREPPFF!J17 -> X | DO10: =[1]APREPPFF!K17 -> 0 | DP10: =[1]APREPPFF!L17 -> 0 | DQ10: =[1]APREPPFF!M17 -> X | DR10: =[1]APREPPFF!N17 -> 0 | DS10: =[1]APREPPFF!O17 -> X | DT10: =[1]APREPPFF!P17 -> 0 | ... DY10: =[1]APREPPFF!U17 -> B | DZ10: =[1]ASISTEN!$BS$4 -> 47 | EA10: =[1]ASISTEN!BT18 -> 1 | EB10: =[1]ASISTEN!BP18 -> 40 | EC10: =[1]ASISTEN!BQ18 -> 7 | ED10: =[1]ASISTEN!BR18 -> 0 | EE10: =[1]ASISTEN!BS18 -> 0 | EF10: =[1]APREPER!AN17 -> Ha logrado avances importantes en varias competencias; sin embargo, aún requiere fortalecer algunos aprendizajes para alcanzar un desempeño más uniforme y seguro. | EG10: =((EJ10*3)+(EK10*2)+(EL10*1)) -> 166 | EH10: =RANK(EG10,$EG$5:$EG$32,0) -> 11 | EJ10: =COUNTIF(C10:CJ10,"AD") -> 0 | EK10: =COUNTIF(C10:CJ10,"A") -> 81 | EL10: =COUNTIF(C10:CJ10,"B") -> 4
A11: 7 | B11: CORNEJO CHALLO JAZAEL RICHARTH | C11: =[1]PERS!N19 -> A | D11: =[1]PERS!AH19 -> A | E11: =[1]PERS!AZ19 -> A | F11: =[1]PERS!R19 -> A | G11: =[1]PERS!AL19 -> A | H11: =[1]PERS!BA19 -> A | I11: =[1]PERS!V19 -> A | J11: =[1]PERS!AP19 -> A | K11: =[1]PERS!BB19 -> A | L11: =[1]PERS!Z19 -> A | M11: =[1]PERS!AT19 -> A | N11: =[1]PERS!BC19 -> A | O11: =[1]PERS!AD19 -> A | P11: =[1]PERS!AX19 -> A | Q11: =[1]PERS!BD19 -> A | R11: =[1]EFIS!N19 -> A | S11: =[1]EFIS!AH19 -> A | T11: =[1]EFIS!AZ19 -> A | U11: =[1]EFIS!R19 -> A | V11: =[1]EFIS!AL19 -> A | W11: =[1]EFIS!BA19 -> A | X11: =[1]EFIS!V19 -> A | Y11: =[1]EFIS!AP19 -> A | Z11: =[1]EFIS!BB19 -> A | AA11: =[1]COMU!N19 -> A | AB11: =[1]COMU!AH19 -> A | AC11: =[1]COMU!AZ19 -> A | AD11: =[1]COMU!R19 -> A | AE11: =[1]COMU!AH19 -> A | AF11: =[1]COMU!BA19 -> A | AG11: =[1]COMU!V19 -> A | AH11: =[1]COMU!AP19 -> A | AI11: =[1]COMU!BB19 -> A | AJ11: =[1]ARTE!N19 -> A | AK11: =[1]ARTE!AH19 -> A | AL11: =[1]ARTE!AZ19 -> A | AM11: =[1]ARTE!R19 -> A | AN11: =[1]ARTE!AL19 -> A | AO11: =[1]ARTE!BA19 -> A | AP11: =[1]ING!N19 -> A | AQ11: =[1]ING!AH19 -> A | AR11: =[1]ING!AZ19 -> A | AS11: =[1]ING!R19 -> A | AT11: =[1]ING!AL19 -> B | AU11: =[1]ING!BA19 -> A | AV11: =[1]ING!V19 -> A | AW11: =[1]ING!AP19 -> A | AX11: =[1]ING!BB19 -> A | AY11: =[1]MATE!N19 -> A | AZ11: =[1]MATE!AH19 -> B | BA11: =[1]MATE!AZ19 -> A | BB11: =[1]MATE!R19 -> A | BC11: =[1]MATE!AL19 -> A | BD11: =[1]MATE!BA19 -> A | BE11: =[1]MATE!V19 -> A | BF11: =[1]MATE!AP19 -> B | BG11: =[1]MATE!BB19 -> A | BH11: =[1]MATE!Z19 -> A | BI11: =[1]MATE!AT19 -> A | BJ11: =[1]MATE!BC19 -> A | BK11: =[1]CTEC!N19 -> A | BL11: =[1]CTEC!AH19 -> B | BM11: =[1]CTEC!AZ19 -> A | BN11: =[1]CTEC!R19 -> A | BO11: =[1]CTEC!AL19 -> A | BP11: =[1]CTEC!BA19 -> A | BQ11: =[1]CTEC!V19 -> A | BR11: =[1]CTEC!AP19 -> B | BS11: =[1]CTEC!BB19 -> A | BT11: =[1]REL!N19 -> A | BU11: =[1]REL!AH19 -> A | BV11: =[1]REL!AZ19 -> A | BW11: =[1]REL!R19 -> A | BX11: =[1]REL!AL19 -> A | BY11: =[1]REL!BA19 -> A | BZ11: =[1]EMPR!N19 -> A | CA11: =[1]EMPR!AH19 -> A | CB11: =[1]EMPR!AZ19 -> A | CC11: =[1]COMPU!N19 -> A | CD11: =[1]COMPU!AH19 -> A | CE11: =[1]COMPU!AZ19 -> A | CF11: =[1]ROBOTI!N19 -> A | CG11: =[1]ROBOTI!AH19 -> A | CH11: =[1]ROBOTI!AZ19 -> A | CI11: =[1]APREPER!AL18 -> A | CJ11: =[1]APREPER!AM18 -> A | CK11: =[1]APREPER!I18 -> X | CL11: =[1]APREPER!J18 -> 0 | CM11: =[1]APREPER!K18 -> 0 | CN11: =[1]APREPER!L18 -> X | CO11: =[1]APREPER!M18 -> 0 | CP11: =[1]APREPER!N18 -> 0 | CQ11: =[1]APREPER!O18 -> X | CR11: =[1]APREPER!P18 -> 0 | ... DL11: =[1]APREPER!AJ18 -> A | DM11: =[1]APREPPFF!I18 -> X | DN11: =[1]APREPPFF!J18 -> 0 | DO11: =[1]APREPPFF!K18 -> 0 | DP11: =[1]APREPPFF!L18 -> X | DQ11: =[1]APREPPFF!M18 -> 0 | DR11: =[1]APREPPFF!N18 -> 0 | DS11: =[1]APREPPFF!O18 -> X | DT11: =[1]APREPPFF!P18 -> 0 | ... DY11: =[1]APREPPFF!U18 -> A | DZ11: =[1]ASISTEN!$BS$4 -> 47 | EA11: =[1]ASISTEN!BT19 -> 1 | EB11: =[1]ASISTEN!BP19 -> 47 | EC11: =[1]ASISTEN!BQ19 -> 0 | ED11: =[1]ASISTEN!BR19 -> 0 | EE11: =[1]ASISTEN!BS19 -> 0 | EF11: =[1]APREPER!AN18 -> Mantiene un rendimiento satisfactorio en todas las competencias evaluadas, demostrando responsabilidad, compromiso y un adecuado desarrollo de sus aprendizajes. | EG11: =((EJ11*3)+(EK11*2)+(EL11*1)) -> 167 | EH11: =RANK(EG11,$EG$5:$EG$32,0) -> 9 | EJ11: =COUNTIF(C11:CJ11,"AD") -> 0 | EK11: =COUNTIF(C11:CJ11,"A") -> 81 | EL11: =COUNTIF(C11:CJ11,"B") -> 5
A12: 8 | B12: CURO GARCÍA ADRIANA YESENIA | C12: =[1]PERS!N20 -> A | D12: =[1]PERS!AH20 -> A | E12: =[1]PERS!AZ20 -> A | F12: =[1]PERS!R20 -> A | G12: =[1]PERS!AL20 -> A | H12: =[1]PERS!BA20 -> A | I12: =[1]PERS!V20 -> B | J12: =[1]PERS!AP20 -> B | K12: =[1]PERS!BB20 -> B | L12: =[1]PERS!Z20 -> A | M12: =[1]PERS!AT20 -> A | N12: =[1]PERS!BC20 -> A | O12: =[1]PERS!AD20 -> A | P12: =[1]PERS!AX20 -> A | Q12: =[1]PERS!BD20 -> A | R12: =[1]EFIS!N20 -> A | S12: =[1]EFIS!AH20 -> A | T12: =[1]EFIS!AZ20 -> A | U12: =[1]EFIS!R20 -> A | V12: =[1]EFIS!AL20 -> A | W12: =[1]EFIS!BA20 -> A | X12: =[1]EFIS!V20 -> A | Y12: =[1]EFIS!AP20 -> A | Z12: =[1]EFIS!BB20 -> A | AA12: =[1]COMU!N20 -> A | AB12: =[1]COMU!AH20 -> A | AC12: =[1]COMU!AZ20 -> A | AD12: =[1]COMU!R20 -> A | AE12: =[1]COMU!AH20 -> A | AF12: =[1]COMU!BA20 -> A | AG12: =[1]COMU!V20 -> B | AH12: =[1]COMU!AP20 -> A | AI12: =[1]COMU!BB20 -> A | AJ12: =[1]ARTE!N20 -> A | AK12: =[1]ARTE!AH20 -> A | AL12: =[1]ARTE!AZ20 -> A | AM12: =[1]ARTE!R20 -> A | AN12: =[1]ARTE!AL20 -> A | AO12: =[1]ARTE!BA20 -> A | AP12: =[1]ING!N20 -> A | AQ12: =[1]ING!AH20 -> A | AR12: =[1]ING!AZ20 -> A | AS12: =[1]ING!R20 -> A | AT12: =[1]ING!AL20 -> A | AU12: =[1]ING!BA20 -> A | AV12: =[1]ING!V20 -> A | AW12: =[1]ING!AP20 -> A | AX12: =[1]ING!BB20 -> A | AY12: =[1]MATE!N20 -> A | AZ12: =[1]MATE!AH20 -> A | BA12: =[1]MATE!AZ20 -> A | BB12: =[1]MATE!R20 -> A | BC12: =[1]MATE!AL20 -> A | BD12: =[1]MATE!BA20 -> A | BE12: =[1]MATE!V20 -> A | BF12: =[1]MATE!AP20 -> A | BG12: =[1]MATE!BB20 -> A | BH12: =[1]MATE!Z20 -> A | BI12: =[1]MATE!AT20 -> A | BJ12: =[1]MATE!BC20 -> A | BK12: =[1]CTEC!N20 -> B | BL12: =[1]CTEC!AH20 -> A | BM12: =[1]CTEC!AZ20 -> A | BN12: =[1]CTEC!R20 -> A | BO12: =[1]CTEC!AL20 -> A | BP12: =[1]CTEC!BA20 -> A | BQ12: =[1]CTEC!V20 -> B | BR12: =[1]CTEC!AP20 -> A | BS12: =[1]CTEC!BB20 -> A | BT12: =[1]REL!N20 -> A | BU12: =[1]REL!AH20 -> A | BV12: =[1]REL!AZ20 -> A | BW12: =[1]REL!R20 -> A | BX12: =[1]REL!AL20 -> A | BY12: =[1]REL!BA20 -> A | BZ12: =[1]EMPR!N20 -> A | CA12: =[1]EMPR!AH20 -> A | CB12: =[1]EMPR!AZ20 -> A | CC12: =[1]COMPU!N20 -> A | CD12: =[1]COMPU!AH20 -> A | CE12: =[1]COMPU!AZ20 -> A | CF12: =[1]ROBOTI!N20 -> A | CG12: =[1]ROBOTI!AH20 -> A | CH12: =[1]ROBOTI!AZ20 -> A | CI12: =[1]APREPER!AL19 -> A | CJ12: =[1]APREPER!AM19 -> A | CK12: =[1]APREPER!I19 -> X | CL12: =[1]APREPER!J19 -> 0 | CM12: =[1]APREPER!K19 -> 0 | CN12: =[1]APREPER!L19 -> X | CO12: =[1]APREPER!M19 -> 0 | CP12: =[1]APREPER!N19 -> 0 | CQ12: =[1]APREPER!O19 -> X | CR12: =[1]APREPER!P19 -> 0 | ... DL12: =[1]APREPER!AJ19 -> A | DM12: =[1]APREPPFF!I19 -> X | DN12: =[1]APREPPFF!J19 -> 0 | DO12: =[1]APREPPFF!K19 -> 0 | DP12: =[1]APREPPFF!L19 -> X | DQ12: =[1]APREPPFF!M19 -> 0 | DR12: =[1]APREPPFF!N19 -> 0 | DS12: =[1]APREPPFF!O19 -> X | DT12: =[1]APREPPFF!P19 -> 0 | ... DY12: =[1]APREPPFF!U19 -> A | DZ12: =[1]ASISTEN!$BS$4 -> 47 | EA12: =[1]ASISTEN!BT20 -> 1 | EB12: =[1]ASISTEN!BP20 -> 47 | EC12: =[1]ASISTEN!BQ20 -> 0 | ED12: =[1]ASISTEN!BR20 -> 0 | EE12: =[1]ASISTEN!BS20 -> 0 | EF12: =[1]APREPER!AN19 -> Ha logrado avances importantes en varias competencias; sin embargo, aún requiere fortalecer algunos aprendizajes para alcanzar un desempeño más uniforme y seguro. | EG12: =((EJ12*3)+(EK12*2)+(EL12*1)) -> 166 | EH12: =RANK(EG12,$EG$5:$EG$32,0) -> 11 | EJ12: =COUNTIF(C12:CJ12,"AD") -> 0 | EK12: =COUNTIF(C12:CJ12,"A") -> 80 | EL12: =COUNTIF(C12:CJ12,"B") -> 6
A13: 9 | B13: FLORES FERNANDEZ NATHALY YAMILEH | C13: =[1]PERS!N21 -> A | D13: =[1]PERS!AH21 -> A | E13: =[1]PERS!AZ21 -> A | F13: =[1]PERS!R21 -> A | G13: =[1]PERS!AL21 -> A | H13: =[1]PERS!BA21 -> A | I13: =[1]PERS!V21 -> B | J13: =[1]PERS!AP21 -> A | K13: =[1]PERS!BB21 -> A | L13: =[1]PERS!Z21 -> A | M13: =[1]PERS!AT21 -> A | N13: =[1]PERS!BC21 -> A | O13: =[1]PERS!AD21 -> A | P13: =[1]PERS!AX21 -> A | Q13: =[1]PERS!BD21 -> A | R13: =[1]EFIS!N21 -> A | S13: =[1]EFIS!AH21 -> A | T13: =[1]EFIS!AZ21 -> A | U13: =[1]EFIS!R21 -> A | V13: =[1]EFIS!AL21 -> A | W13: =[1]EFIS!BA21 -> A | X13: =[1]EFIS!V21 -> A | Y13: =[1]EFIS!AP21 -> A | Z13: =[1]EFIS!BB21 -> A | AA13: =[1]COMU!N21 -> A | AB13: =[1]COMU!AH21 -> A | AC13: =[1]COMU!AZ21 -> A | AD13: =[1]COMU!R21 -> B | AE13: =[1]COMU!AH21 -> A | AF13: =[1]COMU!BA21 -> B | AG13: =[1]COMU!V21 -> B | AH13: =[1]COMU!AP21 -> A | AI13: =[1]COMU!BB21 -> A | AJ13: =[1]ARTE!N21 -> A | AK13: =[1]ARTE!AH21 -> A | AL13: =[1]ARTE!AZ21 -> A | AM13: =[1]ARTE!R21 -> A | AN13: =[1]ARTE!AL21 -> A | AO13: =[1]ARTE!BA21 -> A | AP13: =[1]ING!N21 -> A | AQ13: =[1]ING!AH21 -> A | AR13: =[1]ING!AZ21 -> A | AS13: =[1]ING!R21 -> A | AT13: =[1]ING!AL21 -> B | AU13: =[1]ING!BA21 -> A | AV13: =[1]ING!V21 -> A | AW13: =[1]ING!AP21 -> A | AX13: =[1]ING!BB21 -> A | AY13: =[1]MATE!N21 -> B | AZ13: =[1]MATE!AH21 -> C | BA13: =[1]MATE!AZ21 -> B | BB13: =[1]MATE!R21 -> A | BC13: =[1]MATE!AL21 -> B | BD13: =[1]MATE!BA21 -> A | BE13: =[1]MATE!V21 -> B | BF13: =[1]MATE!AP21 -> B | BG13: =[1]MATE!BB21 -> B | BH13: =[1]MATE!Z21 -> A | BI13: =[1]MATE!AT21 -> A | BJ13: =[1]MATE!BC21 -> A | BK13: =[1]CTEC!N21 -> A | BL13: =[1]CTEC!AH21 -> A | BM13: =[1]CTEC!AZ21 -> A | BN13: =[1]CTEC!R21 -> A | BO13: =[1]CTEC!AL21 -> B | BP13: =[1]CTEC!BA21 -> A | BQ13: =[1]CTEC!V21 -> A | BR13: =[1]CTEC!AP21 -> A | BS13: =[1]CTEC!BB21 -> A | BT13: =[1]REL!N21 -> A | BU13: =[1]REL!AH21 -> A | BV13: =[1]REL!AZ21 -> A | BW13: =[1]REL!R21 -> A | BX13: =[1]REL!AL21 -> A | BY13: =[1]REL!BA21 -> A | BZ13: =[1]EMPR!N21 -> A | CA13: =[1]EMPR!AH21 -> B | CB13: =[1]EMPR!AZ21 -> A | CC13: =[1]COMPU!N21 -> A | CD13: =[1]COMPU!AH21 -> A | CE13: =[1]COMPU!AZ21 -> A | CF13: =[1]ROBOTI!N21 -> A | CG13: =[1]ROBOTI!AH21 -> A | CH13: =[1]ROBOTI!AZ21 -> A | CI13: =[1]APREPER!AL20 -> A | CJ13: =[1]APREPER!AM20 -> A | CK13: =[1]APREPER!I20 -> X | CL13: =[1]APREPER!J20 -> 0 | CM13: =[1]APREPER!K20 -> 0 | CN13: =[1]APREPER!L20 -> X | CO13: =[1]APREPER!M20 -> 0 | CP13: =[1]APREPER!N20 -> 0 | CQ13: =[1]APREPER!O20 -> X | CR13: =[1]APREPER!P20 -> 0 | ... DL13: =[1]APREPER!AJ20 -> A | DM13: =[1]APREPPFF!I20 -> 0 | DN13: =[1]APREPPFF!J20 -> X | DO13: =[1]APREPPFF!K20 -> 0 | DP13: =[1]APREPPFF!L20 -> X | DQ13: =[1]APREPPFF!M20 -> 0 | DR13: =[1]APREPPFF!N20 -> 0 | DS13: =[1]APREPPFF!O20 -> X | DT13: =[1]APREPPFF!P20 -> 0 | ... DY13: =[1]APREPPFF!U20 -> A | DZ13: =[1]ASISTEN!$BS$4 -> 47 | EA13: =[1]ASISTEN!BT21 -> 1 | EB13: =[1]ASISTEN!BP21 -> 46 | EC13: =[1]ASISTEN!BQ21 -> 1 | ED13: =[1]ASISTEN!BR21 -> 0 | EE13: =[1]ASISTEN!BS21 -> 0 | EF13: =[1]APREPER!AN20 -> Ha logrado avances importantes en varias competencias; sin embargo, aún requiere fortalecer algunos aprendizajes para alcanzar un desempeño más uniforme y seguro. | EG13: =((EJ13*3)+(EK13*2)+(EL13*1)) -> 157 | EH13: =RANK(EG13,$EG$5:$EG$32,0) -> 17 | EJ13: =COUNTIF(C13:CJ13,"AD") -> 0 | EK13: =COUNTIF(C13:CJ13,"A") -> 72 | EL13: =COUNTIF(C13:CJ13,"B") -> 13
A14: 10 | B14: GAMARRA RIPALDA AZRAEL ALEJANDRO | C14: =[1]PERS!N22 -> A | D14: =[1]PERS!AH22 -> A | E14: =[1]PERS!AZ22 -> A | F14: =[1]PERS!R22 -> A | G14: =[1]PERS!AL22 -> A | H14: =[1]PERS!BA22 -> A | I14: =[1]PERS!V22 -> A | J14: =[1]PERS!AP22 -> A | K14: =[1]PERS!BB22 -> A | L14: =[1]PERS!Z22 -> A | M14: =[1]PERS!AT22 -> A | N14: =[1]PERS!BC22 -> A | O14: =[1]PERS!AD22 -> A | P14: =[1]PERS!AX22 -> B | Q14: =[1]PERS!BD22 -> A | R14: =[1]EFIS!N22 -> A | S14: =[1]EFIS!AH22 -> A | T14: =[1]EFIS!AZ22 -> A | U14: =[1]EFIS!R22 -> A | V14: =[1]EFIS!AL22 -> A | W14: =[1]EFIS!BA22 -> A | X14: =[1]EFIS!V22 -> A | Y14: =[1]EFIS!AP22 -> A | Z14: =[1]EFIS!BB22 -> A | AA14: =[1]COMU!N22 -> A | AB14: =[1]COMU!AH22 -> A | AC14: =[1]COMU!AZ22 -> A | AD14: =[1]COMU!R22 -> B | AE14: =[1]COMU!AH22 -> A | AF14: =[1]COMU!BA22 -> B | AG14: =[1]COMU!V22 -> B | AH14: =[1]COMU!AP22 -> A | AI14: =[1]COMU!BB22 -> A | AJ14: =[1]ARTE!N22 -> A | AK14: =[1]ARTE!AH22 -> A | AL14: =[1]ARTE!AZ22 -> A | AM14: =[1]ARTE!R22 -> A | AN14: =[1]ARTE!AL22 -> A | AO14: =[1]ARTE!BA22 -> A | AP14: =[1]ING!N22 -> A | AQ14: =[1]ING!AH22 -> A | AR14: =[1]ING!AZ22 -> A | AS14: =[1]ING!R22 -> B | AT14: =[1]ING!AL22 -> B | AU14: =[1]ING!BA22 -> B | AV14: =[1]ING!V22 -> A | AW14: =[1]ING!AP22 -> B | AX14: =[1]ING!BB22 -> A | AY14: =[1]MATE!N22 -> B | AZ14: =[1]MATE!AH22 -> C | BA14: =[1]MATE!AZ22 -> B | BB14: =[1]MATE!R22 -> B | BC14: =[1]MATE!AL22 -> B | BD14: =[1]MATE!BA22 -> B | BE14: =[1]MATE!V22 -> B | BF14: =[1]MATE!AP22 -> C | BG14: =[1]MATE!BB22 -> B | BH14: =[1]MATE!Z22 -> A | BI14: =[1]MATE!AT22 -> A | BJ14: =[1]MATE!BC22 -> A | BK14: =[1]CTEC!N22 -> B | BL14: =[1]CTEC!AH22 -> B | BM14: =[1]CTEC!AZ22 -> B | BN14: =[1]CTEC!R22 -> A | BO14: =[1]CTEC!AL22 -> A | BP14: =[1]CTEC!BA22 -> A | BQ14: =[1]CTEC!V22 -> A | BR14: =[1]CTEC!AP22 -> B | BS14: =[1]CTEC!BB22 -> A | BT14: =[1]REL!N22 -> A | BU14: =[1]REL!AH22 -> A | BV14: =[1]REL!AZ22 -> A | BW14: =[1]REL!R22 -> A | BX14: =[1]REL!AL22 -> A | BY14: =[1]REL!BA22 -> A | BZ14: =[1]EMPR!N22 -> A | CA14: =[1]EMPR!AH22 -> A | CB14: =[1]EMPR!AZ22 -> A | CC14: =[1]COMPU!N22 -> A | CD14: =[1]COMPU!AH22 -> A | CE14: =[1]COMPU!AZ22 -> A | CF14: =[1]ROBOTI!N22 -> A | CG14: =[1]ROBOTI!AH22 -> A | CH14: =[1]ROBOTI!AZ22 -> A | CI14: =[1]APREPER!AL21 -> A | CJ14: =[1]APREPER!AM21 -> A | CK14: =[1]APREPER!I21 -> 0 | CL14: =[1]APREPER!J21 -> X | CM14: =[1]APREPER!K21 -> 0 | CN14: =[1]APREPER!L21 -> 0 | CO14: =[1]APREPER!M21 -> X | CP14: =[1]APREPER!N21 -> 0 | CQ14: =[1]APREPER!O21 -> 0 | CR14: =[1]APREPER!P21 -> X | ... DL14: =[1]APREPER!AJ21 -> A | DM14: =[1]APREPPFF!I21 -> 0 | DN14: =[1]APREPPFF!J21 -> X | DO14: =[1]APREPPFF!K21 -> 0 | DP14: =[1]APREPPFF!L21 -> 0 | DQ14: =[1]APREPPFF!M21 -> X | DR14: =[1]APREPPFF!N21 -> 0 | DS14: =[1]APREPPFF!O21 -> 0 | DT14: =[1]APREPPFF!P21 -> X | ... DY14: =[1]APREPPFF!U21 -> B | DZ14: =[1]ASISTEN!$BS$4 -> 47 | EA14: =[1]ASISTEN!BT22 -> 1 | EB14: =[1]ASISTEN!BP22 -> 28 | EC14: =[1]ASISTEN!BQ22 -> 17 | ED14: =[1]ASISTEN!BR22 -> 2 | EE14: =[1]ASISTEN!BS22 -> 0 | EF14: =[1]APREPER!AN21 -> Requiere mayor esfuerzo y compromiso en sus actividades escolares, ya que la mayoría de competencias aún se encuentran en proceso y demandan atención continua. | EG14: =((EJ14*3)+(EK14*2)+(EL14*1)) -> 149 | EH14: =RANK(EG14,$EG$5:$EG$32,0) -> 20 | EJ14: =COUNTIF(C14:CJ14,"AD") -> 0 | EK14: =COUNTIF(C14:CJ14,"A") -> 65 | EL14: =COUNTIF(C14:CJ14,"B") -> 19
A15: 11 | B15: GARCIA CONDORI HEYDREAN SOFIA | C15: =[1]PERS!N23 -> A | D15: =[1]PERS!AH23 -> A | E15: =[1]PERS!AZ23 -> A | F15: =[1]PERS!R23 -> A | G15: =[1]PERS!AL23 -> A | H15: =[1]PERS!BA23 -> A | I15: =[1]PERS!V23 -> B | J15: =[1]PERS!AP23 -> A | K15: =[1]PERS!BB23 -> A | L15: =[1]PERS!Z23 -> A | M15: =[1]PERS!AT23 -> A | N15: =[1]PERS!BC23 -> A | O15: =[1]PERS!AD23 -> A | P15: =[1]PERS!AX23 -> A | Q15: =[1]PERS!BD23 -> A | R15: =[1]EFIS!N23 -> A | S15: =[1]EFIS!AH23 -> A | T15: =[1]EFIS!AZ23 -> A | U15: =[1]EFIS!R23 -> A | V15: =[1]EFIS!AL23 -> A | W15: =[1]EFIS!BA23 -> A | X15: =[1]EFIS!V23 -> A | Y15: =[1]EFIS!AP23 -> A | Z15: =[1]EFIS!BB23 -> A | AA15: =[1]COMU!N23 -> A | AB15: =[1]COMU!AH23 -> A | AC15: =[1]COMU!AZ23 -> A | AD15: =[1]COMU!R23 -> A | AE15: =[1]COMU!AH23 -> A | AF15: =[1]COMU!BA23 -> A | AG15: =[1]COMU!V23 -> A | AH15: =[1]COMU!AP23 -> A | AI15: =[1]COMU!BB23 -> A | AJ15: =[1]ARTE!N23 -> A | AK15: =[1]ARTE!AH23 -> A | AL15: =[1]ARTE!AZ23 -> A | AM15: =[1]ARTE!R23 -> A | AN15: =[1]ARTE!AL23 -> A | AO15: =[1]ARTE!BA23 -> A | AP15: =[1]ING!N23 -> A | AQ15: =[1]ING!AH23 -> A | AR15: =[1]ING!AZ23 -> A | AS15: =[1]ING!R23 -> A | AT15: =[1]ING!AL23 -> A | AU15: =[1]ING!BA23 -> A | AV15: =[1]ING!V23 -> A | AW15: =[1]ING!AP23 -> A | AX15: =[1]ING!BB23 -> A | AY15: =[1]MATE!N23 -> A | AZ15: =[1]MATE!AH23 -> B | BA15: =[1]MATE!AZ23 -> A | BB15: =[1]MATE!R23 -> AD | BC15: =[1]MATE!AL23 -> A | BD15: =[1]MATE!BA23 -> AD | BE15: =[1]MATE!V23 -> A | BF15: =[1]MATE!AP23 -> A | BG15: =[1]MATE!BB23 -> A | BH15: =[1]MATE!Z23 -> A | BI15: =[1]MATE!AT23 -> A | BJ15: =[1]MATE!BC23 -> A | BK15: =[1]CTEC!N23 -> A | BL15: =[1]CTEC!AH23 -> B | BM15: =[1]CTEC!AZ23 -> A | BN15: =[1]CTEC!R23 -> A | BO15: =[1]CTEC!AL23 -> A | BP15: =[1]CTEC!BA23 -> A | BQ15: =[1]CTEC!V23 -> A | BR15: =[1]CTEC!AP23 -> B | BS15: =[1]CTEC!BB23 -> A | BT15: =[1]REL!N23 -> A | BU15: =[1]REL!AH23 -> A | BV15: =[1]REL!AZ23 -> A | BW15: =[1]REL!R23 -> A | BX15: =[1]REL!AL23 -> A | BY15: =[1]REL!BA23 -> A | BZ15: =[1]EMPR!N23 -> A | CA15: =[1]EMPR!AH23 -> A | CB15: =[1]EMPR!AZ23 -> A | CC15: =[1]COMPU!N23 -> A | CD15: =[1]COMPU!AH23 -> A | CE15: =[1]COMPU!AZ23 -> A | CF15: =[1]ROBOTI!N23 -> A | CG15: =[1]ROBOTI!AH23 -> A | CH15: =[1]ROBOTI!AZ23 -> A | CI15: =[1]APREPER!AL22 -> A | CJ15: =[1]APREPER!AM22 -> A | CK15: =[1]APREPER!I22 -> X | CL15: =[1]APREPER!J22 -> 0 | CM15: =[1]APREPER!K22 -> 0 | CN15: =[1]APREPER!L22 -> X | CO15: =[1]APREPER!M22 -> 0 | CP15: =[1]APREPER!N22 -> 0 | CQ15: =[1]APREPER!O22 -> X | CR15: =[1]APREPER!P22 -> 0 | ... DL15: =[1]APREPER!AJ22 -> A | DM15: =[1]APREPPFF!I22 -> X | DN15: =[1]APREPPFF!J22 -> 0 | DO15: =[1]APREPPFF!K22 -> 0 | DP15: =[1]APREPPFF!L22 -> X | DQ15: =[1]APREPPFF!M22 -> 0 | DR15: =[1]APREPPFF!N22 -> 0 | DS15: =[1]APREPPFF!O22 -> X | DT15: =[1]APREPPFF!P22 -> 0 | ... DY15: =[1]APREPPFF!U22 -> A | DZ15: =[1]ASISTEN!$BS$4 -> 47 | EA15: =[1]ASISTEN!BT23 -> 1 | EB15: =[1]ASISTEN!BP23 -> 46 | EC15: =[1]ASISTEN!BQ23 -> 1 | ED15: =[1]ASISTEN!BR23 -> 0 | EE15: =[1]ASISTEN!BS23 -> 0 | EF15: =[1]APREPER!AN22 -> Mantiene un rendimiento satisfactorio en todas las competencias evaluadas, demostrando responsabilidad, compromiso y un adecuado desarrollo de sus aprendizajes. | EG15: =((EJ15*3)+(EK15*2)+(EL15*1)) -> 170 | EH15: =RANK(EG15,$EG$5:$EG$32,0) -> 6 | EJ15: =COUNTIF(C15:CJ15,"AD") -> 2 | EK15: =COUNTIF(C15:CJ15,"A") -> 80 | EL15: =COUNTIF(C15:CJ15,"B") -> 4
A16: 12 | B16: GONZÁLEZ CAIÑA FELIPE ARNALDO | C16: =[1]PERS!N24 -> A | D16: =[1]PERS!AH24 -> A | E16: =[1]PERS!AZ24 -> A | F16: =[1]PERS!R24 -> A | G16: =[1]PERS!AL24 -> A | H16: =[1]PERS!BA24 -> A | I16: =[1]PERS!V24 -> A | J16: =[1]PERS!AP24 -> A | K16: =[1]PERS!BB24 -> A | L16: =[1]PERS!Z24 -> A | M16: =[1]PERS!AT24 -> A | N16: =[1]PERS!BC24 -> A | O16: =[1]PERS!AD24 -> A | P16: =[1]PERS!AX24 -> A | Q16: =[1]PERS!BD24 -> A | R16: =[1]EFIS!N24 -> A | S16: =[1]EFIS!AH24 -> A | T16: =[1]EFIS!AZ24 -> A | U16: =[1]EFIS!R24 -> A | V16: =[1]EFIS!AL24 -> A | W16: =[1]EFIS!BA24 -> A | X16: =[1]EFIS!V24 -> A | Y16: =[1]EFIS!AP24 -> A | Z16: =[1]EFIS!BB24 -> A | AA16: =[1]COMU!N24 -> A | AB16: =[1]COMU!AH24 -> A | AC16: =[1]COMU!AZ24 -> A | AD16: =[1]COMU!R24 -> A | AE16: =[1]COMU!AH24 -> A | AF16: =[1]COMU!BA24 -> A | AG16: =[1]COMU!V24 -> A | AH16: =[1]COMU!AP24 -> A | AI16: =[1]COMU!BB24 -> A | AJ16: =[1]ARTE!N24 -> A | AK16: =[1]ARTE!AH24 -> A | AL16: =[1]ARTE!AZ24 -> A | AM16: =[1]ARTE!R24 -> A | AN16: =[1]ARTE!AL24 -> A | AO16: =[1]ARTE!BA24 -> A | AP16: =[1]ING!N24 -> A | AQ16: =[1]ING!AH24 -> A | AR16: =[1]ING!AZ24 -> A | AS16: =[1]ING!R24 -> A | AT16: =[1]ING!AL24 -> B | AU16: =[1]ING!BA24 -> A | AV16: =[1]ING!V24 -> A | AW16: =[1]ING!AP24 -> B | AX16: =[1]ING!BB24 -> A | AY16: =[1]MATE!N24 -> A | AZ16: =[1]MATE!AH24 -> A | BA16: =[1]MATE!AZ24 -> A | BB16: =[1]MATE!R24 -> A | BC16: =[1]MATE!AL24 -> A | BD16: =[1]MATE!BA24 -> A | BE16: =[1]MATE!V24 -> A | BF16: =[1]MATE!AP24 -> C | BG16: =[1]MATE!BB24 -> B | BH16: =[1]MATE!Z24 -> A | BI16: =[1]MATE!AT24 -> A | BJ16: =[1]MATE!BC24 -> A | BK16: =[1]CTEC!N24 -> A | BL16: =[1]CTEC!AH24 -> A | BM16: =[1]CTEC!AZ24 -> A | BN16: =[1]CTEC!R24 -> A | BO16: =[1]CTEC!AL24 -> A | BP16: =[1]CTEC!BA24 -> A | BQ16: =[1]CTEC!V24 -> A | BR16: =[1]CTEC!AP24 -> A | BS16: =[1]CTEC!BB24 -> A | BT16: =[1]REL!N24 -> A | BU16: =[1]REL!AH24 -> A | BV16: =[1]REL!AZ24 -> A | BW16: =[1]REL!R24 -> A | BX16: =[1]REL!AL24 -> A | BY16: =[1]REL!BA24 -> A | BZ16: =[1]EMPR!N24 -> A | CA16: =[1]EMPR!AH24 -> A | CB16: =[1]EMPR!AZ24 -> A | CC16: =[1]COMPU!N24 -> A | CD16: =[1]COMPU!AH24 -> A | CE16: =[1]COMPU!AZ24 -> A | CF16: =[1]ROBOTI!N24 -> A | CG16: =[1]ROBOTI!AH24 -> A | CH16: =[1]ROBOTI!AZ24 -> A | CI16: =[1]APREPER!AL23 -> A | CJ16: =[1]APREPER!AM23 -> A | CK16: =[1]APREPER!I23 -> X | CL16: =[1]APREPER!J23 -> 0 | CM16: =[1]APREPER!K23 -> 0 | CN16: =[1]APREPER!L23 -> X | CO16: =[1]APREPER!M23 -> 0 | CP16: =[1]APREPER!N23 -> 0 | CQ16: =[1]APREPER!O23 -> X | CR16: =[1]APREPER!P23 -> 0 | ... DL16: =[1]APREPER!AJ23 -> A | DM16: =[1]APREPPFF!I23 -> X | DN16: =[1]APREPPFF!J23 -> 0 | DO16: =[1]APREPPFF!K23 -> 0 | DP16: =[1]APREPPFF!L23 -> X | DQ16: =[1]APREPPFF!M23 -> 0 | DR16: =[1]APREPPFF!N23 -> 0 | DS16: =[1]APREPPFF!O23 -> X | DT16: =[1]APREPPFF!P23 -> 0 | ... DY16: =[1]APREPPFF!U23 -> A | DZ16: =[1]ASISTEN!$BS$4 -> 47 | EA16: =[1]ASISTEN!BT24 -> 1 | EB16: =[1]ASISTEN!BP24 -> 46 | EC16: =[1]ASISTEN!BQ24 -> 1 | ED16: =[1]ASISTEN!BR24 -> 0 | EE16: =[1]ASISTEN!BS24 -> 0 | EF16: =[1]APREPER!AN23 -> Mantiene un rendimiento satisfactorio en todas las competencias evaluadas, demostrando responsabilidad, compromiso y un adecuado desarrollo de sus aprendizajes. | EG16: =((EJ16*3)+(EK16*2)+(EL16*1)) -> 167 | EH16: =RANK(EG16,$EG$5:$EG$32,0) -> 9 | EJ16: =COUNTIF(C16:CJ16,"AD") -> 0 | EK16: =COUNTIF(C16:CJ16,"A") -> 82 | EL16: =COUNTIF(C16:CJ16,"B") -> 3
... A29: 25 | B29: VEGA BUSTINZA LUCIANA NATALIA | C29: =[1]PERS!N37 -> A | D29: =[1]PERS!AH37 -> A | E29: =[1]PERS!AZ37 -> A | F29: =[1]PERS!R37 -> A | G29: =[1]PERS!AL37 -> A | H29: =[1]PERS!BA37 -> A | I29: =[1]PERS!V37 -> A | J29: =[1]PERS!AP37 -> A | K29: =[1]PERS!BB37 -> A | L29: =[1]PERS!Z37 -> A | M29: =[1]PERS!AT37 -> A | N29: =[1]PERS!BC37 -> A | O29: =[1]PERS!AD37 -> A | P29: =[1]PERS!AX37 -> A | Q29: =[1]PERS!BD37 -> A | R29: =[1]EFIS!N37 -> A | S29: =[1]EFIS!AH37 -> A | T29: =[1]EFIS!AZ37 -> A | U29: =[1]EFIS!R37 -> A | V29: =[1]EFIS!AL37 -> A | W29: =[1]EFIS!BA37 -> A | X29: =[1]EFIS!V37 -> A | Y29: =[1]EFIS!AP37 -> A | Z29: =[1]EFIS!BB37 -> A | AA29: =[1]COMU!N37 -> A | AB29: =[1]COMU!AH37 -> A | AC29: =[1]COMU!AZ37 -> A | AD29: =[1]COMU!R37 -> A | AE29: =[1]COMU!AH37 -> A | AF29: =[1]COMU!BA37 -> A | AG29: =[1]COMU!V37 -> A | AH29: =[1]COMU!AP37 -> A | AI29: =[1]COMU!BB37 -> A | AJ29: =[1]ARTE!N37 -> A | AK29: =[1]ARTE!AH37 -> A | AL29: =[1]ARTE!AZ37 -> A | AM29: =[1]ARTE!R37 -> A | AN29: =[1]ARTE!AL37 -> A | AO29: =[1]ARTE!BA37 -> A | AP29: =[1]ING!N37 -> A | AQ29: =[1]ING!AH37 -> A | AR29: =[1]ING!AZ37 -> A | AS29: =[1]ING!R37 -> A | AT29: =[1]ING!AL37 -> A | AU29: =[1]ING!BA37 -> A | AV29: =[1]ING!V37 -> A | AW29: =[1]ING!AP37 -> A | AX29: =[1]ING!BB37 -> A | AY29: =[1]MATE!N37 -> B | AZ29: =[1]MATE!AH37 -> B | BA29: =[1]MATE!AZ37 -> B | BB29: =[1]MATE!R37 -> A | BC29: =[1]MATE!AL37 -> A | BD29: =[1]MATE!BA37 -> A | BE29: =[1]MATE!V37 -> A | BF29: =[1]MATE!AP37 -> B | BG29: =[1]MATE!BB37 -> A | BH29: =[1]MATE!Z37 -> A | BI29: =[1]MATE!AT37 -> A | BJ29: =[1]MATE!BC37 -> A | BK29: =[1]CTEC!N37 -> B | BL29: =[1]CTEC!AH37 -> A | BM29: =[1]CTEC!AZ37 -> A | BN29: =[1]CTEC!R37 -> A | BO29: =[1]CTEC!AL37 -> A | BP29: =[1]CTEC!BA37 -> A | BQ29: =[1]CTEC!V37 -> B | BR29: =[1]CTEC!AP37 -> B | BS29: =[1]CTEC!BB37 -> B | BT29: =[1]REL!N37 -> A | BU29: =[1]REL!AH37 -> A | BV29: =[1]REL!AZ37 -> A | BW29: =[1]REL!R37 -> A | BX29: =[1]REL!AL37 -> A | BY29: =[1]REL!BA37 -> A | BZ29: =[1]EMPR!N37 -> A | CA29: =[1]EMPR!AH37 -> A | CB29: =[1]EMPR!AZ37 -> A | CC29: =[1]COMPU!N37 -> A | CD29: =[1]COMPU!AH37 -> A | CE29: =[1]COMPU!AZ37 -> A | CF29: =[1]ROBOTI!N37 -> A | CG29: =[1]ROBOTI!AH37 -> A | CH29: =[1]ROBOTI!AZ37 -> A | CI29: =[1]APREPER!AL36 -> A | CJ29: =[1]APREPER!AM36 -> A | CK29: =[1]APREPER!I36 -> X | CL29: =[1]APREPER!J36 -> 0 | CM29: =[1]APREPER!K36 -> 0 | CN29: =[1]APREPER!L36 -> X | CO29: =[1]APREPER!M36 -> 0 | CP29: =[1]APREPER!N36 -> 0 | CQ29: =[1]APREPER!O36 -> X | CR29: =[1]APREPER!P36 | ... DL29: =[1]APREPER!AJ36 -> A | DM29: =[1]APREPPFF!I36 -> X | DN29: =[1]APREPPFF!J36 -> 0 | DO29: =[1]APREPPFF!K36 -> 0 | DP29: =[1]APREPPFF!L36 -> X | DQ29: =[1]APREPPFF!M36 -> 0 | DR29: =[1]APREPPFF!N36 -> 0 | DS29: =[1]APREPPFF!O36 -> X | DT29: =[1]APREPPFF!P36 | ... DY29: =[1]APREPPFF!U36 -> A | DZ29: =[1]ASISTEN!$BS$4 -> 47 | EA29: =[1]ASISTEN!BT37 -> 1 | EB29: =[1]ASISTEN!BP37 -> 43 | EC29: =[1]ASISTEN!BQ37 -> 1 | ED29: =[1]ASISTEN!BR37 -> 3 | EE29: =[1]ASISTEN!BS37 -> 0 | EF29: =[1]APREPER!AN36 -> Ha logrado avances importantes en varias competencias; sin embargo, aún requiere fortalecer algunos aprendizajes para alcanzar un desempeño más uniforme y seguro. | EG29: =((EJ29*3)+(EK29*2)+(EL29*1)) -> 164 | EH29: =RANK(EG29,$EG$5:$EG$32,0) -> 15 | EJ29: =COUNTIF(C29:CJ29,"AD") -> 0 | EK29: =COUNTIF(C29:CJ29,"A") -> 78 | EL29: =COUNTIF(C29:CJ29,"B") -> 8
A30: 26 | C30: =[1]PERS!N38 | D30: =[1]PERS!AH38 | E30: =[1]PERS!AZ38 | F30: =[1]PERS!R38 | G30: =[1]PERS!AL38 | H30: =[1]PERS!BA38 | I30: =[1]PERS!V38 | J30: =[1]PERS!AP38 | K30: =[1]PERS!BB38 | L30: =[1]PERS!Z38 | M30: =[1]PERS!AT38 | N30: =[1]PERS!BC38 | O30: =[1]PERS!AD38 | P30: =[1]PERS!AX38 | Q30: =[1]PERS!BD38 | AA30: =[1]COMU!N38 | AB30: =[1]COMU!AH38 | AC30: =[1]COMU!AZ38 | AD30: =[1]COMU!R38 | AE30: =[1]COMU!AH38 | AF30: =[1]COMU!BA38 | AG30: =[1]COMU!V38 | AH30: =[1]COMU!AP38 | AI30: =[1]COMU!BB38 | AJ30: =[1]ARTE!N38 | AK30: =[1]ARTE!AH38 | AL30: =[1]ARTE!AZ38 | AM30: =[1]ARTE!R38 | AN30: =[1]ARTE!AL38 | AO30: =[1]ARTE!BA38 | AP30: =[1]ING!N38 | AQ30: =[1]ING!AH38 | AR30: =[1]ING!AZ38 | AS30: =[1]ING!R38 | AT30: =[1]ING!AL38 | AU30: =[1]ING!BA38 | AV30: =[1]ING!V38 | AW30: =[1]ING!AP38 | AX30: =[1]ING!BB38 | BA30: =[1]MATE!AZ38 | BB30: =[1]MATE!R38 | BC30: =[1]MATE!AL38 | BD30: =[1]MATE!BA38 | BE30: =[1]MATE!V38 | BF30: =[1]MATE!AP38 | BG30: =[1]MATE!BB38 | BH30: =[1]MATE!Z38 | BI30: =[1]MATE!AT38 | BJ30: =[1]MATE!BC38 | BK30: =[1]CTEC!N38 | BL30: =[1]CTEC!AH38 | BM30: =[1]CTEC!AZ38 | BN30: =[1]CTEC!R38 | BO30: =[1]CTEC!AL38 | BP30: =[1]CTEC!BA38 | BQ30: =[1]CTEC!V38 | BR30: =[1]CTEC!AP38 | BS30: =[1]CTEC!BB38 | BT30: =[1]REL!N38 | BU30: =[1]REL!AH38 | BV30: =[1]REL!AZ38 | BW30: =[1]REL!R38 | BX30: =[1]REL!AL38 | BY30: =[1]REL!BA38 | BZ30: =[1]EMPR!N38 | CA30: =[1]EMPR!AH38 | CB30: =[1]EMPR!AZ38 | CC30: =[1]COMPU!N38 | CD30: =[1]COMPU!AH38 | CE30: =[1]COMPU!AZ38 | CF30: =[1]ROBOTI!N38 | CG30: =[1]ROBOTI!AH38 | CH30: =[1]ROBOTI!AZ38 | CI30: =[1]APREPER!AL37 -> 0 | CJ30: =[1]APREPER!AM37 -> 0 | CK30: =[1]APREPER!I37 -> 0 | CL30: =[1]APREPER!J37 -> 0 | CM30: =[1]APREPER!K37 -> 0 | CN30: =[1]APREPER!L37 | CO30: =[1]APREPER!M37 -> 0 | CP30: =[1]APREPER!N37 -> 0 | CQ30: =[1]APREPER!O37 -> 0 | CR30: =[1]APREPER!P37 | ... DL30: =[1]APREPER!AJ37 -> 0 | DM30: =[1]APREPPFF!I37 -> 0 | DN30: =[1]APREPPFF!J37 -> 0 | DO30: =[1]APREPPFF!K37 -> 0 | DP30: =[1]APREPPFF!L37 | DQ30: =[1]APREPPFF!M37 -> 0 | DR30: =[1]APREPPFF!N37 -> 0 | DS30: =[1]APREPPFF!O37 -> 0 | DT30: =[1]APREPPFF!P37 | ... DY30: =[1]APREPPFF!U37 -> 0 | EA30: =[1]ASISTEN!BT38 | EB30: =[1]ASISTEN!BP38 | EC30: =[1]ASISTEN!BQ38 | ED30: =[1]ASISTEN!BR38 | EE30: =[1]ASISTEN!BS38 | EF30: =[1]APREPER!AN37 -> 0 | EJ30: =COUNTIF(C30:CJ30,"AD") -> 0 | EK30: =COUNTIF(C30:CJ30,"A") -> 0 | EL30: =COUNTIF(C30:CJ30,"B") -> 0
