Workbook

Sheet Libreta
A2: LIBRETA INFORMATIVA DE NOTAS
A3: NIVEL SECUNDARIA 2026
C5: AÑO/GRADO: | D5: 5° AÑO
B6: N° LISTA: | C6: 9
B7: ESTUDIANTE: | C7: =VLOOKUP(Libreta!$C$6,CONSOLIDADO!$A$1:$EF$33,CONSOLIDADO!$B$1,0) -> SULLCA CHIPANA JULIO CESAR MATIAS | E7: II BIMESTRE
B8: DOCENTE: | C8: JOSE LUIS CHOQUEGONZA MAMANI
B9: AREAS | C9: COMPETENCIAS | D9: NOTAS FINALES
D10: U1 | E10: U2 | F10: BIM
B11: Matemática | C11: Resuelve problemas de cantidad. | D11: =IFERROR(VLOOKUP($C$6,CONSOLIDADO!$A$1:$EF$33,CONSOLIDADO!$C$1,0),"-") -> B | E11: =IFERROR(VLOOKUP($C$6,CONSOLIDADO!$A$1:$EF$33,CONSOLIDADO!$D$1,0),"-") -> A | F11: =IFERROR(VLOOKUP($C$6,CONSOLIDADO!$A$1:$EF$33,CONSOLIDADO!$E$1,0),"-") -> A
C12: Resuelve problemas de regularidad, equivalencia y cambio. | D12: =IFERROR(VLOOKUP($C$6,CONSOLIDADO!$A$1:$EF$33,CONSOLIDADO!$F$1,0),"-") -> B | E12: =IFERROR(VLOOKUP($C$6,CONSOLIDADO!$A$1:$EF$33,CONSOLIDADO!$G$1,0),"-") -> B | F12: =IFERROR(VLOOKUP($C$6,CONSOLIDADO!$A$1:$EF$33,CONSOLIDADO!$H$1,0),"-") -> B
C13: Resuelve problemas de movimiento, forma y localización. | D13: =IFERROR(VLOOKUP($C$6,CONSOLIDADO!$A$1:$EF$33,CONSOLIDADO!$I$1,0),"-") -> B | E13: =IFERROR(VLOOKUP($C$6,CONSOLIDADO!$A$1:$EF$33,CONSOLIDADO!$J$1,0),"-") -> B | F13: =IFERROR(VLOOKUP($C$6,CONSOLIDADO!$A$1:$EF$33,CONSOLIDADO!$K$1,0),"-") -> B
C14: Resuelve problemas de gestión de datos e incertidumbre. | D14: =IFERROR(VLOOKUP($C$6,CONSOLIDADO!$A$1:$EF$33,CONSOLIDADO!$L$1,0),"-") -> A | E14: =IFERROR(VLOOKUP($C$6,CONSOLIDADO!$A$1:$EF$33,CONSOLIDADO!$M$1,0),"-") -> A | F14: =IFERROR(VLOOKUP($C$6,CONSOLIDADO!$A$1:$EF$33,CONSOLIDADO!$N$1,0),"-") -> A
B15: Ciencias Sociales | C15: Construye interpretaciones históricas | D15: =IFERROR(VLOOKUP($C$6,CONSOLIDADO!$A$1:$EF$33,CONSOLIDADO!$O$1,0),"-") -> A | E15: =IFERROR(VLOOKUP($C$6,CONSOLIDADO!$A$1:$EF$33,CONSOLIDADO!$P$1,0),"-") -> A | F15: =IFERROR(VLOOKUP($C$6,CONSOLIDADO!$A$1:$EF$33,CONSOLIDADO!$Q$1,0),"-") -> A
C16: Gestiona responsablemente el espacio y el ambiente | D16: =IFERROR(VLOOKUP($C$6,CONSOLIDADO!$A$1:$EF$33,CONSOLIDADO!$R$1,0),"-") -> A | E16: =IFERROR(VLOOKUP($C$6,CONSOLIDADO!$A$1:$EF$33,CONSOLIDADO!$S$1,0),"-") -> A | F16: =IFERROR(VLOOKUP($C$6,CONSOLIDADO!$A$1:$EF$33,CONSOLIDADO!$T$1,0),"-") -> A
C17: Gestiona responsablemente los recursos económicos | D17: =IFERROR(VLOOKUP($C$6,CONSOLIDADO!$A$1:$EF$33,CONSOLIDADO!$U$1,0),"-") -> A | E17: =IFERROR(VLOOKUP($C$6,CONSOLIDADO!$A$1:$EF$33,CONSOLIDADO!$V$1,0),"-") -> B | F17: =IFERROR(VLOOKUP($C$6,CONSOLIDADO!$A$1:$EF$33,CONSOLIDADO!$W$1,0),"-") -> A
B18: Educación Física | C18: Se desenvuelve de manera autónoma a través de su identidad. | D18: =IFERROR(VLOOKUP($C$6,CONSOLIDADO!$A$1:$EF$33,CONSOLIDADO!$X$1,0),"-") -> A | E18: =IFERROR(VLOOKUP($C$6,CONSOLIDADO!$A$1:$EF$33,CONSOLIDADO!$Y$1,0),"-") -> A | F18: =IFERROR(VLOOKUP($C$6,CONSOLIDADO!$A$1:$EF$33,CONSOLIDADO!$Z$1,0),"-") -> A
C19: Asume una vida saludable. | D19: =IFERROR(VLOOKUP($C$6,CONSOLIDADO!$A$1:$EF$33,CONSOLIDADO!$AA$1,0),"-") -> A | E19: =IFERROR(VLOOKUP($C$6,CONSOLIDADO!$A$1:$EF$33,CONSOLIDADO!$AB$1,0),"-") -> A | F19: =IFERROR(VLOOKUP($C$6,CONSOLIDADO!$A$1:$EF$33,CONSOLIDADO!$AC$1,0),"-") -> A
C20: Interactúa a través de sus habilidades sociomotrices. | D20: =IFERROR(VLOOKUP($C$6,CONSOLIDADO!$A$1:$EF$33,CONSOLIDADO!$AD$1,0),"-") -> A | E20: =IFERROR(VLOOKUP($C$6,CONSOLIDADO!$A$1:$EF$33,CONSOLIDADO!$AE$1,0),"-") -> A | F20: =IFERROR(VLOOKUP($C$6,CONSOLIDADO!$A$1:$EF$33,CONSOLIDADO!$AF$1,0),"-") -> A
B21: Desarrollo Personal, Ciudadania y Cívica | C21: Construye su identidad | D21: =IFERROR(VLOOKUP($C$6,CONSOLIDADO!$A$1:$EF$33,CONSOLIDADO!$AG$1,0),"-") -> A | E21: =IFERROR(VLOOKUP($C$6,CONSOLIDADO!$A$1:$EF$33,CONSOLIDADO!$AH$1,0),"-") -> A | F21: =IFERROR(VLOOKUP($C$6,CONSOLIDADO!$A$1:$EF$33,CONSOLIDADO!$AI$1,0),"-") -> A
C22: Convive y participa democráticamente en la búsqueda del bien común | D22: =IFERROR(VLOOKUP($C$6,CONSOLIDADO!$A$1:$EF$33,CONSOLIDADO!$AJ$1,0),"-") -> A | E22: =IFERROR(VLOOKUP($C$6,CONSOLIDADO!$A$1:$EF$33,CONSOLIDADO!$AK$1,0),"-") -> B | F22: =IFERROR(VLOOKUP($C$6,CONSOLIDADO!$A$1:$EF$33,CONSOLIDADO!$AL$1,0),"-") -> A
B23: Arte y Cultura | C23: Aprecia de manera crítica manifestaciones artístico-culturales. | D23: =IFERROR(VLOOKUP($C$6,CONSOLIDADO!$A$1:$EF$33,CONSOLIDADO!$AM$1,0),"-") -> A | E23: =IFERROR(VLOOKUP($C$6,CONSOLIDADO!$A$1:$EF$33,CONSOLIDADO!$AN$1,0),"-") -> A | F23: =IFERROR(VLOOKUP($C$6,CONSOLIDADO!$A$1:$EF$33,CONSOLIDADO!$AO$1,0),"-") -> A
C24: Crea proyectos desde los lenguajes artísticos. | D24: =IFERROR(VLOOKUP($C$6,CONSOLIDADO!$A$1:$EF$33,CONSOLIDADO!$AP$1,0),"-") -> A | E24: =IFERROR(VLOOKUP($C$6,CONSOLIDADO!$A$1:$EF$33,CONSOLIDADO!$AQ$1,0),"-") -> A | F24: =IFERROR(VLOOKUP($C$6,CONSOLIDADO!$A$1:$EF$33,CONSOLIDADO!$AR$1,0),"-") -> A
B25: Comunicación | C25: Se comunica oralmente en lengua materna. | D25: =IFERROR(VLOOKUP($C$6,CONSOLIDADO!$A$1:$EF$33,CONSOLIDADO!$AS$1,0),"-") -> B | E25: =IFERROR(VLOOKUP($C$6,CONSOLIDADO!$A$1:$EF$33,CONSOLIDADO!$AT$1,0),"-") -> B | F25: =IFERROR(VLOOKUP($C$6,CONSOLIDADO!$A$1:$EF$33,CONSOLIDADO!$AU$1,0),"-") -> B
C26: Lee diversos tipos de textos escritos. | D26: =IFERROR(VLOOKUP($C$6,CONSOLIDADO!$A$1:$EF$33,CONSOLIDADO!$AV$1,0),"-") -> B | E26: =IFERROR(VLOOKUP($C$6,CONSOLIDADO!$A$1:$EF$33,CONSOLIDADO!$AW$1,0),"-") -> A | F26: =IFERROR(VLOOKUP($C$6,CONSOLIDADO!$A$1:$EF$33,CONSOLIDADO!$AX$1,0),"-") -> A
C27: Escribe diversos tipos de texto. | D27: =IFERROR(VLOOKUP($C$6,CONSOLIDADO!$A$1:$EF$33,CONSOLIDADO!$AY$1,0),"-") -> A | E27: =IFERROR(VLOOKUP($C$6,CONSOLIDADO!$A$1:$EF$33,CONSOLIDADO!$AZ$1,0),"-") -> A | F27: =IFERROR(VLOOKUP($C$6,CONSOLIDADO!$A$1:$EF$33,CONSOLIDADO!$BA$1,0),"-") -> A
B28: Ciencia y Tecnología | C28: Indaga mediante métodos científicos para construir conocimientos. | D28: =IFERROR(VLOOKUP($C$6,CONSOLIDADO!$A$1:$EF$33,CONSOLIDADO!$BB$1,0),"-") -> B | E28: =IFERROR(VLOOKUP($C$6,CONSOLIDADO!$A$1:$EF$33,CONSOLIDADO!$BC$1,0),"-") -> A | F28: =IFERROR(VLOOKUP($C$6,CONSOLIDADO!$A$1:$EF$33,CONSOLIDADO!$BD$1,0),"-") -> A
C29: Explica el mundo natural y artificial en base a conocimiento sobre los seres vivos, materia, energia, biodiversidad, tierra y universo. | D29: =IFERROR(VLOOKUP($C$6,CONSOLIDADO!$A$1:$EF$33,CONSOLIDADO!$BE$1,0),"-") -> B | E29: =IFERROR(VLOOKUP($C$6,CONSOLIDADO!$A$1:$EF$33,CONSOLIDADO!$BF$1,0),"-") -> C | F29: =IFERROR(VLOOKUP($C$6,CONSOLIDADO!$A$1:$EF$33,CONSOLIDADO!$BG$1,0),"-") -> B
C30: Diseña y construye soluciones tecnológicas para resolver problemas de entorno. | D30: =IFERROR(VLOOKUP($C$6,CONSOLIDADO!$A$1:$EF$33,CONSOLIDADO!$BH$1,0),"-") -> A | E30: =IFERROR(VLOOKUP($C$6,CONSOLIDADO!$A$1:$EF$33,CONSOLIDADO!$BI$1,0),"-") -> C | F30: =IFERROR(VLOOKUP($C$6,CONSOLIDADO!$A$1:$EF$33,CONSOLIDADO!$BJ$1,0),"-") -> B
B31: Inglés como lengua Extranjera | C31: Se comunica oralmente en inglés como lengua extranjera. | D31: =IFERROR(VLOOKUP($C$6,CONSOLIDADO!$A$1:$EF$33,CONSOLIDADO!$BK$1,0),"-") -> B | E31: =IFERROR(VLOOKUP($C$6,CONSOLIDADO!$A$1:$EF$33,CONSOLIDADO!$BL$1,0),"-") -> B | F31: =IFERROR(VLOOKUP($C$6,CONSOLIDADO!$A$1:$EF$33,CONSOLIDADO!$BM$1,0),"-") -> B
C32: Lee diversos tipos de texto en inglés como lengua extranjera. | D32: =IFERROR(VLOOKUP($C$6,CONSOLIDADO!$A$1:$EF$33,CONSOLIDADO!$BN$1,0),"-") -> A | E32: =IFERROR(VLOOKUP($C$6,CONSOLIDADO!$A$1:$EF$33,CONSOLIDADO!$BO$1,0),"-") -> A | F32: =IFERROR(VLOOKUP($C$6,CONSOLIDADO!$A$1:$EF$33,CONSOLIDADO!$BP$1,0),"-") -> A
C33: Escribe diversos tipos de texto en inglés como lengua extranjera. | D33: =IFERROR(VLOOKUP($C$6,CONSOLIDADO!$A$1:$EF$33,CONSOLIDADO!$BQ$1,0),"-") -> A | E33: =IFERROR(VLOOKUP($C$6,CONSOLIDADO!$A$1:$EF$33,CONSOLIDADO!$BR$1,0),"-") -> A | F33: =IFERROR(VLOOKUP($C$6,CONSOLIDADO!$A$1:$EF$33,CONSOLIDADO!$BS$1,0),"-") -> A
B34: Educación Religiosa | C34: Construye su identidad como persona humana amada por Dios, digna, libre y transparente, comprendiendo la doctrina de su propia religión y abierto al dialogo con las personas cercanas. | D34: =IFERROR(VLOOKUP($C$6,CONSOLIDADO!$A$1:$EF$33,CONSOLIDADO!$BT$1,0),"-") -> A | E34: =IFERROR(VLOOKUP($C$6,CONSOLIDADO!$A$1:$EF$33,CONSOLIDADO!$BU$1,0),"-") -> A | F34: =IFERROR(VLOOKUP($C$6,CONSOLIDADO!$A$1:$EF$33,CONSOLIDADO!$BV$1,0),"-") -> A
C35: Asume la experiencia el encuentro personal comunitario con Dios en su proyecto de vida en coherencia con su creencia religiosa. | D35: =IFERROR(VLOOKUP($C$6,CONSOLIDADO!$A$1:$EF$33,CONSOLIDADO!$BW$1,0),"-") -> A | E35: =IFERROR(VLOOKUP($C$6,CONSOLIDADO!$A$1:$EF$33,CONSOLIDADO!$BX$1,0),"-") -> A | F35: =IFERROR(VLOOKUP($C$6,CONSOLIDADO!$A$1:$EF$33,CONSOLIDADO!$BY$1,0),"-") -> A
B36: Educación por el Trabajo | C36: Gestiona proyectos de emprendimiento económico social. | D36: =IFERROR(VLOOKUP($C$6,CONSOLIDADO!$A$1:$EF$33,CONSOLIDADO!$BZ$1,0),"-") -> A | E36: =IFERROR(VLOOKUP($C$6,CONSOLIDADO!$A$1:$EF$33,CONSOLIDADO!$CA$1,0),"-") -> A | F36: =IFERROR(VLOOKUP($C$6,CONSOLIDADO!$A$1:$EF$33,CONSOLIDADO!$CB$1,0),"-") -> A
B37: Taller de Cómputo | C37: Crea, ejecuta y aplica las diferentes herramientas tecnológicas en programas informáticos. | D37: =IFERROR(VLOOKUP($C$6,CONSOLIDADO!$A$1:$EF$33,CONSOLIDADO!$CC$1,0),"-") -> A | E37: =IFERROR(VLOOKUP($C$6,CONSOLIDADO!$A$1:$EF$33,CONSOLIDADO!$CD$1,0),"-") -> A | F37: =IFERROR(VLOOKUP($C$6,CONSOLIDADO!$A$1:$EF$33,CONSOLIDADO!$CE$1,0),"-") -> A
B38: Taller Programación y Robótica | C38: Utiliza la lógica para crear programas utilizando código abierto y desarrolla habilidades en el uso de prototipos robóticos. | D38: =IFERROR(VLOOKUP($C$6,CONSOLIDADO!$A$1:$EF$33,CONSOLIDADO!$CF$1,0),"-") -> A | E38: =IFERROR(VLOOKUP($C$6,CONSOLIDADO!$A$1:$EF$33,CONSOLIDADO!$CG$1,0),"-") -> A | F38: =IFERROR(VLOOKUP($C$6,CONSOLIDADO!$A$1:$EF$33,CONSOLIDADO!$CH$1,0),"-") -> A
B39: Tranversalidad | C39: Gestiona su aprendizaje de manera autónoma. | E39: =IFERROR(VLOOKUP($C$6,CONSOLIDADO!$A$1:$EF$33,CONSOLIDADO!$CI$1,0),"-") -> A
C40: Se desenvuelve en entornos virtuales generados por las TICs. | E40: =IFERROR(VLOOKUP($C$6,CONSOLIDADO!$A$1:$EF$33,CONSOLIDADO!$CJ$1,0),"-") -> A
B42: ACTITUDES DEL ESTUDIANTE | D42: SI | E42: A VECES | F42: NO
B43: 1 | C43: Asiste a clase con cuidando su presentación personal en todo momento. | D43: =IFERROR(VLOOKUP($C$6,CONSOLIDADO!$A$1:$EF$33,CONSOLIDADO!$CK$1,0),"-") -> x | E43: =IFERROR(VLOOKUP($C$6,CONSOLIDADO!$A$1:$EF$33,CONSOLIDADO!$CL$1,0),"-") -> 0 | F43: =IFERROR(VLOOKUP($C$6,CONSOLIDADO!$A$1:$EF$33,CONSOLIDADO!$CM$1,0),"-") -> 0
...

Sheet CONSOLIDADO
B1: 2 | C1: 3 | D1: 4 | E1: 5 | F1: 6 | G1: 7 | H1: 8 | I1: 9 | J1: 10 | K1: 11 | L1: 12 | M1: 13 | N1: 14 | O1: 15 | P1: 16 | Q1: 17 | R1: 18 | S1: 19 | T1: 20 | U1: 21 | V1: 22 | W1: 23 | X1: 24 | Y1: 25 | Z1: 26 | AA1: 27 | AB1: 28 | AC1: 29 | AD1: 30 | AE1: 31 | AF1: 32 | AG1: 33 | AH1: 34 | AI1: 35 | AJ1: 36 | AK1: 37 | AL1: 38 | AM1: 39 | AN1: 40 | AO1: 41 | AP1: 42 | AQ1: 43 | AR1: 44 | AS1: 45 | AT1: 46 | AU1: 47 | AV1: 48 | AW1: 49 | AX1: 50 | AY1: 51 | AZ1: 52 | BA1: 53 | BB1: 54 | BC1: 55 | BD1: 56 | BE1: 57 | BF1: 58 | BG1: 59 | BH1: 60 | BI1: 61 | BJ1: 62 | BK1: 63 | BL1: 64 | BM1: 65 | BN1: 66 | BO1: 67 | BP1: 68 | BQ1: 69 | BR1: 70 | BS1: 71 | BT1: 72 | BU1: 73 | BV1: 74 | BW1: 75 | BX1: 76 | BY1: 77 | BZ1: 78 | CA1: 79 | CB1: 80 | CC1: 81 | CD1: 82 | CE1: 83 | CF1: 84 | CG1: 85 | CH1: 86 | CI1: 87 | CJ1: 88 | CK1: 89 | CL1: 90 | CM1: 91 | CN1: 92 | CO1: 93 | CP1: 94 | CQ1: 95 | CR1: 96 | CS1: 97 | CT1: 98 | CU1: 99 | CV1: 100 | CW1: 101 | CX1: 102 | CY1: 103 | CZ1: 104 | DA1: 105 | DB1: 106 | DC1: 107 | DD1: 108 | DE1: 109 | DF1: 110 | DG1: 111 | DH1: 112 | DI1: 113 | DJ1: 114 | DK1: 115 | DL1: 116 | DM1: 117 | DN1: 118 | DO1: 119 | DP1: 120 | DQ1: 121 | DR1: 122 | DS1: 123 | DT1: 124 | DU1: 125 | DV1: 126 | DW1: 127 | DX1: 128 | DY1: 129 | DZ1: 130 | EA1: 131 | EB1: 132 | EC1: 133 | ED1: 134 | EE1: 135 | EF1: 136
C2: MATEMÁTICA | O2: CIENCIAS SOCIALES | X2: EDUCACION FISICA | AG2: DESAR. PERS, CUIDA Y CIVICA | AM2: ARTE Y CULTURA | AS2: COMUNICACIÓN | BB2: CIENCIA Y TECNOLOGIA | BK2: INGLÉS COMO LENGUA EXTRANJERA | BT2: EDUCACIÓN RELIGIOSA | BZ2: EDUC. TRABAJO | CC2: COMPUTACIÓN | CF2: ROBÓTICA | CI2: TRANSVERSALIDAD | CK2: Nota Aprec. Personal | DM2: Participación PP.FF | DZ2: Asistencia | EF2: Apuntes del Tutor | EG2: OTROS
A3: N° | B3: Apellidos-Nombres | C3: Comp 1 | F3: Comp 2 | I3: Comp 3 | L3: Comp 4 | O3: Comp 1 | R3: Comp 2 | U3: Comp 3 | X3: Comp 1 | AA3: Comp 2 | AD3: Comp 3 | AG3: Comp 1 | AJ3: Comp 2 | AM3: Comp 1 | AP3: Comp 2 | AS3: Comp 1 | AV3: Comp 2 | AY3: Comp 3 | BB3: Comp 1 | BE3: Comp 2 | BH3: Comp 3 | BK3: Comp 1 | BN3: Comp 2 | BQ3: Comp 3 | BT3: Comp 1 | BW3: Comp 2 | BZ3: Comp 1 | CC3: Comp 1 | CF3: Comp 1 | CK3: 1 | CN3: 2 | CQ3: 3 | CT3: 4 | CW3: 5 | CZ3: 6 | DC3: 7 | DF3: 8 | DI3: 9 | DL3: NF | DM3: 1 | DP3: 2 | DS3: 3 | DV3: 4 | DZ3: AT | EA3: A% | EB3: A | EC3: T | ED3: FJ | EE3: F | EG3: Puntaje AD-A | EH3: Orden Merito
C4: 1 | D4: 2 | E4: NF | F4: 1 | G4: 2 | H4: NF | I4: 1 | J4: 2 | K4: NF | L4: 1 | M4: 2 | N4: NF | O4: 1 | P4: 2 | Q4: NF | R4: 1 | S4: 2 | T4: NF | U4: 1 | V4: 2 | W4: NF | X4: 1 | Y4: 2 | Z4: NF | AA4: 1 | AB4: 2 | AC4: NF | AD4: 1 | AE4: 2 | AF4: NF | AG4: 1 | AH4: 2 | AI4: NF | AJ4: 1 | AK4: 2 | AL4: NF | AM4: 1 | AN4: 2 | AO4: NF | AP4: 1 | AQ4: 2 | AR4: NF | AS4: 1 | AT4: 2 | AU4: NF | AV4: 1 | AW4: 2 | AX4: NF | AY4: 1 | AZ4: 2 | BA4: NF | BB4: 1 | BC4: 2 | BD4: NF | BE4: 1 | BF4: 2 | BG4: NF | BH4: 1 | BI4: 2 | BJ4: NF | BK4: 1 | BL4: 2 | BM4: NF | BN4: 1 | BO4: 2 | BP4: NF | BQ4: 1 | BR4: 2 | BS4: NF | BT4: 1 | BU4: 2 | BV4: NF | BW4: 1 | BX4: 2 | BY4: NF | BZ4: 1 | CA4: 2 | CB4: NF | CC4: 1 | CD4: 2 | CE4: NF | CF4: 1 | CG4: 2 | CH4: NF | CI4: 1 | CJ4: 2 | CK4: S | CL4: A | CM4: N | CN4: S | CO4: A | CP4: N | CQ4: S | CR4: A | CS4: N | CT4: S | CU4: A | CV4: N | CW4: S | CX4: A | CY4: N | CZ4: S | DA4: A | DB4: N | DC4: S | DD4: A | DE4: N | DF4: S | DG4: A | DH4: N | DI4: S | DJ4: A | DK4: N | DM4: S | DN4: A | DO4: N | DP4: S | DQ4: A | DR4: N | DS4: S | DT4: A | DU4: N | DV4: S | DW4: A | DX4: N | DY4: NF
A5: 1 | B5: =[1]MAT!C13 -> AGUILAR DIAZ IAN EMANUEL | C5: =[1]MAT!N13 -> A | D5: =[1]MAT!AH13 -> A | E5: =[1]MAT!AZ13 -> A | F5: =[1]MAT!R13 -> C | G5: =[1]MAT!AL13 -> A | H5: =[1]MAT!BA13 -> B | I5: =[1]MAT!V13 -> B | J5: =[1]MAT!AP13 -> B | K5: =[1]MAT!BB13 -> B | L5: =[1]MAT!Z13 -> C | M5: =[1]MAT!AT13 -> C | N5: =[1]MAT!BC13 -> C | O5: =[1]CSOC!N13 -> A | P5: =[1]CSOC!AH13 -> A | Q5: =[1]CSOC!AZ13 -> A | R5: =[1]CSOC!R13 -> A | S5: =[1]CSOC!AL13 -> A | T5: =[1]CSOC!BA13 -> A | U5: =[1]CSOC!V13 -> A | V5: =[1]CSOC!AP13 -> B | W5: =[1]CSOC!BB13 -> A | X5: =[1]EFIS!N13 -> A | Y5: =[1]EFIS!AH13 -> A | Z5: =[1]EFIS!AZ13 -> A | AA5: =[1]EFIS!R13 -> A | AB5: =[1]EFIS!AL13 -> A | AC5: =[1]EFIS!BA13 -> A | AD5: =[1]EFIS!V13 -> A | AE5: =[1]EFIS!AP13 -> A | AF5: =[1]EFIS!BB13 -> A | AG5: =[1]DPCC!N13 -> A | AH5: =[1]DPCC!AH13 -> A | AI5: =[1]DPCC!AZ13 -> A | AJ5: =[1]DPCC!R13 -> A | AK5: =[1]DPCC!AL13 -> B | AL5: =[1]DPCC!BA13 -> A | AM5: =[1]ARTE!N13 -> A | AN5: =[1]ARTE!AH13 -> A | AO5: =[1]ARTE!AZ13 -> A | AP5: =[1]ARTE!R13 -> A | AQ5: =[1]ARTE!AL13 -> A | AR5: =[1]ARTE!BA13 -> A | AS5: =[1]COMU!N13 -> B | AT5: =[1]COMU!AH13 -> C | AU5: =[1]COMU!AZ13 -> B | AV5: =[1]COMU!R13 -> C | AW5: =[1]COMU!AL13 -> B | AX5: =[1]COMU!BA13 -> B | AY5: =[1]COMU!V13 -> B | AZ5: =[1]COMU!AP13 -> B | BA5: =[1]COMU!BB13 -> B | BB5: =[1]CTEC!N13 -> C | BC5: =[1]CTEC!AH13 -> B | BD5: =[1]CTEC!AZ13 -> B | BE5: =[1]CTEC!R13 -> B | BF5: =[1]CTEC!AL13 -> C | BG5: =[1]CTEC!BA13 -> B | BH5: =[1]CTEC!V13 -> C | BI5: =[1]CTEC!AP13 -> B | BJ5: =[1]CTEC!BB13 -> B | BK5: =[1]ING!N13 -> A | BL5: =[1]ING!AH13 -> A | BM5: =[1]ING!AZ13 -> A | BN5: =[1]ING!R13 -> A | BO5: =[1]ING!AL13 -> A | BP5: =[1]ING!BA13 -> A | BQ5: =[1]ING!V13 -> A | BR5: =[1]ING!AP13 -> A | BS5: =[1]ING!BB13 -> A | BT5: =[1]REL!N13 -> A | BU5: =[1]REL!AH13 -> A | BV5: =[1]REL!AZ13 -> A | BW5: =[1]REL!R13 -> A | BX5: =[1]REL!AL13 -> A | BY5: =[1]REL!BA13 -> A | BZ5: =[1]EMPR!N13 -> A | CA5: =[1]EMPR!AH13 -> A | CB5: =[1]EMPR!AZ13 -> A | CC5: =[1]COMPU!N13 -> A | CD5: =[1]COMPU!AH13 -> A | CE5: =[1]COMPU!AZ13 -> A | CF5: =[1]ROBOTI!N13 -> A | CG5: =[1]ROBOTI!AH13 -> A | CH5: =[1]ROBOTI!AZ13 -> A | CI5: =[1]APREPER!AK11 -> A | CJ5: =[1]APREPER!AL11 -> A | CK5: =[1]APREPER!I11 -> 0 | CL5: =[1]APREPER!J11 -> x | CM5: =[1]APREPER!K11 -> 0 | CN5: =[1]APREPER!L11 -> 0 | CO5: =[1]APREPER!M11 -> x | CP5: =[1]APREPER!N11 -> 0 | CQ5: =[1]APREPER!O11 -> 0 | CR5: =[1]APREPER!P11 -> x | ... DL5: =[1]APREPER!AJ11 -> B | DM5: =[1]APREPPFF!I11 -> 0 | DN5: =[1]APREPPFF!J11 -> x | DO5: =[1]APREPPFF!K11 -> 0 | DP5: =[1]APREPPFF!L11 -> x | DQ5: =[1]APREPPFF!M11 -> 0 | DR5: =[1]APREPPFF!N11 -> 0 | DS5: =[1]APREPPFF!O11 -> 0 | DT5: =[1]APREPPFF!P11 -> x | ... DY5: =[1]APREPPFF!U11 -> B | DZ5: =[1]ASISTEN!$BR$4 -> 47 | EA5: =[1]ASISTEN!BS13 -> 0.93617021 | EB5: =[1]ASISTEN!BO13 -> 41 | EC5: =[1]ASISTEN!BP13 -> 3 | ED5: =[1]ASISTEN!BQ13 -> 0 | EE5: =[1]ASISTEN!BR13 -> 3 | EF5: =[1]APREPER!AM11 -> El estudiante es tranquilo, correcto, muestra preocupación en su aprendizaje. Necesita reforzarse en las áreas de Ciencias, cumplir con un trabajo permanente en las actividades y seguimiento constante en casa. | EG5: =((EI5*3)+(EJ5*2)+(EK5*1)) -> 133 | EH5: =RANK(EG5,$EG$5:$EG$32,0) -> 9 | EI5: =COUNTIF(B5:CI5,"AD") -> 0 | EJ5: =COUNTIF(B5:CI5,"A") -> 57 | EK5: =COUNTIF(B5:CI5,"B") -> 19
A6: 2 | B6: =[1]MAT!C14 -> ARPAZA TORRES RODRIGO GONZALO | C6: =[1]MAT!N14 -> A | D6: =[1]MAT!AH14 -> A | E6: =[1]MAT!AZ14 -> A | F6: =[1]MAT!R14 -> B | G6: =[1]MAT!AL14 -> B | H6: =[1]MAT!BA14 -> B | I6: =[1]MAT!V14 -> A | J6: =[1]MAT!AP14 -> A | K6: =[1]MAT!BB14 -> A | L6: =[1]MAT!Z14 -> A | M6: =[1]MAT!AT14 -> A | N6: =[1]MAT!BC14 -> A | O6: =[1]CSOC!N14 -> A | P6: =[1]CSOC!AH14 -> A | Q6: =[1]CSOC!AZ14 -> A | R6: =[1]CSOC!R14 -> A | S6: =[1]CSOC!AL14 -> A | T6: =[1]CSOC!BA14 -> A | U6: =[1]CSOC!V14 -> A | V6: =[1]CSOC!AP14 -> B | W6: =[1]CSOC!BB14 -> A | X6: =[1]EFIS!N14 -> A | Y6: =[1]EFIS!AH14 -> A | Z6: =[1]EFIS!AZ14 -> A | AA6: =[1]EFIS!R14 -> A | AB6: =[1]EFIS!AL14 -> A | AC6: =[1]EFIS!BA14 -> A | AD6: =[1]EFIS!V14 -> A | AE6: =[1]EFIS!AP14 -> A | AF6: =[1]EFIS!BB14 -> A | AG6: =[1]DPCC!N14 -> A | AH6: =[1]DPCC!AH14 -> A | AI6: =[1]DPCC!AZ14 -> A | AJ6: =[1]DPCC!R14 -> A | AK6: =[1]DPCC!AL14 -> B | AL6: =[1]DPCC!BA14 -> A | AM6: =[1]ARTE!N14 -> A | AN6: =[1]ARTE!AH14 -> A | AO6: =[1]ARTE!AZ14 -> A | AP6: =[1]ARTE!R14 -> A | AQ6: =[1]ARTE!AL14 -> A | AR6: =[1]ARTE!BA14 -> A | AS6: =[1]COMU!N14 -> B | AT6: =[1]COMU!AH14 -> B | AU6: =[1]COMU!AZ14 -> B | AV6: =[1]COMU!R14 -> B | AW6: =[1]COMU!AL14 -> B | AX6: =[1]COMU!BA14 -> B | AY6: =[1]COMU!V14 -> B | AZ6: =[1]COMU!AP14 -> B | BA6: =[1]COMU!BB14 -> B | BB6: =[1]CTEC!N14 -> A | BC6: =[1]CTEC!AH14 -> A | BD6: =[1]CTEC!AZ14 -> A | BE6: =[1]CTEC!R14 -> B | BF6: =[1]CTEC!AL14 -> B | BG6: =[1]CTEC!BA14 -> B | BH6: =[1]CTEC!V14 -> B | BI6: =[1]CTEC!AP14 -> B | BJ6: =[1]CTEC!BB14 -> B | BK6: =[1]ING!N14 -> B | BL6: =[1]ING!AH14 -> B | BM6: =[1]ING!AZ14 -> B | BN6: =[1]ING!R14 -> A | BO6: =[1]ING!AL14 -> A | BP6: =[1]ING!BA14 -> A | BQ6: =[1]ING!V14 -> A | BR6: =[1]ING!AP14 -> A | BS6: =[1]ING!BB14 -> A | BT6: =[1]REL!N14 -> A | BU6: =[1]REL!AH14 -> A | BV6: =[1]REL!AZ14 -> A | BW6: =[1]REL!R14 -> A | BX6: =[1]REL!AL14 -> A | BY6: =[1]REL!BA14 -> A | BZ6: =[1]EMPR!N14 -> A | CA6: =[1]EMPR!AH14 -> A | CB6: =[1]EMPR!AZ14 -> A | CC6: =[1]COMPU!N14 -> A | CD6: =[1]COMPU!AH14 -> A | CE6: =[1]COMPU!AZ14 -> A | CF6: =[1]ROBOTI!N14 -> A | CG6: =[1]ROBOTI!AH14 -> A | CH6: =[1]ROBOTI!AZ14 -> A | CI6: =[1]APREPER!AK12 -> A | CJ6: =[1]APREPER!AL12 -> A | CK6: =[1]APREPER!I12 -> 0 | CL6: =[1]APREPER!J12 -> x | CM6: =[1]APREPER!K12 -> 0 | CN6: =[1]APREPER!L12 -> 0 | CO6: =[1]APREPER!M12 -> x | CP6: =[1]APREPER!N12 -> 0 | CQ6: =[1]APREPER!O12 -> 0 | CR6: =[1]APREPER!P12 -> x | ... DL6: =[1]APREPER!AJ12 -> B | DM6: =[1]APREPPFF!I12 -> 0 | DN6: =[1]APREPPFF!J12 -> x | DO6: =[1]APREPPFF!K12 -> 0 | DP6: =[1]APREPPFF!L12 -> x | DQ6: =[1]APREPPFF!M12 -> 0 | DR6: =[1]APREPPFF!N12 -> 0 | DS6: =[1]APREPPFF!O12 -> 0 | DT6: =[1]APREPPFF!P12 -> 0 | ... DY6: =[1]APREPPFF!U12 -> B | DZ6: =[1]ASISTEN!$BR$4 -> 47 | EA6: =[1]ASISTEN!BS14 -> 1 | EB6: =[1]ASISTEN!BO14 -> 42 | EC6: =[1]ASISTEN!BP14 -> 5 | ED6: =[1]ASISTEN!BQ14 -> 0 | EE6: =[1]ASISTEN!BR14 -> 0 | EF6: =[1]APREPER!AM12 -> El estudiante demuestra disposición para aprender. Presenta dificultades en las áreas de comunicación, por lo que necesita reforzar sus hábitos de estudio y mayor monitoreo. Se recomienda un acompañamiento constante. | EG6: =((EI6*3)+(EJ6*2)+(EK6*1)) -> 147 | EH6: =RANK(EG6,$EG$5:$EG$32,0) -> 5 | EI6: =COUNTIF(B6:CI6,"AD") -> 0 | EJ6: =COUNTIF(B6:CI6,"A") -> 62 | EK6: =COUNTIF(B6:CI6,"B") -> 23
A7: 3 | B7: =[1]MAT!C15 -> CHACON MEDINA MIGUEL ANGEL | C7: =[1]MAT!N15 -> A | D7: =[1]MAT!AH15 -> A | E7: =[1]MAT!AZ15 -> A | F7: =[1]MAT!R15 -> A | G7: =[1]MAT!AL15 -> B | H7: =[1]MAT!BA15 -> A | I7: =[1]MAT!V15 -> A | J7: =[1]MAT!AP15 -> B | K7: =[1]MAT!BB15 -> A | L7: =[1]MAT!Z15 -> B | M7: =[1]MAT!AT15 -> A | N7: =[1]MAT!BC15 -> A | O7: =[1]CSOC!N15 -> A | P7: =[1]CSOC!AH15 -> A | Q7: =[1]CSOC!AZ15 -> A | R7: =[1]CSOC!R15 -> A | S7: =[1]CSOC!AL15 -> A | T7: =[1]CSOC!BA15 -> A | U7: =[1]CSOC!V15 -> A | V7: =[1]CSOC!AP15 -> B | W7: =[1]CSOC!BB15 -> A | X7: =[1]EFIS!N15 -> A | Y7: =[1]EFIS!AH15 -> A | Z7: =[1]EFIS!AZ15 -> A | AA7: =[1]EFIS!R15 -> A | AB7: =[1]EFIS!AL15 -> A | AC7: =[1]EFIS!BA15 -> A | AD7: =[1]EFIS!V15 -> A | AE7: =[1]EFIS!AP15 -> A | AF7: =[1]EFIS!BB15 -> A | AG7: =[1]DPCC!N15 -> A | AH7: =[1]DPCC!AH15 -> A | AI7: =[1]DPCC!AZ15 -> A | AJ7: =[1]DPCC!R15 -> A | AK7: =[1]DPCC!AL15 -> B | AL7: =[1]DPCC!BA15 -> A | AM7: =[1]ARTE!N15 -> A | AN7: =[1]ARTE!AH15 -> A | AO7: =[1]ARTE!AZ15 -> A | AP7: =[1]ARTE!R15 -> A | AQ7: =[1]ARTE!AL15 -> A | AR7: =[1]ARTE!BA15 -> A | AS7: =[1]COMU!N15 -> A | AT7: =[1]COMU!AH15 -> B | AU7: =[1]COMU!AZ15 -> A | AV7: =[1]COMU!R15 -> A | AW7: =[1]COMU!AL15 -> A | AX7: =[1]COMU!BA15 -> A | AY7: =[1]COMU!V15 -> A | AZ7: =[1]COMU!AP15 -> A | BA7: =[1]COMU!BB15 -> A | BB7: =[1]CTEC!N15 -> A | BC7: =[1]CTEC!AH15 -> A | BD7: =[1]CTEC!AZ15 -> A | BE7: =[1]CTEC!R15 -> A | BF7: =[1]CTEC!AL15 -> B | BG7: =[1]CTEC!BA15 -> A | BH7: =[1]CTEC!V15 -> B | BI7: =[1]CTEC!AP15 -> B | BJ7: =[1]CTEC!BB15 -> B | BK7: =[1]ING!N15 -> A | BL7: =[1]ING!AH15 -> B | BM7: =[1]ING!AZ15 -> A | BN7: =[1]ING!R15 -> A | BO7: =[1]ING!AL15 -> A | BP7: =[1]ING!BA15 -> A | BQ7: =[1]ING!V15 -> A | BR7: =[1]ING!AP15 -> A | BS7: =[1]ING!BB15 -> A | BT7: =[1]REL!N15 -> AD | BU7: =[1]REL!AH15 -> A | BV7: =[1]REL!AZ15 -> AD | BW7: =[1]REL!R15 -> A | BX7: =[1]REL!AL15 -> A | BY7: =[1]REL!BA15 -> A | BZ7: =[1]EMPR!N15 -> A | CA7: =[1]EMPR!AH15 -> A | CB7: =[1]EMPR!AZ15 -> A | CC7: =[1]COMPU!N15 -> A | CD7: =[1]COMPU!AH15 -> A | CE7: =[1]COMPU!AZ15 -> A | CF7: =[1]ROBOTI!N15 -> A | CG7: =[1]ROBOTI!AH15 -> A | CH7: =[1]ROBOTI!AZ15 -> A | CI7: =[1]APREPER!AK13 -> A | CJ7: =[1]APREPER!AL13 -> A | CK7: =[1]APREPER!I13 -> x | CL7: =[1]APREPER!J13 -> 0 | CM7: =[1]APREPER!K13 -> 0 | CN7: =[1]APREPER!L13 -> x | CO7: =[1]APREPER!M13 -> 0 | CP7: =[1]APREPER!N13 -> 0 | CQ7: =[1]APREPER!O13 -> x | CR7: =[1]APREPER!P13 -> 0 | ... DL7: =[1]APREPER!AJ13 -> A | DM7: =[1]APREPPFF!I13 -> x | DN7: =[1]APREPPFF!J13 -> 0 | DO7: =[1]APREPPFF!K13 -> 0 | DP7: =[1]APREPPFF!L13 -> x | DQ7: =[1]APREPPFF!M13 -> 0 | DR7: =[1]APREPPFF!N13 -> 0 | DS7: =[1]APREPPFF!O13 -> x | DT7: =[1]APREPPFF!P13 -> 0 | ... DY7: =[1]APREPPFF!U13 -> A | DZ7: =[1]ASISTEN!$BR$4 -> 47 | EA7: =[1]ASISTEN!BS15 -> 1 | EB7: =[1]ASISTEN!BO15 -> 47 | EC7: =[1]ASISTEN!BP15 -> 0 | ED7: =[1]ASISTEN!BQ15 -> 0 | EE7: =[1]ASISTEN!BR15 -> 0 | EF7: =[1]APREPER!AM13 -> El estudiante demuestra un buen desempeño académico, es responsable, participativo y organizado. Se sugiere continuar con el mismo compromiso para mantener y fortalecer sus aprendizajes. | EG7: =((EI7*3)+(EJ7*2)+(EK7*1)) -> 161 | EH7: =RANK(EG7,$EG$5:$EG$32,0) -> 2 | EI7: =COUNTIF(B7:CI7,"AD") -> 2 | EJ7: =COUNTIF(B7:CI7,"A") -> 72 | EK7: =COUNTIF(B7:CI7,"B") -> 11
A8: 4 | B8: =[1]MAT!C16 -> CONDORI GOMEZ JOHANNA NIKOL | C8: =[1]MAT!N16 -> B | D8: =[1]MAT!AH16 -> A | E8: =[1]MAT!AZ16 -> A | F8: =[1]MAT!R16 -> B | G8: =[1]MAT!AL16 -> A | H8: =[1]MAT!BA16 -> A | I8: =[1]MAT!V16 -> B | J8: =[1]MAT!AP16 -> B | K8: =[1]MAT!BB16 -> B | L8: =[1]MAT!Z16 -> B | M8: =[1]MAT!AT16 -> B | N8: =[1]MAT!BC16 -> B | O8: =[1]CSOC!N16 -> A | P8: =[1]CSOC!AH16 -> A | Q8: =[1]CSOC!AZ16 -> A | R8: =[1]CSOC!R16 -> A | S8: =[1]CSOC!AL16 -> A | T8: =[1]CSOC!BA16 -> A | U8: =[1]CSOC!V16 -> A | V8: =[1]CSOC!AP16 -> B | W8: =[1]CSOC!BB16 -> A | X8: =[1]EFIS!N16 -> A | Y8: =[1]EFIS!AH16 -> A | Z8: =[1]EFIS!AZ16 -> A | AA8: =[1]EFIS!R16 -> A | AB8: =[1]EFIS!AL16 -> A | AC8: =[1]EFIS!BA16 -> A | AD8: =[1]EFIS!V16 -> A | AE8: =[1]EFIS!AP16 -> A | AF8: =[1]EFIS!BB16 -> A | AG8: =[1]DPCC!N16 -> A | AH8: =[1]DPCC!AH16 -> A | AI8: =[1]DPCC!AZ16 -> A | AJ8: =[1]DPCC!R16 -> A | AK8: =[1]DPCC!AL16 -> A | AL8: =[1]DPCC!BA16 -> A | AM8: =[1]ARTE!N16 -> A | AN8: =[1]ARTE!AH16 -> A | AO8: =[1]ARTE!AZ16 -> A | AP8: =[1]ARTE!R16 -> A | AQ8: =[1]ARTE!AL16 -> A | AR8: =[1]ARTE!BA16 -> A | AS8: =[1]COMU!N16 -> A | AT8: =[1]COMU!AH16 -> B | AU8: =[1]COMU!AZ16 -> A | AV8: =[1]COMU!R16 -> A | AW8: =[1]COMU!AL16 -> A | AX8: =[1]COMU!BA16 -> A | AY8: =[1]COMU!V16 -> A | AZ8: =[1]COMU!AP16 -> A | BA8: =[1]COMU!BB16 -> A | BB8: =[1]CTEC!N16 -> A | BC8: =[1]CTEC!AH16 -> A | BD8: =[1]CTEC!AZ16 -> A | BE8: =[1]CTEC!R16 -> A | BF8: =[1]CTEC!AL16 -> B | BG8: =[1]CTEC!BA16 -> A | BH8: =[1]CTEC!V16 -> B | BI8: =[1]CTEC!AP16 -> B | BJ8: =[1]CTEC!BB16 -> B | BK8: =[1]ING!N16 -> A | BL8: =[1]ING!AH16 -> A | BM8: =[1]ING!AZ16 -> A | BN8: =[1]ING!R16 -> A | BO8: =[1]ING!AL16 -> A | BP8: =[1]ING!BA16 -> A | BQ8: =[1]ING!V16 -> A | BR8: =[1]ING!AP16 -> A | BS8: =[1]ING!BB16 -> A | BT8: =[1]REL!N16 -> A | BU8: =[1]REL!AH16 -> A | BV8: =[1]REL!AZ16 -> A | BW8: =[1]REL!R16 -> A | BX8: =[1]REL!AL16 -> A | BY8: =[1]REL!BA16 -> A | BZ8: =[1]EMPR!N16 -> A | CA8: =[1]EMPR!AH16 -> A | CB8: =[1]EMPR!AZ16 -> A | CC8: =[1]COMPU!N16 -> A | CD8: =[1]COMPU!AH16 -> A | CE8: =[1]COMPU!AZ16 -> A | CF8: =[1]ROBOTI!N16 -> A | CG8: =[1]ROBOTI!AH16 -> A | CH8: =[1]ROBOTI!AZ16 -> A | CI8: =[1]APREPER!AK14 -> A | CJ8: =[1]APREPER!AL14 -> A | CK8: =[1]APREPER!I14 -> x | CL8: =[1]APREPER!J14 -> 0 | CM8: =[1]APREPER!K14 -> 0 | CN8: =[1]APREPER!L14 -> 0 | CO8: =[1]APREPER!M14 -> x | CP8: =[1]APREPER!N14 -> 0 | CQ8: =[1]APREPER!O14 -> x | CR8: =[1]APREPER!P14 -> 0 | ... DL8: =[1]APREPER!AJ14 -> A | DM8: =[1]APREPPFF!I14 -> 0 | DN8: =[1]APREPPFF!J14 -> x | DO8: =[1]APREPPFF!K14 -> 0 | DP8: =[1]APREPPFF!L14 -> x | DQ8: =[1]APREPPFF!M14 -> 0 | DR8: =[1]APREPPFF!N14 -> 0 | DS8: =[1]APREPPFF!O14 -> x | DT8: =[1]APREPPFF!P14 -> 0 | ... DY8: =[1]APREPPFF!U14 -> A | DZ8: =[1]ASISTEN!$BR$4 -> 47 | EA8: =[1]ASISTEN!BS16 -> 1 | EB8: =[1]ASISTEN!BO16 -> 42 | EC8: =[1]ASISTEN!BP16 -> 5 | ED8: =[1]ASISTEN!BQ16 -> 0 | EE8: =[1]ASISTEN!BR16 -> 0 | EF8: =[1]APREPER!AM14 -> Tienes una excelente capacidad de análisis, sus respuestas son bien fundamentadas. Necesita prepararse para sus evaluaciones. | EG8: =((EI8*3)+(EJ8*2)+(EK8*1)) -> 156 | EH8: =RANK(EG8,$EG$5:$EG$32,0) -> 3 | EI8: =COUNTIF(B8:CI8,"AD") -> 0 | EJ8: =COUNTIF(B8:CI8,"A") -> 71 | EK8: =COUNTIF(B8:CI8,"B") -> 14
A9: 5 | B9: =[1]MAT!C17 -> FLORES MAQUERA DHANA LUCIANA | C9: =[1]MAT!N17 -> B | D9: =[1]MAT!AH17 -> A | E9: =[1]MAT!AZ17 -> A | F9: =[1]MAT!R17 -> B | G9: =[1]MAT!AL17 -> B | H9: =[1]MAT!BA17 -> B | I9: =[1]MAT!V17 -> A | J9: =[1]MAT!AP17 -> B | K9: =[1]MAT!BB17 -> A | L9: =[1]MAT!Z17 -> A | M9: =[1]MAT!AT17 -> B | N9: =[1]MAT!BC17 -> A | O9: =[1]CSOC!N17 -> A | P9: =[1]CSOC!AH17 -> A | Q9: =[1]CSOC!AZ17 -> A | R9: =[1]CSOC!R17 -> A | S9: =[1]CSOC!AL17 -> A | T9: =[1]CSOC!BA17 -> A | U9: =[1]CSOC!V17 -> A | V9: =[1]CSOC!AP17 -> B | W9: =[1]CSOC!BB17 -> A | X9: =[1]EFIS!N17 -> A | Y9: =[1]EFIS!AH17 -> A | Z9: =[1]EFIS!AZ17 -> A | AA9: =[1]EFIS!R17 -> A | AB9: =[1]EFIS!AL17 -> A | AC9: =[1]EFIS!BA17 -> A | AD9: =[1]EFIS!V17 -> A | AE9: =[1]EFIS!AP17 -> A | AF9: =[1]EFIS!BB17 -> A | AG9: =[1]DPCC!N17 -> A | AH9: =[1]DPCC!AH17 -> A | AI9: =[1]DPCC!AZ17 -> A | AJ9: =[1]DPCC!R17 -> A | AK9: =[1]DPCC!AL17 -> A | AL9: =[1]DPCC!BA17 -> A | AM9: =[1]ARTE!N17 -> A | AN9: =[1]ARTE!AH17 -> A | AO9: =[1]ARTE!AZ17 -> A | AP9: =[1]ARTE!R17 -> A | AQ9: =[1]ARTE!AL17 -> A | AR9: =[1]ARTE!BA17 -> A | AS9: =[1]COMU!N17 -> A | AT9: =[1]COMU!AH17 -> B | AU9: =[1]COMU!AZ17 -> A | AV9: =[1]COMU!R17 -> A | AW9: =[1]COMU!AL17 -> A | AX9: =[1]COMU!BA17 -> A | AY9: =[1]COMU!V17 -> A | AZ9: =[1]COMU!AP17 -> A | BA9: =[1]COMU!BB17 -> A | BB9: =[1]CTEC!N17 -> B | BC9: =[1]CTEC!AH17 -> A | BD9: =[1]CTEC!AZ17 -> A | BE9: =[1]CTEC!R17 -> B | BF9: =[1]CTEC!AL17 -> B | BG9: =[1]CTEC!BA17 -> B | BH9: =[1]CTEC!V17 -> A | BI9: =[1]CTEC!AP17 -> B | BJ9: =[1]CTEC!BB17 -> A | BK9: =[1]ING!N17 -> A | BL9: =[1]ING!AH17 -> A | BM9: =[1]ING!AZ17 -> A | BN9: =[1]ING!R17 -> A | BO9: =[1]ING!AL17 -> A | BP9: =[1]ING!BA17 -> A | BQ9: =[1]ING!V17 -> A | BR9: =[1]ING!AP17 -> A | BS9: =[1]ING!BB17 -> A | BT9: =[1]REL!N17 -> A | BU9: =[1]REL!AH17 -> A | BV9: =[1]REL!AZ17 -> A | BW9: =[1]REL!R17 -> A | BX9: =[1]REL!AL17 -> B | BY9: =[1]REL!BA17 -> A | BZ9: =[1]EMPR!N17 -> A | CA9: =[1]EMPR!AH17 -> A | CB9: =[1]EMPR!AZ17 -> A | CC9: =[1]COMPU!N17 -> A | CD9: =[1]COMPU!AH17 -> A | CE9: =[1]COMPU!AZ17 -> A | CF9: =[1]ROBOTI!N17 -> A | CG9: =[1]ROBOTI!AH17 -> A | CH9: =[1]ROBOTI!AZ17 -> A | CI9: =[1]APREPER!AK15 -> A | CJ9: =[1]APREPER!AL15 -> A | CK9: =[1]APREPER!I15 -> 0 | CL9: =[1]APREPER!J15 -> x | CM9: =[1]APREPER!K15 -> 0 | CN9: =[1]APREPER!L15 -> 0 | CO9: =[1]APREPER!M15 -> x | CP9: =[1]APREPER!N15 -> 0 | CQ9: =[1]APREPER!O15 -> x | CR9: =[1]APREPER!P15 -> 0 | ... DL9: =[1]APREPER!AJ15 -> A | DM9: =[1]APREPPFF!I15 -> 0 | DN9: =[1]APREPPFF!J15 -> x | DO9: =[1]APREPPFF!K15 -> 0 | DP9: =[1]APREPPFF!L15 -> 0 | DQ9: =[1]APREPPFF!M15 -> x | DR9: =[1]APREPPFF!N15 -> 0 | DS9: =[1]APREPPFF!O15 -> 0 | DT9: =[1]APREPPFF!P15 -> x | ... DY9: =[1]APREPPFF!U15 -> B | DZ9: =[1]ASISTEN!$BR$4 -> 47 | EA9: =[1]ASISTEN!BS17 -> 0.9787234 | EB9: =[1]ASISTEN!BO17 -> 43 | EC9: =[1]ASISTEN!BP17 -> 2 | ED9: =[1]ASISTEN!BQ17 -> 1 | EE9: =[1]ASISTEN!BR17 -> 1 | EF9: =[1]APREPER!AM15 -> Es muy colaborativa, a ayudar a tus compañeros, se destaca la creatividad en sus trabajos. Tiene que reforzar en las áreas de ciencia y matemáticas | EG9: =((EI9*3)+(EJ9*2)+(EK9*1)) -> 156 | EH9: =RANK(EG9,$EG$5:$EG$32,0) -> 3 | EI9: =COUNTIF(B9:CI9,"AD") -> 0 | EJ9: =COUNTIF(B9:CI9,"A") -> 71 | EK9: =COUNTIF(B9:CI9,"B") -> 14
A10: 6 | B10: =[1]MAT!C18 -> MARÍN AQUINO BETZABETH EDALID | C10: =[1]MAT!N18 -> B | D10: =[1]MAT!AH18 -> A | E10: =[1]MAT!AZ18 -> A | F10: =[1]MAT!R18 -> B | G10: =[1]MAT!AL18 -> B | H10: =[1]MAT!BA18 -> B | I10: =[1]MAT!V18 -> B | J10: =[1]MAT!AP18 -> A | K10: =[1]MAT!BB18 -> A | L10: =[1]MAT!Z18 -> A | M10: =[1]MAT!AT18 -> B | N10: =[1]MAT!BC18 -> A | O10: =[1]CSOC!N18 -> A | P10: =[1]CSOC!AH18 -> A | Q10: =[1]CSOC!AZ18 -> A | R10: =[1]CSOC!R18 -> A | S10: =[1]CSOC!AL18 -> A | T10: =[1]CSOC!BA18 -> A | U10: =[1]CSOC!V18 -> A | V10: =[1]CSOC!AP18 -> B | W10: =[1]CSOC!BB18 -> A | X10: =[1]EFIS!N18 -> A | Y10: =[1]EFIS!AH18 -> A | Z10: =[1]EFIS!AZ18 -> A | AA10: =[1]EFIS!R18 -> A | AB10: =[1]EFIS!AL18 -> A | AC10: =[1]EFIS!BA18 -> A | AD10: =[1]EFIS!V18 -> A | AE10: =[1]EFIS!AP18 -> A | AF10: =[1]EFIS!BB18 -> A | AG10: =[1]DPCC!N18 -> A | AH10: =[1]DPCC!AH18 -> A | AI10: =[1]DPCC!AZ18 -> A | AJ10: =[1]DPCC!R18 -> A | AK10: =[1]DPCC!AL18 -> A | AL10: =[1]DPCC!BA18 -> A | AM10: =[1]ARTE!N18 -> A | AN10: =[1]ARTE!AH18 -> A | AO10: =[1]ARTE!AZ18 -> A | AP10: =[1]ARTE!R18 -> A | AQ10: =[1]ARTE!AL18 -> A | AR10: =[1]ARTE!BA18 -> A | AS10: =[1]COMU!N18 -> A | AT10: =[1]COMU!AH18 -> B | AU10: =[1]COMU!AZ18 -> A | AV10: =[1]COMU!R18 -> A | AW10: =[1]COMU!AL18 -> A | AX10: =[1]COMU!BA18 -> A | AY10: =[1]COMU!V18 -> A | AZ10: =[1]COMU!AP18 -> A | BA10: =[1]COMU!BB18 -> A | BB10: =[1]CTEC!N18 -> B | BC10: =[1]CTEC!AH18 -> A | BD10: =[1]CTEC!AZ18 -> A | BE10: =[1]CTEC!R18 -> B | BF10: =[1]CTEC!AL18 -> A | BG10: =[1]CTEC!BA18 -> A | BH10: =[1]CTEC!V18 -> B | BI10: =[1]CTEC!AP18 -> A | BJ10: =[1]CTEC!BB18 -> A | BK10: =[1]ING!N18 -> A | BL10: =[1]ING!AH18 -> B | BM10: =[1]ING!AZ18 -> A | BN10: =[1]ING!R18 -> A | BO10: =[1]ING!AL18 -> A | BP10: =[1]ING!BA18 -> A | BQ10: =[1]ING!V18 -> A | BR10: =[1]ING!AP18 -> A | BS10: =[1]ING!BB18 -> A | BT10: =[1]REL!N18 | BU10: =[1]REL!AH18 | BV10: =[1]REL!AZ18 | BW10: =[1]REL!R18 | BX10: =[1]REL!AL18 | BY10: =[1]REL!BA18 | BZ10: =[1]EMPR!N18 -> A | CA10: =[1]EMPR!AH18 -> A | CB10: =[1]EMPR!AZ18 -> A | CC10: =[1]COMPU!N18 -> A | CD10: =[1]COMPU!AH18 -> A | CE10: =[1]COMPU!AZ18 -> A | CF10: =[1]ROBOTI!N18 -> A | CG10: =[1]ROBOTI!AH18 -> A | CH10: =[1]ROBOTI!AZ18 -> A | CI10: =[1]APREPER!AK16 -> A | CJ10: =[1]APREPER!AL16 -> A | CK10: =[1]APREPER!I16 -> X | CL10: =[1]APREPER!J16 -> 0 | CM10: =[1]APREPER!K16 -> 0 | CN10: =[1]APREPER!L16 -> 0 | CO10: =[1]APREPER!M16 -> x | CP10: =[1]APREPER!N16 -> 0 | CQ10: =[1]APREPER!O16 -> x | CR10: =[1]APREPER!P16 -> 0 | ... DL10: =[1]APREPER!AJ16 -> A | DM10: =[1]APREPPFF!I16 -> x | DN10: =[1]APREPPFF!J16 -> 0 | DO10: =[1]APREPPFF!K16 -> 0 | DP10: =[1]APREPPFF!L16 -> 0 | DQ10: =[1]APREPPFF!M16 -> x | DR10: =[1]APREPPFF!N16 -> 0 | DS10: =[1]APREPPFF!O16 -> X | DT10: =[1]APREPPFF!P16 -> 0 | ... DY10: =[1]APREPPFF!U16 -> A | DZ10: =[1]ASISTEN!$BR$4 -> 47 | EA10: =[1]ASISTEN!BS18 -> 1 | EB10: =[1]ASISTEN!BO18 -> 43 | EC10: =[1]ASISTEN!BP18 -> 3 | ED10: =[1]ASISTEN!BQ18 -> 1 | EE10: =[1]ASISTEN!BR18 -> 0 | EF10: =[1]APREPER!AM16 -> Tiene una excelente capacidad de análisis, muestra preocupación en su aprendizaje. Necesita prepararse para sus evaluaciones. | EG10: =((EI10*3)+(EJ10*2)+(EK10*1)) -> 146 | EH10: =RANK(EG10,$EG$5:$EG$32,0) -> 6 | EI10: =COUNTIF(B10:CI10,"AD") -> 0 | EJ10: =COUNTIF(B10:CI10,"A") -> 67 | EK10: =COUNTIF(B10:CI10,"B") -> 12
A11: 7 | B11: =[1]MAT!C19 -> PACO JIMENEZ YAMILE VALENTINA | C11: =[1]MAT!N19 -> A | D11: =[1]MAT!AH19 -> A | E11: =[1]MAT!AZ19 -> A | F11: =[1]MAT!R19 -> A | G11: =[1]MAT!AL19 -> A | H11: =[1]MAT!BA19 -> A | I11: =[1]MAT!V19 -> A | J11: =[1]MAT!AP19 -> A | K11: =[1]MAT!BB19 -> A | L11: =[1]MAT!Z19 -> A | M11: =[1]MAT!AT19 -> B | N11: =[1]MAT!BC19 -> A | O11: =[1]CSOC!N19 -> A | P11: =[1]CSOC!AH19 -> A | Q11: =[1]CSOC!AZ19 -> A | R11: =[1]CSOC!R19 -> A | S11: =[1]CSOC!AL19 -> A | T11: =[1]CSOC!BA19 -> A | U11: =[1]CSOC!V19 -> A | V11: =[1]CSOC!AP19 -> B | W11: =[1]CSOC!BB19 -> A | X11: =[1]EFIS!N19 -> A | Y11: =[1]EFIS!AH19 -> A | Z11: =[1]EFIS!AZ19 -> A | AA11: =[1]EFIS!R19 -> A | AB11: =[1]EFIS!AL19 -> A | AC11: =[1]EFIS!BA19 -> A | AD11: =[1]EFIS!V19 -> A | AE11: =[1]EFIS!AP19 -> A | AF11: =[1]EFIS!BB19 -> A | AG11: =[1]DPCC!N19 -> A | AH11: =[1]DPCC!AH19 -> A | AI11: =[1]DPCC!AZ19 -> A | AJ11: =[1]DPCC!R19 -> A | AK11: =[1]DPCC!AL19 -> A | AL11: =[1]DPCC!BA19 -> A | AM11: =[1]ARTE!N19 -> A | AN11: =[1]ARTE!AH19 -> A | AO11: =[1]ARTE!AZ19 -> A | AP11: =[1]ARTE!R19 -> A | AQ11: =[1]ARTE!AL19 -> A | AR11: =[1]ARTE!BA19 -> A | AS11: =[1]COMU!N19 -> A | AT11: =[1]COMU!AH19 -> A | AU11: =[1]COMU!AZ19 -> A | AV11: =[1]COMU!R19 -> A | AW11: =[1]COMU!AL19 -> A | AX11: =[1]COMU!BA19 -> A | AY11: =[1]COMU!V19 -> A | AZ11: =[1]COMU!AP19 -> A | BA11: =[1]COMU!BB19 -> A | BB11: =[1]CTEC!N19 -> A | BC11: =[1]CTEC!AH19 -> A | BD11: =[1]CTEC!AZ19 -> A | BE11: =[1]CTEC!R19 -> A | BF11: =[1]CTEC!AL19 -> A | BG11: =[1]CTEC!BA19 -> A | BH11: =[1]CTEC!V19 -> A | BI11: =[1]CTEC!AP19 -> A | BJ11: =[1]CTEC!BB19 -> A | BK11: =[1]ING!N19 -> A | BL11: =[1]ING!AH19 -> A | BM11: =[1]ING!AZ19 -> A | BN11: =[1]ING!R19 -> A | BO11: =[1]ING!AL19 -> A | BP11: =[1]ING!BA19 -> A | BQ11: =[1]ING!V19 -> A | BR11: =[1]ING!AP19 -> A | BS11: =[1]ING!BB19 -> A | BT11: =[1]REL!N19 -> A | BU11: =[1]REL!AH19 -> A | BV11: =[1]REL!AZ19 -> A | BW11: =[1]REL!R19 -> A | BX11: =[1]REL!AL19 -> A | BY11: =[1]REL!BA19 -> A | BZ11: =[1]EMPR!N19 -> A | CA11: =[1]EMPR!AH19 -> A | CB11: =[1]EMPR!AZ19 -> A | CC11: =[1]COMPU!N19 -> A | CD11: =[1]COMPU!AH19 -> A | CE11: =[1]COMPU!AZ19 -> A | CF11: =[1]ROBOTI!N19 -> A | CG11: =[1]ROBOTI!AH19 -> A | CH11: =[1]ROBOTI!AZ19 -> A | CI11: =[1]APREPER!AK17 -> A | CJ11: =[1]APREPER!AL17 -> A | CK11: =[1]APREPER!I17 -> x | CL11: =[1]APREPER!J17 -> 0 | CM11: =[1]APREPER!K17 -> 0 | CN11: =[1]APREPER!L17 -> x | CO11: =[1]APREPER!M17 -> 0 | CP11: =[1]APREPER!N17 -> 0 | CQ11: =[1]APREPER!O17 -> x | CR11: =[1]APREPER!P17 -> 0 | ... DL11: =[1]APREPER!AJ17 -> A | DM11: =[1]APREPPFF!I17 -> x | DN11: =[1]APREPPFF!J17 -> 0 | DO11: =[1]APREPPFF!K17 -> 0 | DP11: =[1]APREPPFF!L17 -> x | DQ11: =[1]APREPPFF!M17 -> 0 | DR11: =[1]APREPPFF!N17 -> 0 | DS11: =[1]APREPPFF!O17 -> X | DT11: =[1]APREPPFF!P17 -> 0 | ... DY11: =[1]APREPPFF!U17 -> A | DZ11: =[1]ASISTEN!$BR$4 -> 47 | EA11: =[1]ASISTEN!BS19 -> 1 | EB11: =[1]ASISTEN!BO19 -> 47 | EC11: =[1]ASISTEN!BP19 -> 0 | ED11: =[1]ASISTEN!BQ19 -> 0 | EE11: =[1]ASISTEN!BR19 -> 0 | EF11: =[1]APREPER!AM17 -> Estudiante que participa siempre en clase; muestra responsabilidad en lo que se le encomienda, aunque a veces suele confiarse demasiado. Se le aconseja que no desista en su lucha por alcanzar sus objetivos | EG11: =((EI11*3)+(EJ11*2)+(EK11*1)) -> 168 | EH11: =RANK(EG11,$EG$5:$EG$32,0) -> 1 | EI11: =COUNTIF(B11:CI11,"AD") -> 0 | EJ11: =COUNTIF(B11:CI11,"A") -> 83 | EK11: =COUNTIF(B11:CI11,"B") -> 2
A12: 8 | B12: =[1]MAT!C20 -> ROMERO TELLEZ VALESKA LARISSA | C12: =[1]MAT!N20 -> B | D12: =[1]MAT!AH20 -> A | E12: =[1]MAT!AZ20 -> A | F12: =[1]MAT!R20 -> B | G12: =[1]MAT!AL20 -> A | H12: =[1]MAT!BA20 -> A | I12: =[1]MAT!V20 -> B | J12: =[1]MAT!AP20 -> B | K12: =[1]MAT!BB20 -> B | L12: =[1]MAT!Z20 -> A | M12: =[1]MAT!AT20 -> A | N12: =[1]MAT!BC20 -> A | O12: =[1]CSOC!N20 -> A | P12: =[1]CSOC!AH20 -> A | Q12: =[1]CSOC!AZ20 -> A | R12: =[1]CSOC!R20 -> A | S12: =[1]CSOC!AL20 -> B | T12: =[1]CSOC!BA20 -> A | U12: =[1]CSOC!V20 -> B | V12: =[1]CSOC!AP20 -> B | W12: =[1]CSOC!BB20 -> B | X12: =[1]EFIS!N20 -> A | Y12: =[1]EFIS!AH20 -> A | Z12: =[1]EFIS!AZ20 -> A | AA12: =[1]EFIS!R20 -> A | AB12: =[1]EFIS!AL20 -> A | AC12: =[1]EFIS!BA20 -> A | AD12: =[1]EFIS!V20 -> A | AE12: =[1]EFIS!AP20 -> A | AF12: =[1]EFIS!BB20 -> A | AG12: =[1]DPCC!N20 -> A | AH12: =[1]DPCC!AH20 -> A | AI12: =[1]DPCC!AZ20 -> A | AJ12: =[1]DPCC!R20 -> A | AK12: =[1]DPCC!AL20 -> B | AL12: =[1]DPCC!BA20 -> A | AM12: =[1]ARTE!N20 -> A | AN12: =[1]ARTE!AH20 -> A | AO12: =[1]ARTE!AZ20 -> A | AP12: =[1]ARTE!R20 -> A | AQ12: =[1]ARTE!AL20 -> A | AR12: =[1]ARTE!BA20 -> A | AS12: =[1]COMU!N20 -> B | AT12: =[1]COMU!AH20 -> C | AU12: =[1]COMU!AZ20 -> B | AV12: =[1]COMU!R20 -> B | AW12: =[1]COMU!AL20 -> B | AX12: =[1]COMU!BA20 -> B | AY12: =[1]COMU!V20 -> B | AZ12: =[1]COMU!AP20 -> B | BA12: =[1]COMU!BB20 -> B | BB12: =[1]CTEC!N20 -> A | BC12: =[1]CTEC!AH20 -> B | BD12: =[1]CTEC!AZ20 -> A | BE12: =[1]CTEC!R20 -> A | BF12: =[1]CTEC!AL20 -> B | BG12: =[1]CTEC!BA20 -> A | BH12: =[1]CTEC!V20 -> B | BI12: =[1]CTEC!AP20 -> B | BJ12: =[1]CTEC!BB20 -> B | BK12: =[1]ING!N20 -> B | BL12: =[1]ING!AH20 -> A | BM12: =[1]ING!AZ20 -> A | BN12: =[1]ING!R20 -> A | BO12: =[1]ING!AL20 -> A | BP12: =[1]ING!BA20 -> A | BQ12: =[1]ING!V20 -> A | BR12: =[1]ING!AP20 -> A | BS12: =[1]ING!BB20 -> A | BT12: =[1]REL!N20 -> A | BU12: =[1]REL!AH20 -> A | BV12: =[1]REL!AZ20 -> A | BW12: =[1]REL!R20 -> A | BX12: =[1]REL!AL20 -> A | BY12: =[1]REL!BA20 -> A | BZ12: =[1]EMPR!N20 -> A | CA12: =[1]EMPR!AH20 -> A | CB12: =[1]EMPR!AZ20 -> A | CC12: =[1]COMPU!N20 -> A | CD12: =[1]COMPU!AH20 -> A | CE12: =[1]COMPU!AZ20 -> A | CF12: =[1]ROBOTI!N20 -> A | CG12: =[1]ROBOTI!AH20 -> A | CH12: =[1]ROBOTI!AZ20 -> A | CI12: =[1]APREPER!AK18 -> A | CJ12: =[1]APREPER!AL18 -> A | CK12: =[1]APREPER!I18 -> 0 | CL12: =[1]APREPER!J18 -> x | CM12: =[1]APREPER!K18 -> 0 | CN12: =[1]APREPER!L18 -> 0 | CO12: =[1]APREPER!M18 -> x | CP12: =[1]APREPER!N18 -> 0 | CQ12: =[1]APREPER!O18 -> 0 | CR12: =[1]APREPER!P18 -> x | ... DL12: =[1]APREPER!AJ18 -> B | DM12: =[1]APREPPFF!I18 -> 0 | DN12: =[1]APREPPFF!J18 -> x | DO12: =[1]APREPPFF!K18 -> 0 | DP12: =[1]APREPPFF!L18 -> 0 | DQ12: =[1]APREPPFF!M18 -> x | DR12: =[1]APREPPFF!N18 -> 0 | DS12: =[1]APREPPFF!O18 -> 0 | DT12: =[1]APREPPFF!P18 -> x | ... DY12: =[1]APREPPFF!U18 -> B | DZ12: =[1]ASISTEN!$BR$4 -> 47 | EA12: =[1]ASISTEN!BS20 -> 0.93617021 | EB12: =[1]ASISTEN!BO20 -> 44 | EC12: =[1]ASISTEN!BP20 -> 0 | ED12: =[1]ASISTEN!BQ20 -> 0 | EE12: =[1]ASISTEN!BR20 -> 3 | EF12: =[1]APREPER!AM18 -> La estudiante ha mostrado habilidades artísticas, participativo y social con sus compañeros. Se le recomienda continuar con su buen aprestamiento integral y seguir reforzando áreas de matemáticas. | EG12: =((EI12*3)+(EJ12*2)+(EK12*1)) -> 144 | EH12: =RANK(EG12,$EG$5:$EG$32,0) -> 8 | EI12: =COUNTIF(B12:CI12,"AD") -> 0 | EJ12: =COUNTIF(B12:CI12,"A") -> 60 | EK12: =COUNTIF(B12:CI12,"B") -> 24
A13: 9 | B13: =[1]MAT!C21 -> SULLCA CHIPANA JULIO CESAR MATIAS | C13: =[1]MAT!N21 -> B | D13: =[1]MAT!AH21 -> A | E13: =[1]MAT!AZ21 -> A | F13: =[1]MAT!R21 -> B | G13: =[1]MAT!AL21 -> B | H13: =[1]MAT!BA21 -> B | I13: =[1]MAT!V21 -> B | J13: =[1]MAT!AP21 -> B | K13: =[1]MAT!BB21 -> B | L13: =[1]MAT!Z21 -> A | M13: =[1]MAT!AT21 -> A | N13: =[1]MAT!BC21 -> A | O13: =[1]CSOC!N21 -> A | P13: =[1]CSOC!AH21 -> A | Q13: =[1]CSOC!AZ21 -> A | R13: =[1]CSOC!R21 -> A | S13: =[1]CSOC!AL21 -> A | T13: =[1]CSOC!BA21 -> A | U13: =[1]CSOC!V21 -> A | V13: =[1]CSOC!AP21 -> B | W13: =[1]CSOC!BB21 -> A | X13: =[1]EFIS!N21 -> A | Y13: =[1]EFIS!AH21 -> A | Z13: =[1]EFIS!AZ21 -> A | AA13: =[1]EFIS!R21 -> A | AB13: =[1]EFIS!AL21 -> A | AC13: =[1]EFIS!BA21 -> A | AD13: =[1]EFIS!V21 -> A | AE13: =[1]EFIS!AP21 -> A | AF13: =[1]EFIS!BB21 -> A | AG13: =[1]DPCC!N21 -> A | AH13: =[1]DPCC!AH21 -> A | AI13: =[1]DPCC!AZ21 -> A | AJ13: =[1]DPCC!R21 -> A | AK13: =[1]DPCC!AL21 -> B | AL13: =[1]DPCC!BA21 -> A | AM13: =[1]ARTE!N21 -> A | AN13: =[1]ARTE!AH21 -> A | AO13: =[1]ARTE!AZ21 -> A | AP13: =[1]ARTE!R21 -> A | AQ13: =[1]ARTE!AL21 -> A | AR13: =[1]ARTE!BA21 -> A | AS13: =[1]COMU!N21 -> B | AT13: =[1]COMU!AH21 -> B | AU13: =[1]COMU!AZ21 -> B | AV13: =[1]COMU!R21 -> B | AW13: =[1]COMU!AL21 -> A | AX13: =[1]COMU!BA21 -> A | AY13: =[1]COMU!V21 -> A | AZ13: =[1]COMU!AP21 -> A | BA13: =[1]COMU!BB21 -> A | BB13: =[1]CTEC!N21 -> B | BC13: =[1]CTEC!AH21 -> A | BD13: =[1]CTEC!AZ21 -> A | BE13: =[1]CTEC!R21 -> B | BF13: =[1]CTEC!AL21 -> C | BG13: =[1]CTEC!BA21 -> B | BH13: =[1]CTEC!V21 -> A | BI13: =[1]CTEC!AP21 -> C | BJ13: =[1]CTEC!BB21 -> B | BK13: =[1]ING!N21 -> B | BL13: =[1]ING!AH21 -> B | BM13: =[1]ING!AZ21 -> B | BN13: =[1]ING!R21 -> A | BO13: =[1]ING!AL21 -> A | BP13: =[1]ING!BA21 -> A | BQ13: =[1]ING!V21 -> A | BR13: =[1]ING!AP21 -> A | BS13: =[1]ING!BB21 -> A | BT13: =[1]REL!N21 -> A | BU13: =[1]REL!AH21 -> A | BV13: =[1]REL!AZ21 -> A | BW13: =[1]REL!R21 -> A | BX13: =[1]REL!AL21 -> A | BY13: =[1]REL!BA21 -> A | BZ13: =[1]EMPR!N21 -> A | CA13: =[1]EMPR!AH21 -> A | CB13: =[1]EMPR!AZ21 -> A | CC13: =[1]COMPU!N21 -> A | CD13: =[1]COMPU!AH21 -> A | CE13: =[1]COMPU!AZ21 -> A | CF13: =[1]ROBOTI!N21 -> A | CG13: =[1]ROBOTI!AH21 -> A | CH13: =[1]ROBOTI!AZ21 -> A | CI13: =[1]APREPER!AK19 -> A | CJ13: =[1]APREPER!AL19 -> A | CK13: =[1]APREPER!I19 -> x | CL13: =[1]APREPER!J19 -> 0 | CM13: =[1]APREPER!K19 -> 0 | CN13: =[1]APREPER!L19 -> x | CO13: =[1]APREPER!M19 -> 0 | CP13: =[1]APREPER!N19 -> 0 | CQ13: =[1]APREPER!O19 -> x | CR13: =[1]APREPER!P19 -> 0 | ... DL13: =[1]APREPER!AJ19 -> A | DM13: =[1]APREPPFF!I19 -> x | DN13: =[1]APREPPFF!J19 -> 0 | DO13: =[1]APREPPFF!K19 -> 0 | DP13: =[1]APREPPFF!L19 -> x | DQ13: =[1]APREPPFF!M19 -> 0 | DR13: =[1]APREPPFF!N19 -> 0 | DS13: =[1]APREPPFF!O19 -> x | DT13: =[1]APREPPFF!P19 -> 0 | ... DY13: =[1]APREPPFF!U19 -> A | DZ13: =[1]ASISTEN!$BR$4 -> 47 | EA13: =[1]ASISTEN!BS21 -> 0.9787234 | EB13: =[1]ASISTEN!BO21 -> 44 | EC13: =[1]ASISTEN!BP21 -> 1 | ED13: =[1]ASISTEN!BQ21 -> 1 | EE13: =[1]ASISTEN!BR21 -> 1 | EF13: =[1]APREPER!AM19 -> El estudiante muestra iniciativa para la colaboración en actividades, debe de mantener reforzando lo que avanza en clase y sus tareas. | EG13: =((EI13*3)+(EJ13*2)+(EK13*1)) -> 146 | EH13: =RANK(EG13,$EG$5:$EG$32,0) -> 6 | EI13: =COUNTIF(B13:CI13,"AD") -> 0 | EJ13: =COUNTIF(B13:CI13,"A") -> 63 | EK13: =COUNTIF(B13:CI13,"B") -> 20
A14: 10 | B14: =[1]MAT!C22 -> 0 | C14: =[1]MAT!N22 | D14: =[1]MAT!AH22 | E14: =[1]MAT!AZ22 | F14: =[1]MAT!R22 | G14: =[1]MAT!AL22 | H14: =[1]MAT!BA22 | I14: =[1]MAT!V22 | J14: =[1]MAT!AP22 | K14: =[1]MAT!BB22 | L14: =[1]MAT!Z22 | M14: =[1]MAT!AT22 | N14: =[1]MAT!BC22 | O14: =[1]CSOC!N22 | P14: =[1]CSOC!AH22 | Q14: =[1]CSOC!AZ22 | R14: =[1]CSOC!R22 | S14: =[1]CSOC!AL22 | T14: =[1]CSOC!BA22 | U14: =[1]CSOC!V22 | V14: =[1]CSOC!AP22 | W14: =[1]CSOC!BB22 | X14: =[1]EFIS!N22 | Y14: =[1]EFIS!AH22 | Z14: =[1]EFIS!AZ22 | AA14: =[1]EFIS!R22 | AB14: =[1]EFIS!AL22 | AC14: =[1]EFIS!BA22 | AD14: =[1]EFIS!V22 | AE14: =[1]EFIS!AP22 | AF14: =[1]EFIS!BB22 | AG14: =[1]DPCC!N22 | AH14: =[1]DPCC!AH22 | AI14: =[1]DPCC!AZ22 | AJ14: =[1]DPCC!R22 | AK14: =[1]DPCC!AL22 | AL14: =[1]DPCC!BA22 | AM14: =[1]ARTE!N22 | AN14: =[1]ARTE!AH22 | AO14: =[1]ARTE!AZ22 | AP14: =[1]ARTE!R22 | AQ14: =[1]ARTE!AL22 | AR14: =[1]ARTE!BA22 | AS14: =[1]COMU!N22 | AT14: =[1]COMU!AH22 | AU14: =[1]COMU!AZ22 | AV14: =[1]COMU!R22 | AW14: =[1]COMU!AL22 | AX14: =[1]COMU!BA22 | AY14: =[1]COMU!V22 | AZ14: =[1]COMU!AP22 | BA14: =[1]COMU!BB22 | BB14: =[1]CTEC!N22 | BC14: =[1]CTEC!AH22 | BD14: =[1]CTEC!AZ22 | BE14: =[1]CTEC!R22 | BF14: =[1]CTEC!AL22 | BG14: =[1]CTEC!BA22 | BH14: =[1]CTEC!V22 | BI14: =[1]CTEC!AP22 | BJ14: =[1]CTEC!BB22 | BK14: =[1]ING!N22 | BL14: =[1]ING!AH22 | BM14: =[1]ING!AZ22 | BN14: =[1]ING!R22 | BO14: =[1]ING!AL22 | BP14: =[1]ING!BA22 | BQ14: =[1]ING!V22 | BR14: =[1]ING!AP22 | BS14: =[1]ING!BB22 | BT14: =[1]REL!N22 | BU14: =[1]REL!AH22 | BV14: =[1]REL!AZ22 | BW14: =[1]REL!R22 | BX14: =[1]REL!AL22 | BY14: =[1]REL!BA22 | BZ14: =[1]EMPR!N22 | CA14: =[1]EMPR!AH22 | CB14: =[1]EMPR!AZ22 | CC14: =[1]COMPU!N22 | CD14: =[1]COMPU!AH22 | CE14: =[1]COMPU!AZ22 | CF14: =[1]ROBOTI!N22 | CG14: =[1]ROBOTI!AH22 | CH14: =[1]ROBOTI!AZ22 | CI14: =[1]APREPER!AK20 -> 0 | CJ14: =[1]APREPER!AL20 -> 0 | CK14: =[1]APREPER!I20 -> 0 | CL14: =[1]APREPER!J20 -> 0 | CM14: =[1]APREPER!K20 -> 0 | CN14: =[1]APREPER!L20 -> 0 | CO14: =[1]APREPER!M20 -> 0 | CP14: =[1]APREPER!N20 -> 0 | CQ14: =[1]APREPER!O20 -> 0 | CR14: =[1]APREPER!P20 -> 0 | ... DL14: =[1]APREPER!AJ20 -> 0 | DM14: =[1]APREPPFF!I20 -> 0 | DN14: =[1]APREPPFF!J20 -> 0 | DO14: =[1]APREPPFF!K20 -> 0 | DP14: =[1]APREPPFF!L20 -> 0 | DQ14: =[1]APREPPFF!M20 -> 0 | DR14: =[1]APREPPFF!N20 -> 0 | DS14: =[1]APREPPFF!O20 -> 0 | DT14: =[1]APREPPFF!P20 -> 0 | ... DY14: =[1]APREPPFF!U20 -> 0 | EF14: =[1]APREPER!AM20 -> 0 | EI14: =COUNTIF(B14:CI14,"AD") -> 0 | EJ14: =COUNTIF(B14:CI14,"A") -> 0 | EK14: =COUNTIF(B14:CI14,"B") -> 0
A15: 11 | B15: =[1]MAT!C23 -> 0 | C15: =[1]MAT!N23 | D15: =[1]MAT!AH23 | E15: =[1]MAT!AZ23 | F15: =[1]MAT!R23 | G15: =[1]MAT!AL23 | H15: =[1]MAT!BA23 | I15: =[1]MAT!V23 | J15: =[1]MAT!AP23 | K15: =[1]MAT!BB23 | L15: =[1]MAT!Z23 | M15: =[1]MAT!AT23 | N15: =[1]MAT!BC23 | O15: =[1]CSOC!N23 | P15: =[1]CSOC!AH23 | Q15: =[1]CSOC!AZ23 | R15: =[1]CSOC!R23 | S15: =[1]CSOC!AL23 | T15: =[1]CSOC!BA23 | U15: =[1]CSOC!V23 | V15: =[1]CSOC!AP23 | W15: =[1]CSOC!BB23 | X15: =[1]EFIS!N23 | Y15: =[1]EFIS!AH23 | Z15: =[1]EFIS!AZ23 | AA15: =[1]EFIS!R23 | AB15: =[1]EFIS!AL23 | AC15: =[1]EFIS!BA23 | AD15: =[1]EFIS!V23 | AE15: =[1]EFIS!AP23 | AF15: =[1]EFIS!BB23 | AG15: =[1]DPCC!N23 | AH15: =[1]DPCC!AH23 | AI15: =[1]DPCC!AZ23 | AJ15: =[1]DPCC!R23 | AK15: =[1]DPCC!AL23 | AL15: =[1]DPCC!BA23 | AM15: =[1]ARTE!N23 | AN15: =[1]ARTE!AH23 | AO15: =[1]ARTE!AZ23 | AP15: =[1]ARTE!R23 | AQ15: =[1]ARTE!AL23 | AR15: =[1]ARTE!BA23 | AS15: =[1]COMU!N23 | AT15: =[1]COMU!AH23 | AU15: =[1]COMU!AZ23 | AV15: =[1]COMU!R23 | AW15: =[1]COMU!AL23 | AX15: =[1]COMU!BA23 | AY15: =[1]COMU!V23 | AZ15: =[1]COMU!AP23 | BA15: =[1]COMU!BB23 | BB15: =[1]CTEC!N23 | BC15: =[1]CTEC!AH23 | BD15: =[1]CTEC!AZ23 | BE15: =[1]CTEC!R23 | BF15: =[1]CTEC!AL23 | BG15: =[1]CTEC!BA23 | BH15: =[1]CTEC!V23 | BI15: =[1]CTEC!AP23 | BJ15: =[1]CTEC!BB23 | BK15: =[1]ING!N23 | BL15: =[1]ING!AH23 | BM15: =[1]ING!AZ23 | BN15: =[1]ING!R23 | BO15: =[1]ING!AL23 | BP15: =[1]ING!BA23 | BQ15: =[1]ING!V23 | BR15: =[1]ING!AP23 | BS15: =[1]ING!BB23 | BT15: =[1]REL!N23 | BU15: =[1]REL!AH23 | BV15: =[1]REL!AZ23 | BW15: =[1]REL!R23 | BX15: =[1]REL!AL23 | BY15: =[1]REL!BA23 | BZ15: =[1]EMPR!N23 | CA15: =[1]EMPR!AH23 | CB15: =[1]EMPR!AZ23 | CC15: =[1]COMPU!N23 | CD15: =[1]COMPU!AH23 | CE15: =[1]COMPU!AZ23 | CF15: =[1]ROBOTI!N23 | CG15: =[1]ROBOTI!AH23 | CH15: =[1]ROBOTI!AZ23 | CI15: =[1]APREPER!AK21 -> 0 | CJ15: =[1]APREPER!AL21 -> 0 | CK15: =[1]APREPER!I21 -> 0 | CL15: =[1]APREPER!J21 -> 0 | CM15: =[1]APREPER!K21 -> 0 | CN15: =[1]APREPER!L21 -> 0 | CO15: =[1]APREPER!M21 -> 0 | CP15: =[1]APREPER!N21 -> 0 | CQ15: =[1]APREPER!O21 -> 0 | CR15: =[1]APREPER!P21 -> 0 | ... DL15: =[1]APREPER!AJ21 -> 0 | DM15: =[1]APREPPFF!I21 -> 0 | DN15: =[1]APREPPFF!J21 -> 0 | DO15: =[1]APREPPFF!K21 -> 0 | DP15: =[1]APREPPFF!L21 -> 0 | DQ15: =[1]APREPPFF!M21 -> 0 | DR15: =[1]APREPPFF!N21 -> 0 | DS15: =[1]APREPPFF!O21 -> 0 | DT15: =[1]APREPPFF!P21 -> 0 | ... DY15: =[1]APREPPFF!U21 -> 0 | EF15: =[1]APREPER!AM21 -> 0 | EI15: =COUNTIF(B15:CI15,"AD") -> 0 | EJ15: =COUNTIF(B15:CI15,"A") -> 0 | EK15: =COUNTIF(B15:CI15,"B") -> 0
A16: 12 | B16: =[1]MAT!C24 -> 0 | C16: =[1]MAT!N24 | D16: =[1]MAT!AH24 | E16: =[1]MAT!AZ24 | F16: =[1]MAT!R24 | G16: =[1]MAT!AL24 | H16: =[1]MAT!BA24 | I16: =[1]MAT!V24 | J16: =[1]MAT!AP24 | K16: =[1]MAT!BB24 | L16: =[1]MAT!Z24 | M16: =[1]MAT!AT24 | N16: =[1]MAT!BC24 | O16: =[1]CSOC!N24 | P16: =[1]CSOC!AH24 | Q16: =[1]CSOC!AZ24 | R16: =[1]CSOC!R24 | S16: =[1]CSOC!AL24 | T16: =[1]CSOC!BA24 | U16: =[1]CSOC!V24 | V16: =[1]CSOC!AP24 | W16: =[1]CSOC!BB24 | X16: =[1]EFIS!N24 | Y16: =[1]EFIS!AH24 | Z16: =[1]EFIS!AZ24 | AA16: =[1]EFIS!R24 | AB16: =[1]EFIS!AL24 | AC16: =[1]EFIS!BA24 | AD16: =[1]EFIS!V24 | AE16: =[1]EFIS!AP24 | AF16: =[1]EFIS!BB24 | AG16: =[1]DPCC!N24 | AH16: =[1]DPCC!AH24 | AI16: =[1]DPCC!AZ24 | AJ16: =[1]DPCC!R24 | AK16: =[1]DPCC!AL24 | AL16: =[1]DPCC!BA24 | AM16: =[1]ARTE!N24 | AN16: =[1]ARTE!AH24 | AO16: =[1]ARTE!AZ24 | AP16: =[1]ARTE!R24 | AQ16: =[1]ARTE!AL24 | AR16: =[1]ARTE!BA24 | AS16: =[1]COMU!N24 | AT16: =[1]COMU!AH24 | AU16: =[1]COMU!AZ24 | AV16: =[1]COMU!R24 | AW16: =[1]COMU!AL24 | AX16: =[1]COMU!BA24 | AY16: =[1]COMU!V24 | AZ16: =[1]COMU!AP24 | BA16: =[1]COMU!BB24 | BB16: =[1]CTEC!N24 | BC16: =[1]CTEC!AH24 | BD16: =[1]CTEC!AZ24 | BE16: =[1]CTEC!R24 | BF16: =[1]CTEC!AL24 | BG16: =[1]CTEC!BA24 | BH16: =[1]CTEC!V24 | BI16: =[1]CTEC!AP24 | BJ16: =[1]CTEC!BB24 | BK16: =[1]ING!N24 | BL16: =[1]ING!AH24 | BM16: =[1]ING!AZ24 | BN16: =[1]ING!R24 | BO16: =[1]ING!AL24 | BP16: =[1]ING!BA24 | BQ16: =[1]ING!V24 | BR16: =[1]ING!AP24 | BS16: =[1]ING!BB24 | BT16: =[1]REL!N24 | BU16: =[1]REL!AH24 | BV16: =[1]REL!AZ24 | BW16: =[1]REL!R24 | BX16: =[1]REL!AL24 | BY16: =[1]REL!BA24 | BZ16: =[1]EMPR!N24 | CA16: =[1]EMPR!AH24 | CB16: =[1]EMPR!AZ24 | CC16: =[1]COMPU!N24 | CD16: =[1]COMPU!AH24 | CE16: =[1]COMPU!AZ24 | CF16: =[1]ROBOTI!N24 | CG16: =[1]ROBOTI!AH24 | CH16: =[1]ROBOTI!AZ24 | CI16: =[1]APREPER!AK22 -> 0 | CJ16: =[1]APREPER!AL22 -> 0 | CK16: =[1]APREPER!I22 -> 0 | CL16: =[1]APREPER!J22 -> 0 | CM16: =[1]APREPER!K22 -> 0 | CN16: =[1]APREPER!L22 -> 0 | CO16: =[1]APREPER!M22 -> 0 | CP16: =[1]APREPER!N22 -> 0 | CQ16: =[1]APREPER!O22 -> 0 | CR16: =[1]APREPER!P22 -> 0 | ... DL16: =[1]APREPER!AJ22 -> 0 | DM16: =[1]APREPPFF!I22 -> 0 | DN16: =[1]APREPPFF!J22 -> 0 | DO16: =[1]APREPPFF!K22 -> 0 | DP16: =[1]APREPPFF!L22 -> 0 | DQ16: =[1]APREPPFF!M22 -> 0 | DR16: =[1]APREPPFF!N22 -> 0 | DS16: =[1]APREPPFF!O22 -> 0 | DT16: =[1]APREPPFF!P22 -> 0 | ... DY16: =[1]APREPPFF!U22 -> 0 | EF16: =[1]APREPER!AM22 -> 0 | EI16: =COUNTIF(B16:CI16,"AD") -> 0 | EJ16: =COUNTIF(B16:CI16,"A") -> 0 | EK16: =COUNTIF(B16:CI16,"B") -> 0
A17: 13 | B17: =[1]MAT!C25 -> 0 | C17: =[1]MAT!N25 | D17: =[1]MAT!AH25 | E17: =[1]MAT!AZ25 | F17: =[1]MAT!R25 | G17: =[1]MAT!AL25 | H17: =[1]MAT!BA25 | I17: =[1]MAT!V25 | J17: =[1]MAT!AP25 | K17: =[1]MAT!BB25 | L17: =[1]MAT!Z25 | M17: =[1]MAT!AT25 | N17: =[1]MAT!BC25 | O17: =[1]CSOC!N25 | P17: =[1]CSOC!AH25 | Q17: =[1]CSOC!AZ25 | R17: =[1]CSOC!R25 | S17: =[1]CSOC!AL25 | T17: =[1]CSOC!BA25 | U17: =[1]CSOC!V25 | V17: =[1]CSOC!AP25 | W17: =[1]CSOC!BB25 | X17: =[1]EFIS!N25 | Y17: =[1]EFIS!AH25 | Z17: =[1]EFIS!AZ25 | AA17: =[1]EFIS!R25 | AB17: =[1]EFIS!AL25 | AC17: =[1]EFIS!BA25 | AD17: =[1]EFIS!V25 | AE17: =[1]EFIS!AP25 | AF17: =[1]EFIS!BB25 | AG17: =[1]DPCC!N25 | AH17: =[1]DPCC!AH25 | AI17: =[1]DPCC!AZ25 | AJ17: =[1]DPCC!R25 | AK17: =[1]DPCC!AL25 | AL17: =[1]DPCC!BA25 | AM17: =[1]ARTE!N25 | AN17: =[1]ARTE!AH25 | AO17: =[1]ARTE!AZ25 | AP17: =[1]ARTE!R25 | AQ17: =[1]ARTE!AL25 | AR17: =[1]ARTE!BA25 | AS17: =[1]COMU!N25 | AT17: =[1]COMU!AH25 | AU17: =[1]COMU!AZ25 | AV17: =[1]COMU!R25 | AW17: =[1]COMU!AL25 | AX17: =[1]COMU!BA25 | AY17: =[1]COMU!V25 | AZ17: =[1]COMU!AP25 | BA17: =[1]COMU!BB25 | BB17: =[1]CTEC!N25 | BC17: =[1]CTEC!AH25 | BD17: =[1]CTEC!AZ25 | BE17: =[1]CTEC!R25 | BF17: =[1]CTEC!AL25 | BG17: =[1]CTEC!BA25 | BH17: =[1]CTEC!V25 | BI17: =[1]CTEC!AP25 | BJ17: =[1]CTEC!BB25 | BK17: =[1]ING!N25 | BL17: =[1]ING!AH25 | BM17: =[1]ING!AZ25 | BN17: =[1]ING!R25 | BO17: =[1]ING!AL25 | BP17: =[1]ING!BA25 | BQ17: =[1]ING!V25 | BR17: =[1]ING!AP25 | BS17: =[1]ING!BB25 | BT17: =[1]REL!N25 | BU17: =[1]REL!AH25 | BV17: =[1]REL!AZ25 | BW17: =[1]REL!R25 | BX17: =[1]REL!AL25 | BY17: =[1]REL!BA25 | BZ17: =[1]EMPR!N25 | CA17: =[1]EMPR!AH25 | CB17: =[1]EMPR!AZ25 | CC17: =[1]COMPU!N25 | CD17: =[1]COMPU!AH25 | CE17: =[1]COMPU!AZ25 | CF17: =[1]ROBOTI!N25 | CG17: =[1]ROBOTI!AH25 | CH17: =[1]ROBOTI!AZ25 | CI17: =[1]APREPER!AK23 -> 0 | CJ17: =[1]APREPER!AL23 -> 0 | CK17: =[1]APREPER!I23 -> 0 | CL17: =[1]APREPER!J23 -> 0 | CM17: =[1]APREPER!K23 -> 0 | CN17: =[1]APREPER!L23 -> 0 | CO17: =[1]APREPER!M23 -> 0 | CP17: =[1]APREPER!N23 -> 0 | CQ17: =[1]APREPER!O23 -> 0 | CR17: =[1]APREPER!P23 -> 0 | ... DL17: =[1]APREPER!AJ23 -> 0 | DM17: =[1]APREPPFF!I23 -> 0 | DN17: =[1]APREPPFF!J23 -> 0 | DO17: =[1]APREPPFF!K23 -> 0 | DP17: =[1]APREPPFF!L23 -> 0 | DQ17: =[1]APREPPFF!M23 -> 0 | DR17: =[1]APREPPFF!N23 -> 0 | DS17: =[1]APREPPFF!O23 -> 0 | DT17: =[1]APREPPFF!P23 -> 0 | ... DY17: =[1]APREPPFF!U23 -> 0 | EF17: =[1]APREPER!AM23 -> 0 | EI17: =COUNTIF(B17:CI17,"AD") -> 0 | EJ17: =COUNTIF(B17:CI17,"A") -> 0 | EK17: =COUNTIF(B17:CI17,"B") -> 0
A18: 14 | B18: =[1]MAT!C26 -> 0 | C18: =[1]MAT!N26 | D18: =[1]MAT!AH26 | E18: =[1]MAT!AZ26 | F18: =[1]MAT!R26 | G18: =[1]MAT!AL26 | H18: =[1]MAT!BA26 | I18: =[1]MAT!V26 | J18: =[1]MAT!AP26 | K18: =[1]MAT!BB26 | L18: =[1]MAT!Z26 | M18: =[1]MAT!AT26 | N18: =[1]MAT!BC26 | O18: =[1]CSOC!N26 | P18: =[1]CSOC!AH26 | Q18: =[1]CSOC!AZ26 | R18: =[1]CSOC!R26 | S18: =[1]CSOC!AL26 | T18: =[1]CSOC!BA26 | U18: =[1]CSOC!V26 | V18: =[1]CSOC!AP26 | W18: =[1]CSOC!BB26 | X18: =[1]EFIS!N26 | Y18: =[1]EFIS!AH26 | Z18: =[1]EFIS!AZ26 | AA18: =[1]EFIS!R26 | AB18: =[1]EFIS!AL26 | AC18: =[1]EFIS!BA26 | AD18: =[1]EFIS!V26 | AE18: =[1]EFIS!AP26 | AF18: =[1]EFIS!BB26 | AG18: =[1]DPCC!N26 | AH18: =[1]DPCC!AH26 | AI18: =[1]DPCC!AZ26 | AJ18: =[1]DPCC!R26 | AK18: =[1]DPCC!AL26 | AL18: =[1]DPCC!BA26 | AM18: =[1]ARTE!N26 | AN18: =[1]ARTE!AH26 | AO18: =[1]ARTE!AZ26 | AP18: =[1]ARTE!R26 | AQ18: =[1]ARTE!AL26 | AR18: =[1]ARTE!BA26 | AS18: =[1]COMU!N26 | AT18: =[1]COMU!AH26 | AU18: =[1]COMU!AZ26 | AV18: =[1]COMU!R26 | AW18: =[1]COMU!AL26 | AX18: =[1]COMU!BA26 | AY18: =[1]COMU!V26 | AZ18: =[1]COMU!AP26 | BA18: =[1]COMU!BB26 | BB18: =[1]CTEC!N26 | BC18: =[1]CTEC!AH26 | BD18: =[1]CTEC!AZ26 | BE18: =[1]CTEC!R26 | BF18: =[1]CTEC!AL26 | BG18: =[1]CTEC!BA26 | BH18: =[1]CTEC!V26 | BI18: =[1]CTEC!AP26 | BJ18: =[1]CTEC!BB26 | BK18: =[1]ING!N26 | BL18: =[1]ING!AH26 | BM18: =[1]ING!AZ26 | BN18: =[1]ING!R26 | BO18: =[1]ING!AL26 | BP18: =[1]ING!BA26 | BQ18: =[1]ING!V26 | BR18: =[1]ING!AP26 | BS18: =[1]ING!BB26 | BT18: =[1]REL!N26 | BU18: =[1]REL!AH26 | BV18: =[1]REL!AZ26 | BW18: =[1]REL!R26 | BX18: =[1]REL!AL26 | BY18: =[1]REL!BA26 | BZ18: =[1]EMPR!N26 | CA18: =[1]EMPR!AH26 | CB18: =[1]EMPR!AZ26 | CC18: =[1]COMPU!N26 | CD18: =[1]COMPU!AH26 | CE18: =[1]COMPU!AZ26 | CF18: =[1]ROBOTI!N26 | CG18: =[1]ROBOTI!AH26 | CH18: =[1]ROBOTI!AZ26 | CI18: =[1]APREPER!AK24 -> 0 | CJ18: =[1]APREPER!AL24 -> 0 | CK18: =[1]APREPER!I24 -> 0 | CL18: =[1]APREPER!J24 -> 0 | CM18: =[1]APREPER!K24 -> 0 | CN18: =[1]APREPER!L24 -> 0 | CO18: =[1]APREPER!M24 -> 0 | CP18: =[1]APREPER!N24 -> 0 | CQ18: =[1]APREPER!O24 -> 0 | CR18: =[1]APREPER!P24 -> 0 | ... DL18: =[1]APREPER!AJ24 -> 0 | DM18: =[1]APREPPFF!I24 -> 0 | DN18: =[1]APREPPFF!J24 -> 0 | DO18: =[1]APREPPFF!K24 -> 0 | DP18: =[1]APREPPFF!L24 -> 0 | DQ18: =[1]APREPPFF!M24 -> 0 | DR18: =[1]APREPPFF!N24 -> 0 | DS18: =[1]APREPPFF!O24 -> 0 | DT18: =[1]APREPPFF!P24 -> 0 | ... DY18: =[1]APREPPFF!U24 -> 0 | EF18: =[1]APREPER!AM24 -> 0 | EI18: =COUNTIF(B18:CI18,"AD") -> 0 | EJ18: =COUNTIF(B18:CI18,"A") -> 0 | EK18: =COUNTIF(B18:CI18,"B") -> 0
A19: 15 | B19: =[1]MAT!C27 -> 0 | C19: =[1]MAT!N27 | D19: =[1]MAT!AH27 | E19: =[1]MAT!AZ27 | F19: =[1]MAT!R27 | G19: =[1]MAT!AL27 | H19: =[1]MAT!BA27 | I19: =[1]MAT!V27 | J19: =[1]MAT!AP27 | K19: =[1]MAT!BB27 | L19: =[1]MAT!Z27 | M19: =[1]MAT!AT27 | N19: =[1]MAT!BC27 | O19: =[1]CSOC!N27 | P19: =[1]CSOC!AH27 | Q19: =[1]CSOC!AZ27 | R19: =[1]CSOC!R27 | S19: =[1]CSOC!AL27 | T19: =[1]CSOC!BA27 | U19: =[1]CSOC!V27 | V19: =[1]CSOC!AP27 | W19: =[1]CSOC!BB27 | X19: =[1]EFIS!N27 | Y19: =[1]EFIS!AH27 | Z19: =[1]EFIS!AZ27 | AA19: =[1]EFIS!R27 | AB19: =[1]EFIS!AL27 | AC19: =[1]EFIS!BA27 | AD19: =[1]EFIS!V27 | AE19: =[1]EFIS!AP27 | AF19: =[1]EFIS!BB27 | AG19: =[1]DPCC!N27 | AH19: =[1]DPCC!AH27 | AI19: =[1]DPCC!AZ27 | AJ19: =[1]DPCC!R27 | AK19: =[1]DPCC!AL27 | AL19: =[1]DPCC!BA27 | AM19: =[1]ARTE!N27 | AN19: =[1]ARTE!AH27 | AO19: =[1]ARTE!AZ27 | AP19: =[1]ARTE!R27 | AQ19: =[1]ARTE!AL27 | AR19: =[1]ARTE!BA27 | AS19: =[1]COMU!N27 | AT19: =[1]COMU!AH27 | AU19: =[1]COMU!AZ27 | AV19: =[1]COMU!R27 | AW19: =[1]COMU!AL27 | AX19: =[1]COMU!BA27 | AY19: =[1]COMU!V27 | AZ19: =[1]COMU!AP27 | BA19: =[1]COMU!BB27 | BB19: =[1]CTEC!N27 | BC19: =[1]CTEC!AH27 | BD19: =[1]CTEC!AZ27 | BE19: =[1]CTEC!R27 | BF19: =[1]CTEC!AL27 | BG19: =[1]CTEC!BA27 | BH19: =[1]CTEC!V27 | BI19: =[1]CTEC!AP27 | BJ19: =[1]CTEC!BB27 | BK19: =[1]ING!N27 | BL19: =[1]ING!AH27 | BM19: =[1]ING!AZ27 | BN19: =[1]ING!R27 | BO19: =[1]ING!AL27 | BP19: =[1]ING!BA27 | BQ19: =[1]ING!V27 | BR19: =[1]ING!AP27 | BS19: =[1]ING!BB27 | BT19: =[1]REL!N27 | BU19: =[1]REL!AH27 | BV19: =[1]REL!AZ27 | BW19: =[1]REL!R27 | BX19: =[1]REL!AL27 | BY19: =[1]REL!BA27 | BZ19: =[1]EMPR!N27 | CA19: =[1]EMPR!AH27 | CB19: =[1]EMPR!AZ27 | CC19: =[1]COMPU!N27 | CD19: =[1]COMPU!AH27 | CE19: =[1]COMPU!AZ27 | CF19: =[1]ROBOTI!N27 | CG19: =[1]ROBOTI!AH27 | CH19: =[1]ROBOTI!AZ27 | CI19: =[1]APREPER!AK25 -> 0 | CJ19: =[1]APREPER!AL25 -> 0 | CK19: =[1]APREPER!I25 -> 0 | CL19: =[1]APREPER!J25 -> 0 | CM19: =[1]APREPER!K25 -> 0 | CN19: =[1]APREPER!L25 -> 0 | CO19: =[1]APREPER!M25 -> 0 | CP19: =[1]APREPER!N25 -> 0 | CQ19: =[1]APREPER!O25 -> 0 | CR19: =[1]APREPER!P25 -> 0 | ... DL19: =[1]APREPER!AJ25 -> 0 | DM19: =[1]APREPPFF!I25 -> 0 | DN19: =[1]APREPPFF!J25 -> 0 | DO19: =[1]APREPPFF!K25 -> 0 | DP19: =[1]APREPPFF!L25 -> 0 | DQ19: =[1]APREPPFF!M25 -> 0 | DR19: =[1]APREPPFF!N25 -> 0 | DS19: =[1]APREPPFF!O25 -> 0 | DT19: =[1]APREPPFF!P25 -> 0 | ... DY19: =[1]APREPPFF!U25 -> 0 | EF19: =[1]APREPER!AM25 -> 0 | EI19: =COUNTIF(B19:CI19,"AD") -> 0 | EJ19: =COUNTIF(B19:CI19,"A") -> 0 | EK19: =COUNTIF(B19:CI19,"B") -> 0
